Workbook

Sheet CEX (wide)
A1: Category | C1: Commodities | D1: Commodities | E1: Commodities | F1: Commodities | G1: Stocks | H1: Stocks | I1: Stocks | J1: Stocks | K1: Stocks | L1: Stocks | M1: Stocks | N1: Stocks | O1: Indices | P1: Stocks | Q1: Commodities | R1: Stocks | S1: Commodities | T1: Stocks | U1: Stocks | V1: Stocks | W1: Indices | X1: Stocks | Y1: Indices | Z1: Stocks | AA1: Stocks | AB1: Commodities | AC1: Indices | AD1: Pre-IPO | AE1: Commodities | AF1: Stocks | AG1: Stocks | AH1: Stocks | AI1: Stocks | AJ1: Stocks | AK1: Commodities | AL1: Stocks | AM1: Stocks | AN1: Stocks | AO1: Indices | AP1: Stocks | AQ1: Stocks | AR1: Stocks | AS1: Stocks | AT1: Stocks | AU1: Indices | AV1: Indices | AW1: Stocks | AX1: Indices | AY1: Stocks | AZ1: Stocks | BA1: Stocks | BB1: Stocks | BC1: Indices | BD1: Stocks | BE1: Pre-IPO | BF1: Pre-IPO | BG1: Stocks | BH1: Stocks | BI1: Stocks | BJ1: Stocks | BK1: Stocks | BL1: Stocks | BM1: Stocks | BN1: Indices | BO1: Stocks | BP1: Stocks | BQ1: Stocks | BR1: Stocks | BS1: Stocks | BT1: Stocks | BU1: Stocks | BV1: Indices | BW1: Stocks | BX1: Stocks | BY1: Stocks | BZ1: Stocks | CA1: Stocks | CB1: Stocks | CC1: Indices | CD1: Stocks | CE1: Indices | CF1: Stocks | CG1: Stocks | CH1: Stocks | CI1: Stocks | CJ1: Stocks | CK1: Stocks | CL1: Stocks | CM1: Stocks | CN1: Commodities | CO1: Indices | CP1: Stocks | CQ1: Stocks | CR1: Stocks | CS1: Stocks | CT1: Indices | CU1: Stocks | CV1: Stocks | CW1: Stocks | CX1: Stocks | CY1: Stocks | CZ1: Stocks | DA1: Indices | DB1: Stocks | DC1: Indices | DD1: Indices | DE1: Stocks | DF1: Indices | DG1: Indices | DH1: Stocks | DI1: Stocks | DJ1: Stocks | DK1: Stocks | DL1: Stocks | DM1: Stocks | DN1: Indices | DO1: Stocks | DP1: Stocks | DQ1: Stocks | DR1: Stocks | DS1: Stocks | DT1: Stocks | DU1: Stocks | DV1: Stocks | DW1: Pre-IPO | DX1: Stocks | DY1: Indices | DZ1: Stocks | EA1: Commodities | EB1: Indices | EC1: Indices | ED1: FX | EE1: Commodities | EF1: Stocks | EG1: Stocks | EH1: FX | EI1: Indices | EJ1: Stocks | EK1: Stocks | EL1: Pre-IPO | EM1: Stocks | EN1: Indices | EO1: Indices | EP1: Stocks | EQ1: Stocks | ER1: Stocks | ES1: Stocks | ET1: FX | EU1: Stocks | EV1: FX | EW1: Stocks | EX1: Stocks | EY1: Stocks | EZ1: Stocks | FA1: Stocks | FB1: Stocks | FC1: Stocks | FD1: Stocks | FE1: Stocks | FF1: Stocks | FG1: Stocks | FH1: Stocks | FI1: Stocks | FJ1: Stocks | FK1: Stocks | FL1: Stocks | FM1: Stocks | FN1: Stocks | FO1: Stocks | FP1: Stocks | FQ1: Stocks | FR1: Stocks | FS1: Stocks | FT1: Stocks | FU1: Stocks | FV1: Stocks | FW1: Stocks | FX1: Stocks | FY1: Stocks | FZ1: Stocks | GA1: FX | GB1: Stocks | GC1: Stocks | GD1: Stocks | GE1: FX | GF1: FX | GG1: FX
A2: dt | B2: Total | C2: XAU | D2: XAG | E2: WTI | F2: BZ | G2: CRCL | H2: TSLA | I2: MU | J2: SNDK | K2: NVDA | L2: MSTR | M2: INTC | N2: COIN | O2: EWY | P2: HOOD | Q2: NATGAS | R2: AAPL | S2: XPT | T2: PLTR | U2: AMZN | V2: GOOGL | W2: QQQ | X2: AMD | Y2: SOXL | Z2: META | AA2: MSFT | AB2: XCU | AC2: SPY | AD2: CBRS | AE2: XPD | AF2: TSM | AG2: AIA | AH2: ORCL | AI2: PLAY | AJ2: BABA | AK2: NG | AL2: MRVL | AM2: ARM | AN2: RKLB | AO2: DRAM | AP2: QCOM | AQ2: AVGO | AR2: LITE | AS2: NFLX | AT2: IP | AU2: NAS100 | AV2: TQQQ | AW2: PAYP | AX2: EWJ | AY2: FLY | AZ2: AAOI | BA2: CFG | BB2: APP | BC2: LIT | BD2: RDDT | BE2: OPENAI | BF2: ANTHROPIC | BG2: ASML | BH2: APLD | BI2: USAR | BJ2: CRWV | BK2: OXY | BL2: FUTU | BM2: STX | BN2: SOXS | BO2: JD | BP2: IONQ | BQ2: NBIS | BR2: MCD | BS2: LLY | BT2: WMT | BU2: EDU | BV2: SQQQ | BW2: XOM | BX2: MET | BY2: COHR | BZ2: UNH | CA2: BE | CB2: COP | CC2: TW88 | CD2: GE | CE2: EWT | CF2: GME | CG2: CSCO | CH2: KOPN | CI2: IR | CJ2: COST | CK2: CRDO | CL2: AXTI | CM2: LWLG | CN2: GAS | CO2: UK100 | CP2: OKLO | CQ2: AMAT | CR2: MP | CS2: KLAC | CT2: KWEB | CU2: BMNR | CV2: GT | CW2: WDC | CX2: A | CY2: VRT | CZ2: FLNC | DA2: JPN225 | DB2: INFQ | DC2: US30 | DD2: VIX | DE2: DIS | DF2: HK50 | DG2: XLE | DH2: JPM | DI2: TENCENT | DJ2: HD | DK2: XIAOMI | DL2: KO | DM2: UBER | DN2: AUS200 | DO2: V | DP2: BA | DQ2: NIO | DR2: IBM | DS2: NOC | DT2: LMT | DU2: BRKB | DV2: GLW | DW2: ZHIPU | DX2: IREN | DY2: US2000 | DZ2: ACN | EA2: GLD | EB2: IWM | EC2: GER40 | ED2: EURUSD | EE2: XUNCE | EF2: GD | EG2: KUAISHOU | EH2: HSCHKD | EI2: EWH | EJ2: ALL | EK2: MEITUAN | EL2: MINIMAX | EM2: RTX | EN2: SBP | EO2: INDA | EP2: SMCI | EQ2: LENOVO | ER2: PG | ES2: PEP | ET2: GBPUSD | EU2: ASTS | EV2: EUR | EW2: FN | EX2: CARR | EY2: CMI | EZ2: NXT | FA2: ETN | FB2: DELL | FC2: GEELY | FD2: SUNAC | FE2: ANTA | FF2: BWXT | FG2: CEG | FH2: AKESO | FI2: CLS | FJ2: ABBV | FK2: HPE | FL2: DDOG | FM2: FSLR | FN2: CCJ | FO2: CITIC | FP2: JNJ | FQ2: POET | FR2: ALB | FS2: JCI | FT2: HSBC | FU2: MDB | FV2: RDW | FW2: APH | FX2: SNOW | FY2: ANET | FZ2: NOK | GA2: GBP | GB2: ONDS | GC2: SHLD | GD2: OUST | GE2: CHF | GF2: JPY | GG2: AUD
A3: 46162 | B3: 8.5814482e+09 | C3: 2.2296084e+09 | D3: 1.8897786e+09 | E3: 1.7836155e+09 | F3: 4.0701165e+08 | G3: 1.2479557e+08 | H3: 73846649 | I3: 3.6149794e+08 | J3: 3.4396301e+08 | K3: 3.0902692e+08 | L3: 62669403 | M3: 1.7494909e+08 | N3: 23160793 | O3: 1.2290054e+08 | P3: 7837966 | Q3: 45744495 | R3: 11858738 | S3: 8472266.1 | T3: 10372937 | U3: 9371163.9 | V3: 40062293 | W3: 42666898 | X3: 50333970 | Y3: 66269034 | Z3: 8291444.6 | AA3: 14026733 | AB3: 7654506.3 | AC3: 18907151 | AD3: 1.2285408e+08 | AE3: 4492061.1 | AF3: 6382881.3 | AG3: 3199934.9 | AH3: 7400429.6 | AI3: 12296697 | AJ3: 11969816 | AK3: 4979870.1 | AL3: 14561771 | AM3: 5013066.5 | AN3: 16361389 | AO3: 21024826 | AP3: 6197131.7 | AQ3: 3421360.8 | AR3: 9589269.6 | AS3: 329131.81 | AT3: 362770.56 | AU3: 689583.64 | AV3: 1714242.6 | AW3: 497574.8 | AX3: 1312523.4 | AY3: 2868989.4 | AZ3: 2821129.1 | BA3: 383291.99 | BB3: 405961.97 | BC3: 6587671.9 | BD3: 742594.26 | BE3: 1624454.3 | BF3: 2191286.1 | BG3: 1021124.3 | BH3: 7579302 | BI3: 5520870 | BJ3: 2247769.3 | BK3: 1198538.9 | BL3: 300950.99 | BM3: 174468.49 | BN3: 2256859.5 | BO3: 111554.99 | BP3: 1685284.8 | BQ3: 2591550.8 | BR3: 186452.04 | BS3: 508485.34 | BT3: 925131.21 | BU3: 127111.67 | BV3: 1470003.3 | BW3: 281342.11 | BX3: 60910.43 | BY3: 1063532.8 | BZ3: 189201.3 | CA3: 3456721.5 | CB3: 102181.05 | CC3: 959143.28 | CD3: 140247.77 | CE3: 542302.84 | CF3: 130278 | CG3: 2504613.4 | CH3: 2111366.3 | CI3: 14490.107 | CJ3: 345956.52 | CK3: 1686650.2 | CL3: 1877524.5 | CM3: 1707317 | CN3: 43381.536 | CO3: 81490.742 | CP3: 505742.13 | CQ3: 189951.45 | CR3: 1102830.9 | CS3: 622576.54 | CT3: 11921.965 | CU3: 112429.98 | CV3: 47799.257 | CW3: 489528.45 | CX3: 37123.176 | CY3: 2047945.4 | CZ3: 2038953.7 | DA3: 26899.204 | DB3: 623236.19 | DC3: 106540.7 | DD3: 56715.736 | DE3: 314136.62 | DF3: 25090.56 | DG3: 133285.01 | DH3: 489879.66 | DI3: 145187.12 | DJ3: 460884.2 | DK3: 21558.859 | DL3: 17896.439 | DM3: 367929.18 | DN3: 11535.034 | DO3: 692270.22 | DP3: 19492.57 | DQ3: 741324.22 | DR3: 20799.644 | DS3: 13145.36 | DT3: 9456.7857 | DU3: 847003.34 | DV3: 183178.9 | DW3: 11415.693 | DX3: 89209.475 | DY3: 8157.3535 | DZ3: 9164.3275 | EA3: 599197.94 | EB3: 20979.679 | EC3: 20287.809 | ED3: 18334.981 | EE3: 8197.332 | EF3: 7686.8244 | EG3: 16938.438 | EH3: 3227.7651 | EI3: 4861.0848 | EJ3: 19671.849 | EK3: 7360.3435 | EL3: 15696.892 | EM3: 11453.437 | EN3: 18886.043 | EO3: 47052.648 | EP3: 152064.09 | EQ3: 5082.539 | ER3: 2534.5985 | ES3: 6408.9702 | ET3: 4618.3087 | EU3: 622183.45 | EV3: 33664.237 | EW3: 13922.393 | EX3: 17533.155 | EY3: 14092.585 | EZ3: 2943.4216 | FA3: 107181.63 | FB3: 55745.553 | FC3: 4563.448 | FD3: 2704.2114 | FE3: 3006.1007 | FF3: 3609.287 | FG3: 19823.778 | FH3: 3054.1265 | FI3: 14314.764 | FJ3: 5450.1981 | FK3: 7601.832 | FL3: 6220.4768 | FM3: 7657.3427 | FN3: 9586.2885 | FO3: 3688.1653 | FP3: 4916.1995 | FQ3: 246857.4 | FR3: 3246.1727 | FS3: 3439.0766 | FT3: 2170.1372 | FU3: 7206.824 | FV3: 213759.54 | FW3: 3052.5553 | FX3: 5337.434 | FY3: 2784.5832 | FZ3: 98715.457 | GA3: 0 | GB3: 48073.39 | GC3: 16024.781 | GD3: 17734.787 | GE3: 0 | GF3: 0 | GG3: 0
A4: 46161 | B4: 7.2487997e+09 | C4: 2.0584575e+09 | D4: 1.892921e+09 | E4: 8.0882903e+08 | F4: 1.7827564e+08 | G4: 1.8182528e+08 | H4: 74338010 | I4: 5.2523086e+08 | J4: 4.3014738e+08 | K4: 1.8904375e+08 | L4: 56791059 | M4: 1.3111408e+08 | N4: 25738089 | O4: 83937290 | P4: 9249524.3 | Q4: 43589413 | R4: 7482620.9 | S4: 9387224.2 | T4: 9659250.4 | U4: 7920141.9 | V4: 29125724 | W4: 39120191 | X4: 33733036 | Y4: 78615381 | Z4: 9077104.9 | AA4: 23341009 | AB4: 7372737.1 | AC4: 13249008 | AD4: 1.0367191e+08 | AE4: 4919705.5 | AF4: 5899075.9 | AG4: 9565179.1 | AH4: 6882095.7 | AI4: 3024254.8 | AJ4: 7346290.4 | AK4: 3163247.3 | AL4: 8237113.2 | AM4: 3192196.1 | AN4: 12456131 | AO4: 20589493 | AP4: 4759556.4 | AQ4: 3861123.2 | AR4: 8924113.2 | AS4: 947878.86 | AT4: 346073.56 | AU4: 1007267.8 | AV4: 2501705.1 | AW4: 307512.22 | AX4: 1173256.7 | AY4: 4273933 | AZ4: 4575670.4 | BA4: 476573.57 | BB4: 525064.31 | BC4: 1917406.6 | BD4: 310860.33 | BE4: 9274948.2 | BF4: 1039898.8 | BG4: 585124.01 | BH4: 3732206.6 | BI4: 3166948.5 | BJ4: 3499590.5 | BK4: 59216.812 | BL4: 383941.98 | BM4: 236094.57 | BN4: 4719220.6 | BO4: 101837.14 | BP4: 2033379.2 | BQ4: 4058027.5 | BR4: 174011.14 | BS4: 556074.71 | BT4: 1147257.2 | BU4: 138706.66 | BV4: 1999766 | BW4: 54532.614 | BX4: 56868.299 | BY4: 2788917.8 | BZ4: 229756.44 | CA4: 2657128.8 | CB4: 57851.816 | CC4: 32972.17 | CD4: 66657.878 | CE4: 709237.46 | CF4: 99615.66 | CG4: 1768342.8 | CH4: 1658871.7 | CI4: 83313.14 | CJ4: 304329.97 | CK4: 1280672.7 | CL4: 2985749.6 | CM4: 1175746 | CN4: 122589.37 | CO4: 74525.236 | CP4: 524790.45 | CQ4: 190060.56 | CR4: 1242971.9 | CS4: 454520.05 | CT4: 42269.883 | CU4: 139546.26 | CV4: 55878.18 | CW4: 781258.71 | CX4: 24512.607 | CY4: 1604083.5 | CZ4: 1755651.3 | DA4: 55499.293 | DB4: 244715.65 | DC4: 95393.177 | DD4: 50802.97 | DE4: 435484.31 | DF4: 67594.167 | DG4: 233628.29 | DH4: 616889.23 | DI4: 153937.5 | DJ4: 921182.4 | DK4: 23715.207 | DL4: 16822.631 | DM4: 299306.34 | DN4: 14375.412 | DO4: 476795.69 | DP4: 57904.152 | DQ4: 112222.69 | DR4: 7441.1763 | DS4: 10024.601 | DT4: 9390.0634 | DU4: 736738.47 | DV4: 280394.65 | DW4: 20042.072 | DX4: 58451.773 | DY4: 14002.707 | DZ4: 62033.128 | EA4: 1794.2126 | EB4: 151189.76 | EC4: 11239.493 | ED4: 21171.006 | EE4: 22502.503 | EF4: 7452.2989 | EG4: 15547.289 | EH4: 27452.892 | EI4: 19297.817 | EJ4: 18902.82 | EK4: 12589.204 | EL4: 11293.264 | EM4: 10671.176 | EN4: 12606.328 | EO4: 5055.0877 | EP4: 19163.454 | EQ4: 4215.4995 | ER4: 3264.7407 | ES4: 6512.1492 | ET4: 6266.1796 | EU4: 179757.91 | EV4: 388424.48 | EW4: 14259.514 | EX4: 23260.045 | EY4: 13535.539 | EZ4: 6721.5317 | FA4: 49889.192 | FB4: 5518.3984 | FC4: 4513.03 | FD4: 2714.9307 | FE4: 1713.009 | FF4: 3617.329 | FG4: 10914.857 | FH4: 2657.9416 | FI4: 6113.429 | FJ4: 11282.324 | FK4: 6412.469 | FL4: 8917.6812 | FM4: 5829.6565 | FN4: 2835.2179 | FO4: 2997.4652 | FP4: 4251.5089 | FQ4: 71860.181 | FR4: 4026.6948 | FS4: 2834.8695 | FT4: 2231.0647 | FU4: 18335.538 | FV4: 26321.338 | FW4: 3627.4975 | FX4: 6455.5192 | FY4: 3241.9169 | FZ4: 34467.445 | GA4: 210.14764 | GB4: 20139.45 | GC4: 15236.285 | GD4: 16126.29 | GE4: 0 | GF4: 0 | GG4: 0
A5: 46160 | B5: 9.0823647e+09 | C5: 2.3808183e+09 | D5: 2.2387889e+09 | E5: 1.5752684e+09 | F5: 4.7371597e+08 | G5: 2.0012192e+08 | H5: 86079130 | I5: 4.5873126e+08 | J5: 4.5530081e+08 | K5: 2.04593e+08 | L5: 1.1177519e+08 | M5: 1.8978921e+08 | N5: 34046735 | O5: 1.1891924e+08 | P5: 18254406 | Q5: 49808120 | R5: 10970466 | S5: 10358416 | T5: 10054112 | U5: 9205823.5 | V5: 34155967 | W5: 34088815 | X5: 33388228 | Y5: 47828861 | Z5: 7907556.7 | AA5: 17078740 | AB5: 8812488.7 | AC5: 15515339 | AD5: 40678829 | AE5: 4771972.5 | AF5: 8443002.9 | AG5: 12227281 | AH5: 8533352.3 | AI5: 535573.02 | AJ5: 10272233 | AK5: 3606360.8 | AL5: 11349113 | AM5: 2967015.5 | AN5: 20378596 | AO5: 12879218 | AP5: 3843729 | AQ5: 5535959.1 | AR5: 10450719 | AS5: 1008701.1 | AT5: 612290.2 | AU5: 1051508 | AV5: 2900088.6 | AW5: 806404.05 | AX5: 1579849.8 | AY5: 6377349.7 | AZ5: 5150824.5 | BA5: 365824.72 | BB5: 753575.27 | BC5: 525935.06 | BD5: 470290.02 | BE5: 894359.08 | BF5: 2856193.8 | BG5: 623293.35 | BH5: 3478584.3 | BI5: 5609363.8 | BJ5: 4910528 | BK5: 197313.07 | BL5: 377441.51 | BM5: 583297.68 | BN5: 5287664.7 | BO5: 285845.75 | BP5: 4503568.9 | BQ5: 4214499.8 | BR5: 300430.93 | BS5: 1144699 | BT5: 808333.96 | BU5: 385506.81 | BV5: 1813621.1 | BW5: 187701.86 | BX5: 83695.145 | BY5: 1770206.9 | BZ5: 1015179.2 | CA5: 2063078.3 | CB5: 43850.262 | CC5: 69941.202 | CD5: 230504.36 | CE5: 582305.4 | CF5: 201745.75 | CG5: 3253497.5 | CH5: 1789768.1 | CI5: 228259.16 | CJ5: 532932.47 | CK5: 621390.84 | CL5: 1738840 | CM5: 1103862.7 | CN5: 14562.81 | CO5: 80942.457 | CP5: 796050.62 | CQ5: 119206.89 | CR5: 633068.55 | CS5: 446640.53 | CT5: 14127.42 | CU5: 1709291 | CV5: 75525.072 | CW5: 689855.31 | CX5: 53715.629 | CY5: 1153790.4 | CZ5: 1103645 | DA5: 100552.78 | DB5: 907640.01 | DC5: 49757.842 | DD5: 30530.964 | DE5: 1087123.6 | DF5: 12323.199 | DG5: 546385.66 | DH5: 723102.95 | DI5: 22524.447 | DJ5: 808696.23 | DK5: 27751.345 | DL5: 19322.903 | DM5: 455408.62 | DN5: 17597.101 | DO5: 1230568 | DP5: 20424.58 | DQ5: 179971.03 | DR5: 5712.0477 | DS5: 10757.465 | DT5: 10392.801 | DU5: 673905.07 | DV5: 211958.35 | DW5: 35757.29 | DX5: 70348.015 | DY5: 7795.723 | DZ5: 18431.926 | EA5: 24850.778 | EB5: 81139.027 | EC5: 28639.855 | ED5: 130580.3 | EE5: 6742.155 | EF5: 9826.8151 | EG5: 24471.213 | EH5: 2961.4307 | EI5: 12429.727 | EJ5: 28692.427 | EK5: 35610.021 | EL5: 13849.381 | EM5: 61100.966 | EN5: 11906.949 | EO5: 15547.694 | EP5: 11582.393 | EQ5: 3664.9989 | ER5: 2610.3689 | ES5: 18668.364 | ET5: 7271.9383 | EV5: 1512.6076 | EW5: 38930.767 | EX5: 11239.659 | EY5: 12997.209 | EZ5: 15063.605 | FA5: 114451.13 | FB5: 56502.326 | FC5: 5271.808 | FD5: 3573.0594 | FE5: 5140.1992 | FF5: 3737.731 | FG5: 24634.375 | FH5: 3211.9763 | FI5: 6373.506 | FJ5: 4819.7879 | FK5: 7222.221 | FL5: 5046.2332 | FM5: 9664.0692 | FN5: 17105.535 | FO5: 3301.6795 | FP5: 4608.0536 | FR5: 3929.0293 | FS5: 3323.0905 | FT5: 5395.7481 | FU5: 20771.838 | FW5: 4659.8651 | FX5: 4870.3207 | FY5: 4251.9935 | GA5: 0 | GC5: 13487.065 | GE5: 0 | GF5: 0 | GG5: 0
A6: 46159 | B6: 1.3052204e+09 | C6: 4.0949112e+08 | D6: 3.1841008e+08 | E6: 2.0194689e+08 | F6: 52992134 | G6: 16568781 | H6: 8343979.8 | I6: 33677618 | J6: 25892874 | K6: 30462050 | L6: 12910501 | M6: 10370267 | N6: 3866355.8 | O6: 15893610 | P6: 1978419.5 | Q6: 7897471.9 | R6: 3653244.3 | S6: 3266302.8 | T6: 1426887.8 | U6: 831899.3 | V6: 7254391.8 | W6: 9290053.8 | X6: 2950552.6 | Y6: 2310463.4 | Z6: 1128617.2 | AA6: 1499639.1 | AB6: 5606610.6 | AC6: 6107491 | AD6: 6596984.6 | AE6: 1463772.1 | AF6: 827607.12 | AG6: 65725875 | AH6: 2045948 | AI6: 1466963.1 | AJ6: 549461.49 | AK6: 879301.75 | AL6: 4404383.2 | AM6: 321634.24 | AN6: 1155001.4 | AO6: 2250833.8 | AP6: 1410704 | AQ6: 1120819.5 | AR6: 1992469 | AS6: 152868.78 | AT6: 789602.65 | AU6: 558793.28 | AV6: 306840.2 | AW6: 321420.09 | AX6: 1452181.5 | AY6: 10235.536 | AZ6: 54514.563 | BA6: 142080.04 | BB6: 8049.6308 | BC6: 126884.94 | BD6: 16707.57 | BE6: 4626913.1 | BF6: 622052.91 | BG6: 142278.47 | BH6: 163517.62 | BI6: 440334.03 | BJ6: 167999.91 | BK6: 14086.213 | BL6: 97668.399 | BM6: 355140.51 | BN6: 240309.95 | BO6: 29025.662 | BP6: 112904.77 | BQ6: 127107.05 | BR6: 30988.175 | BS6: 1240789.6 | BT6: 16989.008 | BU6: 139975.94 | BV6: 81912.071 | BW6: 71078.658 | BX6: 73942.42 | BY6: 160283.51 | BZ6: 15626.456 | CA6: 132782.57 | CB6: 7106.3547 | CC6: 47768.172 | CD6: 17972.781 | CE6: 14560.81 | CF6: 55202.45 | CG6: 424719.9 | CH6: 27283.229 | CI6: 30094.986 | CJ6: 65298.938 | CK6: 80510.844 | CL6: 111009.9 | CM6: 29096.08 | CN6: 39623.238 | CO6: 3367.9843 | CP6: 30743.217 | CQ6: 29461.09 | CR6: 22492.288 | CS6: 21968.206 | CT6: 4240.8561 | CU6: 659264.33 | CV6: 54316.337 | CW6: 163958.54 | CX6: 101642.49 | CY6: 41819.147 | DA6: 9096.3345 | DB6: 108949 | DC6: 17677.756 | DD6: 33265.408 | DE6: 631826.86 | DF6: 6056.5764 | DG6: 187231.72 | DH6: 7361.5874 | DI6: 24098.506 | DJ6: 94383.976 | DK6: 23738.173 | DL6: 14635.734 | DM6: 161734.17 | DN6: 10875.391 | DO6: 7012.962 | DP6: 13724.153 | DQ6: 12492.245 | DR6: 10206.777 | DS6: 9655.1653 | DT6: 9264.6198 | DU6: 15343.547 | DV6: 49072.775 | DW6: 3502.8808 | DX6: 10258.224 | DY6: 5438.056 | DZ6: 4505.8155 | EA6: 16.3293 | EB6: 58802.635 | EC6: 5048.0316 | ED6: 2457.0126 | EE6: 10439.669 | EF6: 6324.7184 | EG6: 12347.72 | EH6: 2800.4154 | EI6: 1820.9268 | EJ6: 14444.423 | EK6: 14812.794 | EL6: 4885.3314 | EM6: 36257.799 | EN6: 11873.713 | EO6: 4527.1222 | EP6: 5783.127 | EQ6: 3753.9435 | ER6: 3488.9006 | ES6: 2660.0775 | ET6: 4587.9949 | EV6: 35.55 | EW6: 12756.718 | EX6: 11169.604 | EY6: 12368.035 | EZ6: 3073.8581 | FA6: 10739.481 | FB6: 4795.4485 | FC6: 4715.432 | FD6: 7483.6019 | FE6: 2590.8022 | FF6: 5706.402 | FG6: 19505.459 | FH6: 4084.79 | FI6: 6236.071 | FJ6: 7713.4178 | FK6: 7536.198 | FL6: 5839.6763 | FM6: 4525.8309 | FN6: 1929.2053 | FO6: 2967.9675 | FP6: 4840.5658 | FR6: 3762.5713 | FS6: 2574.6569 | FT6: 1610.0742 | FU6: 5736.67 | FW6: 2383.8113 | FX6: 4461.9227 | FY6: 3280.0286 | GA6: 0 | GE6: 0 | GF6: 0 | GG6: 0
A7: 46158 | B7: 8.7199853e+08 | C7: 3.0646108e+08 | D7: 1.4156483e+08 | E7: 1.6641608e+08 | F7: 36486731 | G7: 18898716 | H7: 6458215.7 | I7: 25186415 | J7: 23906061 | K7: 24484453 | L7: 11194576 | M7: 7831960.5 | N7: 3793089.6 | O7: 4798523 | P7: 2729924.8 | Q7: 4495347.1 | R7: 4428255.9 | S7: 4740886.1 | T7: 1812628.9 | U7: 1165737.7 | V7: 7469464.4 | W7: 9691168.9 | X7: 2728453.4 | Y7: 1786906.9 | Z7: 1263166.2 | AA7: 2448095.2 | AB7: 1902176.3 | AC7: 5914085.5 | AD7: 5776992.6 | AE7: 1245613.2 | AF7: 1482138.4 | AG7: 3196915.1 | AH7: 1428227.2 | AI7: 1479035.3 | AJ7: 995974.43 | AK7: 735633.97 | AL7: 5267555.5 | AM7: 603699.42 | AN7: 952387.75 | AO7: 1090718 | AP7: 1131192.9 | AQ7: 1535420.7 | AR7: 1225517.7 | AS7: 207561.92 | AT7: 524461.96 | AU7: 186546.91 | AV7: 204524.28 | AW7: 131664.37 | AX7: 660870.99 | AY7: 50117.397 | AZ7: 101636 | BA7: 134429.99 | BB7: 34135.195 | BC7: 131418.66 | BD7: 10035.45 | BE7: 762652.76 | BF7: 725497.5 | BG7: 39550.736 | BH7: 73892.471 | BI7: 169436.09 | BJ7: 626885.35 | BK7: 58065.603 | BL7: 10789.462 | BM7: 211543.07 | BN7: 136981.31 | BO7: 34605.396 | BP7: 575808.53 | BQ7: 92290.381 | BR7: 37933.4 | BS7: 377101.57 | BT7: 16459.876 | BU7: 147084.93 | BV7: 102470.9 | BW7: 30170.972 | BX7: 40877.134 | BY7: 152154.09 | BZ7: 108533.88 | CA7: 137454.58 | CB7: 4099.3414 | CC7: 53848.862 | CD7: 5747.4694 | CE7: 8263.451 | CF7: 34350.766 | CG7: 1867651 | CH7: 88769.08 | CI7: 28928.486 | CJ7: 90579.629 | CK7: 19777.643 | CL7: 223463.36 | CM7: 19929.777 | CN7: 36099.489 | CO7: 3515.4357 | CP7: 26965.938 | CQ7: 32727.224 | CR7: 9234.3972 | CS7: 18403.735 | CT7: 2913.7124 | CU7: 1094219.3 | CV7: 73104.103 | CW7: 159658 | CX7: 97608.806 | CY7: 30262.635 | DA7: 12898.073 | DB7: 11425.552 | DC7: 20924.473 | DD7: 146379.18 | DE7: 245143.57 | DF7: 5949.2688 | DG7: 211920.07 | DH7: 10616.626 | DI7: 12977.262 | DJ7: 414874.4 | DK7: 83144.549 | DL7: 16251.511 | DM7: 409117.87 | DN7: 10753.511 | DO7: 5977.527 | DP7: 27787.957 | DQ7: 97456.022 | DR7: 3943.2928 | DS7: 18330.73 | DT7: 9120.7353 | DU7: 8793.783 | DV7: 80130.051 | DW7: 2887.2648 | DX7: 14156.804 | DY7: 5717.802 | DZ7: 3859.9742 | EA7: 418626.31 | EB7: 102682.95 | EC7: 5183.5412 | ED7: 2335.3648 | EE7: 10164.603 | EF7: 7877.5081 | EG7: 10765.586 | EH7: 2036.8835 | EI7: 2317.18 | EJ7: 16163.136 | EK7: 6373.042 | EL7: 3795.2686 | EM7: 3397.5053 | EN7: 12376.017 | EO7: 2772.2827 | EP7: 5593.856 | EQ7: 2801.8719 | ER7: 2465.728 | ES7: 2625.3256 | ET7: 2528.1759 | EV7: 1960.5068 | EW7: 13712.83 | EX7: 11613.037 | EY7: 12425.842 | EZ7: 2945.7449 | FA7: 12814.758 | FB7: 5028.2517 | FC7: 4723.628 | FD7: 5482.8666 | FE7: 3453.7801 | FF7: 3654.728 | FG7: 30421.266 | FH7: 2717.9697 | FI7: 6894.267 | FJ7: 3907.5401 | FK7: 5736.932 | FL7: 9250.4671 | FM7: 4267.6569 | FN7: 8644.3016 | FO7: 2973.25 | FP7: 4103.307 | FR7: 3156.0722 | FS7: 2671.2498 | FT7: 1668.717 | FU7: 5754.724 | FW7: 2495.8957 | FX7: 3466.3648 | FY7: 29343.778 | GA7: 0 | GE7: 0 | GF7: 0 | GG7: 0
A8: 46157 | B8: 9.7713e+09 | C8: 3.1721097e+09 | D8: 2.8857125e+09 | E8: 1.0545491e+09 | F8: 3.9178465e+08 | G8: 2.4377398e+08 | H8: 85460428 | I8: 4.1847633e+08 | J8: 4.7526675e+08 | K8: 2.5601366e+08 | L8: 82229495 | M8: 1.2256605e+08 | N8: 29772650 | O8: 82057386 | P8: 14035706 | Q8: 36160422 | R8: 15918063 | S8: 13731860 | T8: 13513309 | U8: 9800491.5 | V8: 19572086 | W8: 32799538 | X8: 32289616 | Y8: 26754787 | Z8: 12311209 | AA8: 20451684 | AB8: 18192424 | AC8: 13228959 | AD8: 39727727 | AE8: 6742333.2 | AF8: 9204873.7 | AG8: 916119.79 | AH8: 5881852.3 | AI8: 4475403.2 | AJ8: 7412987.1 | AK8: 3177406.6 | AL8: 6253723.9 | AM8: 2429974.6 | AN8: 4773461.7 | AO8: 8735677.7 | AP8: 6926201.5 | AQ8: 5486704.2 | AR8: 11133372 | AS8: 566834.88 | AT8: 850660.53 | AU8: 1001856.3 | AV8: 2707235.2 | AW8: 493986.56 | AX8: 1798339 | AY8: 5703354.8 | AZ8: 2434871.8 | BA8: 138634.69 | BB8: 662190.48 | BC8: 355880.37 | BD8: 404947.01 | BE8: 842790.96 | BF8: 778571.21 | BG8: 354338.61 | BH8: 2763101.7 | BI8: 2518098.8 | BJ8: 1663616.3 | BK8: 222990.56 | BL8: 965736.27 | BM8: 515577.57 | BN8: 1819739.1 | BO8: 416400.84 | BP8: 4481661.8 | BQ8: 3077120.7 | BR8: 134193.03 | BS8: 1785941.4 | BT8: 268811.78 | BU8: 264615.06 | BV8: 1205098.3 | BW8: 435316.12 | BX8: 36675.485 | BY8: 2066681.7 | BZ8: 473304.92 | CA8: 2271585.3 | CB8: 63236.248 | CC8: 1432381.6 | CD8: 234500.47 | CE8: 1009118.3 | CF8: 164733.64 | CG8: 2834590.7 | CH8: 1300626.2 | CI8: 185824.82 | CJ8: 625736.13 | CK8: 816244.19 | CL8: 2194945 | CM8: 1358720.5 | CN8: 94501.326 | CO8: 27868.453 | CP8: 568901.35 | CQ8: 347972.63 | CR8: 458346.68 | CS8: 591405.89 | CT8: 46402.379 | CU8: 970969.66 | CV8: 81150.965 | CW8: 763763.6 | CX8: 127223.44 | CY8: 636101.07 | DA8: 57522.615 | DB8: 1262394.5 | DC8: 45848.692 | DD8: 61495.359 | DE8: 1025917.2 | DF8: 23034.509 | DG8: 244542.29 | DH8: 7853.2043 | DI8: 46962.711 | DJ8: 451453.32 | DK8: 90073.402 | DL8: 18399.147 | DM8: 1076162.2 | DN8: 12509.678 | DO8: 6321.136 | DP8: 222807.38 | DQ8: 125242.34 | DR8: 8858.396 | DS8: 9793.2787 | DT8: 14890.948 | DU8: 15326.849 | DV8: 37561.654 | DW8: 21645.975 | DX8: 208090.59 | DY8: 10065.78 | DZ8: 4008.5273 | EA8: 8600.725 | EB8: 448147.08 | EC8: 18060.957 | ED8: 15378.619 | EE8: 11635.353 | EF8: 7041.4438 | EG8: 16353.348 | EH8: 8134.3673 | EI8: 18634.829 | EJ8: 12240.033 | EK8: 2461.3357 | EL8: 10744.885 | EM8: 8428.0096 | EN8: 14558.941 | EO8: 10142.672 | EP8: 7936.454 | EQ8: 28267.424 | ER8: 4993.1049 | ES8: 43571.37 | ET8: 26526.808 | EV8: 1118.9675 | EW8: 24865.42 | EX8: 11589.935 | EY8: 18632.454 | EZ8: 11402.132 | FA8: 48785.516 | FB8: 4853.0679 | FC8: 4902.312 | FD8: 3983.4972 | FE8: 7928.2624 | FF8: 5701.889 | FG8: 6435.021 | FH8: 3255.3566 | FI8: 6593.098 | FJ8: 4322.2262 | FK8: 6647.093 | FL8: 7299.7842 | FM8: 6002.7835 | FN8: 2290.7901 | FO8: 3435.8314 | FP8: 5692.4089 | FR8: 10720.38 | FS8: 6292.5252 | FT8: 3029.8536 | FU8: 6799.975 | FW8: 7225.3469 | FX8: 9558.8111 | FY8: 2908.2681 | GA8: 378.58904 | GE8: 0 | GF8: 0 | GG8: 0
A9: 46156 | B9: 7.1033667e+09 | C9: 1.855873e+09 | D9: 2.1279618e+09 | E9: 9.3678294e+08 | F9: 2.5243052e+08 | G9: 3.1014604e+08 | H9: 81373255 | I9: 3.179578e+08 | J9: 2.4947167e+08 | K9: 2.4982685e+08 | L9: 1.0312398e+08 | M9: 1.1756601e+08 | N9: 56260016 | O9: 33963063 | P9: 17640126 | Q9: 50989508 | R9: 11117196 | S9: 14788894 | T9: 10724684 | U9: 8258428.2 | V9: 18671122 | W9: 29480348 | X9: 32211031 | Y9: 10639363 | Z9: 9647292.9 | AA9: 17805610 | AB9: 11254950 | AC9: 10814121 | AD9: 13993151 | AE9: 5784499 | AF9: 11089036 | AG9: 428338.46 | AH9: 4534111.7 | AI9: 3854921.5 | AJ9: 13566577 | AK9: 4700284.2 | AL9: 3962213.1 | AM9: 3461504.3 | AN9: 5723052.7 | AO9: 5219828.6 | AP9: 9998809.4 | AQ9: 8133153.7 | AR9: 3961786.7 | AS9: 493057.96 | AT9: 717010.97 | AU9: 1039414 | AV9: 1245121 | AW9: 773540.64 | AX9: 2463877.8 | AY9: 2582933 | AZ9: 3888616.8 | BA9: 151540.14 | BB9: 525038.04 | BC9: 227703.5 | BD9: 277919.49 | BE9: 1199240.5 | BF9: 1282886.5 | BG9: 467337.65 | BH9: 1848011 | BI9: 3353170.5 | BJ9: 2328387 | BK9: 84183.605 | BL9: 696699.74 | BM9: 342511.43 | BN9: 833594.56 | BO9: 372871.32 | BP9: 1409518.9 | BQ9: 2155593.6 | BR9: 83227.407 | BS9: 2350960.5 | BT9: 137429.94 | BU9: 346454.66 | BV9: 511465.55 | BW9: 40720.578 | BX9: 83219.103 | BY9: 1933949.3 | BZ9: 151997.97 | CA9: 861042.2 | CB9: 18746.305 | CC9: 483531.34 | CD9: 69037.115 | CE9: 207598.24 | CF9: 317829.99 | CG9: 200751.44 | CH9: 3468014.5 | CI9: 66831.858 | CJ9: 319209.31 | CK9: 1281112.8 | CL9: 1327510.9 | CM9: 2238889.4 | CN9: 20159.519 | CO9: 134766.99 | CP9: 1443545 | CQ9: 1269674.3 | CR9: 338852.89 | CS9: 1114049.4 | CT9: 144929.21 | CU9: 1396881.1 | CV9: 55335.157 | CW9: 881521.51 | CX9: 66449.012 | CY9: 114288.93 | DA9: 26581.444 | DB9: 579674.32 | DC9: 32804.527 | DD9: 23534.385 | DE9: 6181.3882 | DF9: 34377.528 | DG9: 101060.41 | DH9: 7700.7464 | DI9: 121074.7 | DJ9: 5506.191 | DK9: 84858.905 | DL9: 14864.097 | DM9: 9870.975 | DN9: 12456.188 | DO9: 10012.989 | DP9: 350896.47 | DQ9: 368734.15 | DR9: 17808.853 | DS9: 13579.224 | DT9: 12007.532 | DU9: 24863.093 | DV9: 58424.113 | DW9: 140211.11 | DX9: 271458.93 | DY9: 8195.3139 | DZ9: 4624.8916 | EA9: 7666.4404 | EB9: 784227.56 | EC9: 13828.521 | ED9: 13512.123 | EE9: 15132.75 | EF9: 7615.1621 | EG9: 21411.386 | EH9: 4202.3674 | EI9: 60331.278 | EJ9: 6510.8613 | EK9: 7422.5828 | EL9: 23011.074 | EM9: 4169.1286 | EN9: 14488.069 | EO9: 11373.886 | EP9: 8006.15 | EQ9: 34630.628 | ER9: 2510.708 | ES9: 3153.9907 | ET9: 75461.289 | EV9: 263.2005 | EW9: 27089.08 | EX9: 11762.392 | EY9: 13386.424 | EZ9: 235838.13 | FA9: 34439.708 | FB9: 24852.74 | FC9: 12381.614 | FD9: 2534.9601 | FE9: 1935.1228 | FF9: 3933.786 | FG9: 7186.784 | FH9: 2879.3521 | FI9: 9582.963 | FJ9: 4863.6613 | FK9: 27479.152 | FL9: 4100.5296 | FM9: 4821.5753 | FN9: 7486.5322 | FO9: 3214.0409 | FP9: 4497.8166 | FR9: 5485.7821 | FS9: 5631.0367 | FT9: 1661.0411 | FU9: 6395.361 | FW9: 2542.6376 | FX9: 5994.8841 | FY9: 3768.3367 | GA9: 0 | GE9: 0 | GF9: 0 | GG9: 0
A10: 46155 | B10: 7.0803498e+09 | C10: 1.4044272e+09 | D10: 2.0411772e+09 | E10: 1.109374e+09 | F10: 2.7881095e+08 | G10: 2.5169194e+08 | H10: 1.1447906e+08 | I10: 5.3935624e+08 | J10: 4.0815698e+08 | K10: 1.707138e+08 | L10: 60465831 | M10: 1.8385444e+08 | N10: 29241498 | O10: 62490337 | P10: 14644194 | Q10: 49004282 | R10: 9455167.8 | S10: 15204095 | T10: 13277481 | U10: 7695239.2 | V10: 26541163 | W10: 21501782 | X10: 49613294 | Y10: 11239632 | Z10: 12438768 | AA10: 9249905.4 | AB10: 21447575 | AC10: 10275302 | AD10: 882146.57 | AE10: 5255223.7 | AF10: 6934475.4 | AG10: 469248.3 | AH10: 3174012.7 | AI10: 1333669.8 | AJ10: 26909962 | AK10: 3686286.1 | AL10: 5519766.9 | AM10: 2743900.9 | AN10: 4945694 | AO10: 11407974 | AP10: 13668976 | AQ10: 3403365.8 | AR10: 5425484.2 | AS10: 762877.99 | AT10: 826280.05 | AU10: 845010.49 | AV10: 1534162.4 | AW10: 706874.7 | AX10: 1528712 | AY10: 1238803.4 | AZ10: 4167383.2 | BA10: 259164.45 | BB10: 322742.81 | BC10: 342153.78 | BD10: 207225.85 | BE10: 1553971.5 | BF10: 2499874.6 | BG10: 511701.72 | BH10: 1668287.5 | BI10: 2605061 | BJ10: 2109655.7 | BK10: 136633.38 | BL10: 1074499 | BM10: 1562248.3 | BN10: 1334096.9 | BO10: 1371717 | BP10: 802225.93 | BQ10: 3431570.1 | BR10: 157365.96 | BS10: 505487.74 | BT10: 251264.66 | BU10: 295414.42 | BV10: 733129.33 | BW10: 45721.474 | BX10: 116898.46 | BY10: 2483872.6 | BZ10: 272477.44 | CA10: 1156732.4 | CB10: 80098.375 | CC10: 266636.9 | CD10: 100219.99 | CE10: 306882.77 | CF10: 242293.17 | CG10: 483227.09 | CH10: 2249200.3 | CI10: 125036.96 | CJ10: 369712.75 | CK10: 987724.32 | CL10: 1992099.5 | CM10: 3561192.2 | CN10: 45578.748 | CO10: 608828.65 | CP10: 1221675.4 | CQ10: 269478.45 | CR10: 410480.88 | CS10: 250593.81 | CT10: 334582.05 | CU10: 86700.784 | CV10: 82787.133 | CW10: 1333083.4 | CX10: 76734.883 | CY10: 322735.5 | DA10: 40596.861 | DB10: 541335.64 | DC10: 10925.259 | DD10: 70291.697 | DF10: 47305.562 | DG10: 180614.62 | DH10: 6248.1725 | DI10: 67697.624 | DJ10: 15727.523 | DK10: 59769.967 | DL10: 16295.761 | DM10: 8715.501 | DN10: 17232.546 | DO10: 7368.583 | DP10: 107669.59 | DQ10: 411006.16 | DR10: 28153.604 | DS10: 11856.841 | DT10: 15115.004 | DV10: 218011.12 | DW10: 639963.5 | DX10: 148904.28 | DY10: 9513.9207 | DZ10: 6248.7258 | EA10: 4316.616 | EC10: 15275.459 | ED10: 37014.945 | EE10: 75707.439 | EF10: 9494.8968 | EG10: 18904.332 | EH10: 4504.1804 | EI10: 19817.624 | EJ10: 9921.3666 | EK10: 10898.097 | EL10: 36995.561 | EM10: 3874.5179 | EN10: 20073.382 | EO10: 4950.2936 | EP10: 9089.749 | EQ10: 9288.4048 | ER10: 33310.447 | ES10: 3157.7346 | ET10: 8598.3783 | EV10: 0 | EW10: 20306.079 | EX10: 11506.082 | EY10: 17522.731 | EZ10: 21457.743 | FA10: 275871.16 | FB10: 18748.563 | FC10: 6927.959 | FD10: 2715.1444 | FE10: 2779.915 | FF10: 4543.142 | FG10: 27028.429 | FH10: 3222.0832 | FI10: 8411.13 | FJ10: 7569.1548 | FK10: 5830.859 | FL10: 11514.261 | FM10: 4923.031 | FN10: 4546.0356 | FO10: 3909.7095 | FP10: 4030.7234 | FR10: 6464.2144 | FS10: 3412.2613 | FT10: 1641.6303 | FU10: 7399.278 | FW10: 14153.753 | FX10: 5661.7695 | FY10: 8868.6415 | GA10: 617.92341 | GE10: 0 | GF10: 0 | GG10: 0
A11: 46154 | B11: 9.1805284e+09 | C11: 2.6367219e+09 | D11: 2.3263627e+09 | E11: 1.4281229e+09 | F11: 3.9481367e+08 | G11: 4.5686387e+08 | H11: 1.2110264e+08 | I11: 4.176653e+08 | J11: 4.1335436e+08 | K11: 1.4216706e+08 | L11: 73105667 | M11: 2.033353e+08 | N11: 44503566 | O11: 95411534 | P11: 14777045 | Q11: 47936299 | R11: 8038245.1 | S11: 13108361 | T11: 13743630 | U11: 7854663 | V11: 23277854 | W11: 29228989 | X11: 53021642 | Y11: 26755949 | Z11: 7345844.8 | AA11: 8931711 | AB11: 17544934 | AC11: 6868820.3 | AD11: 329014.73 | AE11: 4510670.4 | AF11: 8509329.9 | AG11: 398004.77 | AH11: 4037965.7 | AI11: 1111298.1 | AJ11: 2902901.1 | AK11: 4670860.1 | AL11: 2691171.4 | AM11: 2955714.9 | AN11: 8108761.3 | AO11: 10280473 | AP11: 16083602 | AQ11: 3725440.6 | AR11: 10027357 | AS11: 1142040.3 | AT11: 1099892.2 | AU11: 759638.98 | AV11: 1846945.6 | AW11: 1124399.9 | AX11: 1508465.3 | AY11: 3753336.3 | AZ11: 4095207.6 | BA11: 273542.89 | BB11: 603799.77 | BC11: 381603.55 | BD11: 297695.19 | BE11: 2182946 | BF11: 2865400.3 | BG11: 427663.19 | BH11: 3592975.7 | BI11: 2021717.1 | BJ11: 4261029.8 | BK11: 151515.64 | BL11: 715943.4 | BM11: 598580.1 | BN11: 1231880.3 | BO11: 1149098.7 | BP11: 2895696.2 | BQ11: 1490174.8 | BR11: 193527.8 | BS11: 440360.46 | BT11: 80857.436 | BU11: 546349.25 | BV11: 693446.99 | BW11: 146601.02 | BX11: 88402.485 | BY11: 2362905 | BZ11: 357010.29 | CA11: 1339223.7 | CB11: 114979.63 | CC11: 505953.87 | CD11: 142847.64 | CE11: 751931.63 | CF11: 979210.3 | CG11: 173931.43 | CH11: 4424046 | CI11: 444344.03 | CJ11: 297899.3 | CK11: 2959565.3 | CL11: 1503544.7 | CM11: 2159032.6 | CN11: 23826.076 | CO11: 410664.7 | CP11: 1538132.1 | CQ11: 299265.42 | CR11: 226679.54 | CS11: 180899.31 | CT11: 47706.243 | CU11: 49418.783 | CV11: 102913.41 | CW11: 2120779.1 | CX11: 98100.349 | CY11: 29835.272 | DA11: 61142.773 | DC11: 21359.332 | DD11: 26954.969 | DF11: 12609.588 | DG11: 370976.34 | DH11: 17846.963 | DI11: 40459.729 | DK11: 31848.165 | DL11: 37000.443 | DN11: 11355.733 | DO11: 6224.253 | DP11: 137248.18 | DQ11: 76499.417 | DR11: 20060.878 | DS11: 9951.8615 | DT11: 11307.753 | DV11: 233718.83 | DW11: 30961.743 | DX11: 256712.49 | DY11: 10124.613 | DZ11: 13304.263 | EA11: 2568.8884 | EC11: 7839.0893 | ED11: 6611.9933 | EE11: 20566.171 | EF11: 14219.984 | EG11: 27772.984 | EH11: 3543.2827 | EI11: 7452.0301 | EJ11: 3951.3545 | EK11: 3637.0009 | EL11: 26222.89 | EM11: 14350.352 | EN11: 19070.108 | EO11: 18768.946 | EP11: 20156.21 | EQ11: 3297.0955 | ER11: 4745.5714 | ES11: 6521.2157 | ET11: 7088.6657 | EV11: 0 | EW11: 14081.341 | EX11: 12901.591 | EY11: 14258.596 | EZ11: 12378.377 | FB11: 59952.261 | FC11: 5372.107 | FD11: 3615.9744 | FE11: 2796.0784 | FF11: 3893.316 | FG11: 15416.201 | FH11: 3689.0337 | FI11: 13756.804 | FJ11: 10548.47 | FK11: 7056.304 | FL11: 9449.4706 | FM11: 4372.7603 | FN11: 10139.857 | FO11: 3777.5558 | FP11: 6629.8277 | FR11: 9586.1967 | FS11: 6235.6782 | FT11: 2607.8629 | FU11: 11181.055 | FW11: 5727.0748 | FX11: 6953.204 | FY11: 3080.0297 | GA11: 618.3667 | GE11: 0 | GF11: 0 | GG11: 0
A12: 46153 | B12: 8.0185646e+09 | C12: 2.029449e+09 | D12: 2.1516841e+09 | E12: 1.0507551e+09 | F12: 3.2596877e+08 | G12: 6.2590165e+08 | H12: 99695151 | I12: 3.6775953e+08 | J12: 4.5238905e+08 | K12: 1.2513303e+08 | L12: 79636433 | M12: 2.1149689e+08 | N12: 53876499 | O12: 43370163 | P12: 20582855 | Q12: 62158680 | R12: 6770254.4 | S12: 14103276 | T12: 12274645 | U12: 6439792.9 | V12: 14642082 | W12: 20234638 | X12: 50783632 | Y12: 22932359 | Z12: 5432191.9 | AA12: 7058639.7 | AB12: 16041029 | AC12: 6387224.6 | AE12: 5916998.4 | AF12: 7057250.8 | AG12: 773034.25 | AH12: 3649892.5 | AI12: 2201075.3 | AJ12: 2691127.5 | AK12: 5595362.5 | AL12: 2745098.3 | AM12: 3636020.2 | AN12: 9499812.2 | AO12: 11790750 | AP12: 20669857 | AQ12: 2892478.8 | AR12: 4625734.6 | AS12: 1271554.9 | AT12: 910793.81 | AU12: 539459.39 | AV12: 1430033.1 | AW12: 793565.85 | AX12: 1027749.8 | AY12: 1408095.8 | AZ12: 3569141.8 | BA12: 389907.4 | BB12: 353930.47 | BC12: 568892.91 | BD12: 337714.92 | BE12: 3834673 | BF12: 2938603.1 | BG12: 651451.15 | BH12: 2899744 | BI12: 2926534.7 | BJ12: 1603435 | BK12: 225533.43 | BL12: 1037014 | BM12: 868815.97 | BN12: 619785.3 | BO12: 184206.02 | BP12: 2604773.1 | BQ12: 969143.77 | BR12: 457283.43 | BS12: 409872.75 | BT12: 160581.75 | BU12: 414227.46 | BV12: 295748.91 | BW12: 69786.944 | BX12: 76053.806 | BY12: 673219.9 | BZ12: 213373.13 | CA12: 868968.37 | CB12: 142477.19 | CC12: 27895.88 | CD12: 111954.43 | CE12: 154607.42 | CF12: 2081791 | CG12: 29166.514 | CH12: 828870.38 | CI12: 701421.18 | CJ12: 317634.26 | CK12: 866631.8 | CL12: 1605519.7 | CM12: 1149027.9 | CN12: 22966.677 | CO12: 284373.96 | CP12: 910545.74 | CQ12: 450074.79 | CR12: 626275.61 | CS12: 78140.621 | CT12: 37002.549 | CU12: 60408.295 | CV12: 88593.06 | CW12: 83471.541 | CX12: 250701.92 | CY12: 74000.284 | DA12: 46602.724 | DC12: 17817.937 | DD12: 15780.488 | DF12: 9402.1305 | DG12: 1422582.3 | DH12: 9348.8153 | DI12: 51506.224 | DK12: 46203.716 | DL12: 15975.065 | DN12: 12295.37 | DO12: 12923.243 | DP12: 110729.29 | DQ12: 448960.58 | DR12: 10956.27 | DS12: 10998.962 | DT12: 18744.741 | DV12: 244305.77 | DW12: 3441.185 | DX12: 130041.26 | DY12: 6783.3403 | DZ12: 7065.1254 | EA12: 4561.425 | EC12: 24973.894 | ED12: 5843.5979 | EE12: 9423.488 | EF12: 6412.2956 | EG12: 38599.151 | EH12: 3343.4797 | EI12: 5022.7278 | EJ12: 4859.0664 | EK12: 5290.7303 | EL12: 15676.977 | EM12: 6416.8453 | EN12: 23035.309 | EO12: 17497.023 | EP12: 17037.341 | EQ12: 7185.3996 | ER12: 23077.474 | ES12: 29315.006 | ET12: 7928.8641 | EV12: 0 | EW12: 12074.965 | EX12: 13936.647 | EY12: 12477.975 | EZ12: 2394.4232 | FB12: 83305.606 | FC12: 5349.778 | FD12: 2698.9112 | FE12: 115425.96 | FF12: 3792.841 | FG12: 37064.136 | FH12: 3940.7856 | FI12: 9564.049 | FJ12: 4820.4284 | FK12: 5724.515 | FL12: 6120.2689 | FM12: 5436.8852 | FN12: 3079.9417 | FO12: 3087.5235 | FP12: 4293.3919 | FR12: 4299.4475 | FS12: 3319.3822 | FT12: 2684.0619 | FU12: 8840.252 | FW12: 3101.8925 | FX12: 8767.4838 | FY12: 2618.8162 | GA12: 0 | GE12: 0 | GF12: 0 | GG12: 0
A13: 46152 | B13: 1.6838098e+09 | C13: 4.2822009e+08 | D13: 3.539857e+08 | E13: 4.3695853e+08 | F13: 1.2351925e+08 | G13: 31604175 | H13: 16348587 | I13: 37347702 | J13: 24307631 | K13: 23363649 | L13: 25577760 | M13: 22130035 | N13: 6404008.1 | O13: 13969449 | P13: 3471868.6 | Q13: 10604513 | R13: 2753580.4 | S13: 3011945.9 | T13: 2404590.3 | U13: 3651585.6 | V13: 5471797.8 | W13: 14953397 | X13: 11302039 | Y13: 647187.55 | Z13: 2548355.9 | AA13: 2568218.3 | AB13: 23618532 | AC13: 6345502.2 | AE13: 1345990.4 | AF13: 1349672.6 | AG13: 907488.9 | AH13: 992390.82 | AI13: 9830135.5 | AJ13: 1498733.6 | AK13: 1127115.8 | AL13: 291597.7 | AM13: 373171.72 | AN13: 1097733.2 | AO13: 2939333.7 | AP13: 3699556.6 | AQ13: 1517692.9 | AR13: 928057.2 | AS13: 208041.52 | AT13: 1525813 | AU13: 587457.43 | AV13: 450293.25 | AW13: 108091.68 | AX13: 478959.17 | AY13: 52415.333 | AZ13: 175311.03 | BA13: 515786.48 | BB13: 51709.787 | BC13: 250304.66 | BD13: 76388.196 | BE13: 3660445.4 | BF13: 6191054.1 | BG13: 86629.904 | BH13: 24115.429 | BI13: 709504.68 | BJ13: 378929.77 | BK13: 49038.754 | BL13: 14358.135 | BM13: 272887.07 | BN13: 78526.604 | BO13: 8630.9083 | BP13: 71810.113 | BQ13: 36583.574 | BR13: 40381.279 | BS13: 134008.38 | BT13: 43106.432 | BU13: 493553.16 | BV13: 131817.73 | BW13: 12082.071 | BX13: 160554.11 | BY13: 55694.949 | BZ13: 53463.967 | CA13: 58673.268 | CB13: 40090.236 | CC13: 10230.207 | CD13: 2042.4282 | CE13: 37886.964 | CF13: 26301.907 | CG13: 19329.388 | CI13: 207787.73 | CJ13: 22264.953 | CK13: 6150.1018 | CN13: 36478.657 | CO13: 7756.3062 | CP13: 120820.71 | CQ13: 110898.03 | CR13: 57692.81 | CS13: 28577.515 | CT13: 3636.9462 | CU13: 27699.896 | CV13: 61309.858 | CW13: 12748.462 | CX13: 113861.82 | CY13: 9482.8 | DA13: 11709.397 | DC13: 9117.5843 | DD13: 14835.217 | DF13: 6059.5964 | DH13: 8317.3266 | DI13: 15342.095 | DK13: 57791.346 | DL13: 16554.559 | DN13: 12050.427 | DO13: 6205.075 | DP13: 12819.945 | DR13: 4869.2587 | DS13: 13470.132 | DT13: 9391.6409 | DV13: 23515.918 | DW13: 2352.5894 | DX13: 49801.046 | DY13: 8183.1273 | DZ13: 7360.8971 | EA13: 6334.346 | EC13: 5603.2167 | ED13: 2499.7574 | EE13: 10338.807 | EF13: 14630.828 | EG13: 16768.824 | EH13: 18183.463 | EI13: 6275.5301 | EJ13: 8920.0804 | EK13: 2021.5964 | EL13: 7915.784 | EM13: 4165.4448 | EN13: 14503.445 | EO13: 3118.6798 | EP13: 13400.984 | EQ13: 2995.4758 | ER13: 3329.9649 | ES13: 2744.751 | ET13: 3797.1572 | EV13: 0 | EW13: 11135.002 | EX13: 12266.694 | EY13: 16043.052 | EZ13: 3330.7467 | FB13: 22776.487 | FC13: 7031.009 | FD13: 2721.8853 | FE13: 1960.1576 | FF13: 4249.649 | FG13: 9809.501 | FH13: 4711.3682 | FI13: 7031.853 | FJ13: 3729.6581 | FK13: 5635.826 | FL13: 3872.7588 | FM13: 3993.5421 | FN13: 2906.4817 | FO13: 3053.5837 | FP13: 4240.2079 | FR13: 11034.366 | FS13: 7891.3394 | FT13: 8747.0085 | FU13: 5575.081 | FW13: 2411.0426 | FX13: 4379.5915 | FY13: 4132.3824 | GA13: 0 | GE13: 0 | GF13: 0 | GG13: 0
A14: 46151 | B14: 5.6281653e+08 | C14: 1.068298e+08 | D14: 45100664 | E14: 1.3283842e+08 | F14: 36422299 | G14: 16172828 | H14: 7191090 | I14: 19549218 | J14: 17310398 | K14: 13471328 | L14: 8325706.1 | M14: 9321589.9 | N14: 3387931.9 | O14: 8423073.8 | P14: 1376349.4 | Q14: 6706759.6 | R14: 1484115.3 | S14: 983558.94 | T14: 904393.07 | U14: 1142281.8 | V14: 3180784.6 | W14: 8593004.4 | X14: 4354749.6 | Y14: 244410.79 | Z14: 1186376.5 | AA14: 1767021.9 | AB14: 4120753.7 | AC14: 44806652 | AE14: 837209.83 | AF14: 1370477.1 | AG14: 1300826.4 | AH14: 676846.97 | AI14: 17807734 | AJ14: 499631.91 | AK14: 852723.03 | AL14: 165584.21 | AM14: 126399.91 | AN14: 881492.69 | AO14: 5090425.9 | AP14: 819538.19 | AQ14: 880692.21 | AR14: 1753877.6 | AS14: 247339.35 | AT14: 2065158.5 | AU14: 314591.12 | AV14: 122737.23 | AW14: 115470.68 | AX14: 467629.02 | AY14: 47888.859 | AZ14: 239229.01 | BA14: 1679091 | BB14: 17558.558 | BC14: 535852.83 | BD14: 42285.484 | BE14: 4934304.8 | BF14: 8898455.4 | BG14: 54934.023 | BH14: 90743.791 | BI14: 623417.18 | BJ14: 339090.37 | BK14: 43284.187 | BL14: 63847.052 | BM14: 144680.18 | BN14: 194373.11 | BO14: 5764.43 | BP14: 40261.661 | BQ14: 36203.053 | BR14: 229431.41 | BS14: 132072.48 | BT14: 20237.439 | BU14: 620995.26 | BV14: 150665.18 | BW14: 19453.901 | BX14: 249085.26 | BY14: 47022.467 | BZ14: 11694.393 | CA14: 33268.398 | CB14: 16887.453 | CC14: 14024.491 | CD14: 3399.9035 | CE14: 12060.724 | CF14: 251912.64 | CG14: 16950.39 | CI14: 35367.811 | CJ14: 48216.78 | CK14: 48445.807 | CN14: 30550.715 | CO14: 32531.228 | CP14: 43834.883 | CQ14: 22159.699 | CR14: 117494.17 | CS14: 4270.5759 | CT14: 6419.4285 | CU14: 24925.862 | CV14: 76038.871 | CW14: 16417.14 | CX14: 80493.816 | CY14: 21585.555 | DA14: 11685.333 | DC14: 10676.258 | DD14: 15346.869 | DF14: 8835.7966 | DH14: 9126.808 | DI14: 21141.186 | DK14: 38159.299 | DL14: 22946.456 | DN14: 12210.448 | DO14: 6216.068 | DP14: 15475.392 | DR14: 5979.8114 | DS14: 9661.9875 | DT14: 9345.6711 | DV14: 21841.038 | DW14: 2135.0312 | DX14: 32953.272 | DY14: 5644.5348 | DZ14: 20158.15 | EA14: 17.8104 | EC14: 5779.1985 | ED14: 2716.5544 | EE14: 6043.325 | EF14: 34866.091 | EG14: 17841.359 | EH14: 16938.843 | EI14: 1897.2713 | EJ14: 6991.4923 | EK14: 2454.6925 | EL14: 21964.176 | EM14: 11622.389 | EN14: 14210.608 | EO14: 4006.1016 | EP14: 14680.519 | EQ14: 4639.3504 | ER14: 2679.2533 | ES14: 4492.862 | ET14: 2890.8727 | EV14: 0 | EW14: 15583.913 | EX14: 21651.223 | EY14: 27455.794 | EZ14: 3416.3297 | FB14: 22240.342 | FC14: 6298.568 | FD14: 3077.1888 | FE14: 8781.5213 | FF14: 12675.543 | FG14: 15933.129 | FH14: 11311.928 | FI14: 10702.862 | FJ14: 5417.6866 | FK14: 6639.617 | FL14: 4907.7883 | FM14: 4886.1213 | FN14: 13994.846 | FO14: 4981.5194 | FP14: 32223.106 | FR14: 6631.7753 | FS14: 9232.6538 | FT14: 4689.1928 | FU14: 14260.411 | FW14: 2610.2364 | FX14: 25599.668 | FY14: 3937.8932 | GA14: 0 | GE14: 0 | GF14: 0 | GG14: 0
A15: 46150 | B15: 5.8766396e+09 | C15: 1.5231662e+09 | D15: 1.2223399e+09 | E15: 1.2445352e+09 | F15: 5.6590194e+08 | G15: 1.0352719e+08 | H15: 80783942 | I15: 1.1825771e+08 | J15: 2.0589982e+08 | K15: 89571264 | L15: 57959959 | M15: 1.9095013e+08 | N15: 32094999 | O15: 29107246 | P15: 16302871 | Q15: 1.1374528e+08 | R15: 9017519.7 | S15: 9001923.8 | T15: 13326716 | U15: 6354095.5 | V15: 10704389 | W15: 25885593 | X15: 28906496 | Y15: 8092508.9 | Z15: 6816403.1 | AA15: 9295992.9 | AB15: 7912971.5 | AC15: 8037547.1 | AE15: 5944246.9 | AF15: 7704419.2 | AG15: 996707.18 | AH15: 5178294.1 | AI15: 22729876 | AJ15: 2323845.2 | AK15: 6244291.2 | AL15: 1284618.2 | AM15: 3525582.3 | AN15: 10221932 | AO15: 3435655.1 | AP15: 9374455.2 | AQ15: 4397669.5 | AR15: 3178351.5 | AS15: 357663.94 | AT15: 940969.83 | AU15: 1744412.6 | AV15: 1695549.6 | AW15: 1542288.9 | AX15: 1408823.6 | AY15: 4180665 | AZ15: 4888696.5 | BA15: 823035.45 | BB15: 1308116.2 | BC15: 418139.03 | BD15: 219340.3 | BE15: 2490429.8 | BF15: 5633970.1 | BG15: 569022.98 | BH15: 2245251.2 | BI15: 2014203.2 | BJ15: 3856875.1 | BK15: 261370.07 | BL15: 1613306 | BM15: 850868.66 | BN15: 932697.84 | BO15: 96469.55 | BP15: 844030.94 | BQ15: 665090.67 | BR15: 412800.33 | BS15: 382063.12 | BT15: 76478.229 | BU15: 426960.43 | BV15: 763521.16 | BW15: 94840.547 | BX15: 182887.74 | BY15: 704000.93 | BZ15: 123002.22 | CA15: 1102954.9 | CB15: 190870.72 | CC15: 113498.2 | CD15: 122925.56 | CE15: 370397.33 | CF15: 191877.32 | CG15: 54435.526 | CI15: 49598.358 | CJ15: 133094.43 | CK15: 607481.86 | CN15: 29616.729 | CO15: 492762.22 | CP15: 275204.56 | CQ15: 230176.27 | CR15: 1489645.7 | CS15: 256086.2 | CT15: 80586.319 | CU15: 66704.503 | CV15: 74730.158 | CW15: 45041.676 | CX15: 114487.47 | CY15: 45810.312 | DA15: 49065.792 | DC15: 30423.202 | DD15: 20429.295 | DF15: 10124.833 | DH15: 16879.524 | DI15: 117137.08 | DK15: 135078.19 | DL15: 22004.786 | DN15: 12949.015 | DO15: 6294.352 | DP15: 36845.11 | DR15: 19511.409 | DS15: 9789.3406 | DT15: 15679.522 | DV15: 121028.54 | DW15: 4683.389 | DX15: 169521.15 | DY15: 9897.1093 | DZ15: 21750.818 | EA15: 1500.256 | EC15: 17431.741 | ED15: 11144.285 | EE15: 19665.982 | EF15: 30328.102 | EG15: 80447.408 | EH15: 11319.602 | EI15: 7798.8822 | EJ15: 5052.7668 | EK15: 27158.15 | EL15: 44922.418 | EM15: 53736.906 | EN15: 22862.794 | EO15: 4770.0722 | EP15: 27269.172 | EQ15: 11366.114 | ER15: 4469.8948 | ES15: 3775.149 | ET15: 4916.2399 | EV15: 0 | EW15: 17549.871 | EX15: 22775.528 | EY15: 16870.178 | EZ15: 5098.1912 | FB15: 32390.594 | FC15: 6957 | FD15: 22725.822 | FE15: 8390.5435 | FF15: 30008.306 | FG15: 49754.465 | FH15: 19108.185 | FI15: 22450.451 | FJ15: 20740.182 | FK15: 5920.37 | FL15: 52183.754 | FM15: 5091.1371 | FN15: 15777.951 | FO15: 3849.1421 | FP15: 12771.758 | FR15: 38836.873 | FS15: 4479.6119 | FT15: 12145.385 | FU15: 11660.227 | FW15: 8869.0731 | FX15: 25019.631 | FY15: 7571.0976 | GA15: 0 | GE15: 0 | GF15: 0 | GG15: 0
A16: 46149 | B16: 8.4486545e+09 | C16: 2.3050121e+09 | D16: 1.757482e+09 | E16: 2.1638788e+09 | F16: 9.5581727e+08 | G16: 1.3429262e+08 | H16: 84312939 | I16: 95809535 | J16: 1.7494768e+08 | K16: 1.5602707e+08 | L16: 56386424 | M16: 1.0004536e+08 | N16: 50420753 | O16: 31436364 | P16: 21192293 | Q16: 58491523 | R16: 10288889 | S16: 11947688 | T16: 19608200 | U16: 8233990.8 | V16: 16746725 | W16: 20636180 | X16: 27941493 | Y16: 24694906 | Z16: 7687246.2 | AA16: 11400549 | AB16: 7955667.2 | AC16: 9075087.6 | AE16: 4049164.3 | AF16: 8680719.6 | AG16: 530161.35 | AH16: 7523861.9 | AI16: 5366609.5 | AJ16: 3388666.4 | AK16: 7985932.7 | AL16: 1983356.9 | AM16: 7634879.9 | AN16: 4212842.7 | AP16: 7337428.2 | AQ16: 4239724.5 | AR16: 2910200.7 | AS16: 604900.41 | AT16: 1883115.6 | AU16: 1283289.5 | AV16: 2300528.4 | AW16: 2407684.9 | AX16: 1264471.5 | AY16: 865737.41 | AZ16: 4119001.5 | BA16: 1512535.3 | BB16: 3200697 | BC16: 367486.44 | BD16: 298867.03 | BE16: 6414005.8 | BF16: 4493516.3 | BG16: 711820.35 | BH16: 3377672.9 | BI16: 2754010.9 | BJ16: 3240559.9 | BK16: 288501.7 | BL16: 1254181.9 | BM16: 1155608.9 | BN16: 808644.39 | BO16: 214000.59 | BP16: 1501919 | BQ16: 1568638.7 | BR16: 775157.45 | BS16: 170430.85 | BT16: 176364.74 | BU16: 407807.59 | BV16: 777202.53 | BW16: 200203.32 | BX16: 265054.04 | BY16: 1157753.3 | BZ16: 153969.11 | CA16: 577102.44 | CB16: 163982.07 | CC16: 135602.21 | CD16: 127000.56 | CE16: 512412.57 | CF16: 235945.69 | CG16: 52098.408 | CI16: 82363.13 | CJ16: 192931.55 | CK16: 1309128.2 | CN16: 9366.739 | CO16: 123249.6 | CP16: 630629.64 | CQ16: 518249.38 | CR16: 1139393.3 | CS16: 202356.63 | CT16: 55263.512 | CU16: 175222.62 | CV16: 169461.61 | CW16: 51307.433 | CX16: 116734.99 | CY16: 13125.299 | DA16: 83126.198 | DC16: 35056.573 | DD16: 26849.885 | DF16: 19508.893 | DH16: 44093.57 | DI16: 203966.39 | DK16: 197467.83 | DL16: 45539.376 | DN16: 35195.889 | DO16: 9766.609 | DP16: 27935.593 | DR16: 20468.103 | DS16: 20752.064 | DT16: 13467.275 | DV16: 128895.71 | DW16: 7222.8729 | DX16: 159653.29 | DY16: 9975.8835 | DZ16: 7726.5413 | EA16: 5926.25 | EC16: 17761.197 | ED16: 4065.3946 | EE16: 29556.155 | EF16: 13028.282 | EG16: 190859.38 | EH16: 29683.827 | EI16: 6076.8381 | EJ16: 11233.576 | EK16: 59956.588 | EL16: 75545.561 | EM16: 26997.807 | EN16: 31276.999 | EO16: 9141.7663 | EP16: 42289.131 | EQ16: 10451.761 | ER16: 3776.1552 | ES16: 4045.8165 | ET16: 15146.749 | EV16: 810.17677 | EW16: 21259.636 | EX16: 18699.463 | EY16: 22017.32 | EZ16: 18156.754 | FB16: 20344.414 | FC16: 8535.737 | FD16: 56940.677 | FE16: 3952.5268 | FF16: 37899.816 | FG16: 57515.288 | FH16: 6852.8964 | FI16: 58005.588 | FJ16: 32138.241 | FK16: 9097.55 | FL16: 168461.95 | FM16: 10017.445 | FN16: 14088.207 | FO16: 11485.054 | FP16: 6610.3009 | FR16: 87960.212 | FS16: 7101.3326 | FT16: 37799.219 | FU16: 19681.908 | FW16: 11220.437 | FX16: 36294.534 | FY16: 6806.0756 | GA16: 0 | GE16: 0 | GF16: 0 | GG16: 0
A17: 46148 | B17: 8.6882409e+09 | C17: 2.6259339e+09 | D17: 1.3238821e+09 | E17: 2.5706331e+09 | F17: 9.150707e+08 | G17: 1.587216e+08 | H17: 62021242 | I17: 93896960 | J17: 1.6885419e+08 | K17: 1.3642872e+08 | L17: 93439282 | M17: 1.1595349e+08 | N17: 26858212 | O17: 34326231 | P17: 19457999 | Q17: 34062873 | R17: 7421945.3 | S17: 13699504 | T17: 16841558 | U17: 12609410 | V17: 19677550 | W17: 21283931 | X17: 53758348 | Y17: 23286327 | Z17: 10494991 | AA17: 11130166 | AB17: 9056138.1 | AC17: 7132989.9 | AE17: 4952632.3 | AF17: 10749785 | AG17: 498432.53 | AH17: 5627254.3 | AI17: 2623133.3 | AJ17: 5001616.1 | AK17: 2775659.9 | AL17: 1835666.9 | AM17: 11414310 | AN17: 1984486.4 | AP17: 3610831.3 | AQ17: 3258243.6 | AR17: 4493939.6 | AS17: 1030090.8 | AT17: 1370070.4 | AU17: 1001548.1 | AV17: 1967893.8 | AW17: 1835369.5 | AX17: 673835.06 | AY17: 1355448.3 | AZ17: 1976967.6 | BA17: 591076.12 | BB17: 3972481.7 | BC17: 277604.21 | BD17: 428113.5 | BG17: 850418.96 | BH17: 994709.06 | BI17: 3074757.8 | BJ17: 949754.82 | BK17: 963941.21 | BL17: 191422.95 | BM17: 1982458.8 | BN17: 1183498.1 | BO17: 180411.75 | BP17: 3169479.5 | BQ17: 512898.97 | BR17: 251149.84 | BS17: 243602.92 | BT17: 260255.72 | BU17: 120788.9 | BV17: 838757.84 | BW17: 180503.14 | BX17: 107899.63 | BY17: 1121565 | BZ17: 310064.09 | CA17: 377451.96 | CB17: 395175.24 | CC17: 103556.6 | CD17: 485754.08 | CE17: 451220.38 | CF17: 474629.53 | CG17: 44632.896 | CI17: 344056.64 | CJ17: 128172.01 | CK17: 907308.23 | CN17: 20586.319 | CO17: 144727.23 | CP17: 959560.65 | CQ17: 847622.97 | CR17: 514251.87 | CS17: 152439.94 | CT17: 6866.6829 | CU17: 35164.825 | CV17: 229690.1 | CW17: 73411.171 | CX17: 94886.194 | CY17: 69125.926 | DA17: 100890.15 | DC17: 128046.65 | DD17: 33481.289 | DF17: 28725.544 | DH17: 63095.471 | DI17: 142280.95 | DK17: 156366.92 | DL17: 53972.591 | DN17: 39614.95 | DO17: 12093.027 | DP17: 14674.819 | DR17: 18083.724 | DS17: 19920.354 | DT17: 41673.488 | DV17: 164300.38 | DW17: 5335.3295 | DX17: 95442.417 | DY17: 19630.906 | DZ17: 13004.171 | EA17: 1194.566 | EC17: 47059.132 | ED17: 65305.903 | EE17: 112550.03 | EF17: 21150.971 | EG17: 181443.98 | EH17: 12222.541 | EI17: 16810.864 | EJ17: 13705.474 | EK17: 31367.453 | EL17: 51977.318 | EM17: 13068.328 | EN17: 31855.36 | EO17: 8521.0623 | EP17: 247406.97 | EQ17: 14861.198 | ER17: 4544.8479 | ES17: 6174.3733 | ET17: 10519.434 | EV17: 0 | EW17: 35171.424 | EX17: 20750.125 | EY17: 25262.795 | EZ17: 21172.393 | FB17: 70258.523 | FC17: 13693.679 | FD17: 30769.549 | FE17: 3772.727 | FF17: 50412.129 | FG17: 30798.991 | FH17: 23532.812 | FI17: 28763.556 | FJ17: 79184.671 | FK17: 16367.098 | FL17: 17065.265 | FM17: 11530.73 | FN17: 16287.049 | FO17: 6118.9388 | FP17: 7617.5707 | FR17: 18464.014 | FS17: 7489.6831 | FT17: 24977.258 | FU17: 11790.018 | FW17: 11396.829 | FX17: 10149.377 | FY17: 17179.663 | GA17: 0 | GE17: 0 | GF17: 0 | GG17: 0
A18: 46147 | B18: 5.5852181e+09 | C18: 1.749012e+09 | D18: 8.2131635e+08 | E18: 1.5517994e+09 | F18: 4.0302921e+08 | G18: 2.5661884e+08 | H18: 64519351 | I18: 62933879 | J18: 72559823 | K18: 66786342 | L18: 78913580 | M18: 1.2038537e+08 | N18: 35365946 | O18: 20231975 | P18: 31196790 | Q18: 33641225 | R18: 8355242.1 | S18: 8112912.7 | T18: 32680771 | U18: 17825875 | V18: 20325925 | W18: 14848999 | X18: 15822472 | Y18: 14050234 | Z18: 6677742.6 | AA18: 6401033.8 | AB18: 2937835.8 | AC18: 4697982.8 | AE18: 2172342.5 | AF18: 6525775.2 | AG18: 527372.95 | AH18: 4142699.7 | AI18: 349792.75 | AJ18: 1423732.8 | AK18: 2054325.8 | AL18: 1569032.9 | AM18: 4038597.2 | AN18: 2923909.5 | AP18: 48429.603 | AQ18: 2498930.6 | AR18: 3541390.3 | AS18: 1063213.3 | AT18: 1089735.2 | AU18: 876098.62 | AV18: 2385357 | AW18: 505885.27 | AX18: 450613.07 | AY18: 3072785.2 | AZ18: 2399139.4 | BA18: 1547837.9 | BB18: 152300.1 | BC18: 642882.39 | BD18: 424428.4 | BG18: 504632.88 | BH18: 1033963.2 | BJ18: 451206.44 | BK18: 211390.13 | BL18: 80066.675 | BM18: 4533916.1 | BN18: 999172.22 | BO18: 184194.73 | BP18: 609692.7 | BQ18: 565327.09 | BR18: 349241.98 | BS18: 209584.62 | BT18: 152292.25 | BU18: 113566.82 | BV18: 414486.68 | BW18: 76629.585 | BX18: 99644.295 | BY18: 621747.35 | BZ18: 135133.17 | CA18: 541154.91 | CB18: 39483.156 | CC18: 107923.42 | CD18: 87115.529 | CE18: 591593.21 | CF18: 632771.42 | CG18: 42113.323 | CI18: 235406.9 | CJ18: 135804.64 | CK18: 573906.66 | CN18: 18424.428 | CO18: 129105.43 | CP18: 229079.78 | CQ18: 598410.51 | CR18: 232296.41 | CS18: 110952.6 | CT18: 57413.992 | CU18: 26422.735 | CV18: 379550.4 | CW18: 45622.358 | CX18: 47679.392 | CY18: 12764.676 | DA18: 40704.963 | DC18: 57308.714 | DD18: 17586.588 | DF18: 21282.466 | DH18: 9374.2341 | DI18: 30337.466 | DK18: 77103.732 | DL18: 37522.257 | DN18: 18522.939 | DO18: 11507.805 | DP18: 11574.851 | DR18: 15540.536 | DS18: 16577.646 | DT18: 23972.397 | DV18: 9034.3907 | DW18: 5580.034 | DX18: 49469.495 | DY18: 10170.02 | DZ18: 11712.832 | EA18: 1127.2244 | EC18: 27491.666 | ED18: 39711.19 | EE18: 76151.009 | EF18: 20775.385 | EG18: 37921.11 | EH18: 11557.725 | EI18: 3112.6466 | EJ18: 6323.6328 | EK18: 16042.899 | EL18: 36738.295 | EM18: 5336.0284 | EN18: 22269.068 | EO18: 8253.7312 | EP18: 167658.28 | EQ18: 4350.9902 | ER18: 86086.973 | ES18: 5906.5245 | ET18: 20756.009 | EV18: 0 | EW18: 75448.301 | EX18: 26622.961 | EY18: 36296.381 | EZ18: 27748.351 | FB18: 14108.716 | FC18: 11391.663 | FD18: 4636.0128 | FE18: 7892.7523 | FF18: 10393.882 | FG18: 17873.476 | FH18: 6618.0331 | FI18: 13120.117 | FJ18: 9063.8086 | FK18: 30215.327 | FL18: 6533.9423 | FM18: 24434.111 | FN18: 28721.614 | FO18: 4885.4097 | FP18: 6603.9129 | FR18: 27497.112 | FS18: 9015.1628 | FT18: 4439.6757 | FU18: 12353.147 | FW18: 6858.453 | FX18: 4628.7004 | FY18: 23595.063 | GA18: 0 | GE18: 0 | GF18: 0 | GG18: 0
A19: 46146 | B19: 7.1559664e+09 | C19: 2.2187101e+09 | D19: 1.3878941e+09 | E19: 1.8213913e+09 | F19: 6.1845228e+08 | G19: 2.4285358e+08 | H19: 70763141 | I19: 39451237 | J19: 53840473 | K19: 93802343 | L19: 1.0466446e+08 | M19: 77588388 | N19: 33378295 | O19: 97395457 | P19: 35046722 | Q19: 30526015 | R19: 9179397.8 | S19: 9616841.1 | T19: 33388415 | U19: 17321005 | V19: 17733701 | W19: 16651488 | X19: 6028441.6 | Y19: 12940899 | Z19: 9048941.3 | AA19: 8505879.6 | AB19: 4290151.1 | AC19: 7771652.2 | AE19: 4689506.1 | AF19: 26382055 | AG19: 995193.42 | AH19: 5240011.5 | AI19: 691514.99 | AJ19: 2275093.4 | AK19: 1857881.9 | AL19: 1274238.6 | AM19: 1024918.2 | AN19: 2147506.6 | AP19: 44800.863 | AQ19: 1721115.3 | AR19: 1744032.8 | AS19: 498138.62 | AT19: 1802689.8 | AU19: 973638.72 | AV19: 1216595.4 | AW19: 897807.67 | AX19: 393983.08 | AY19: 1294609 | AZ19: 1119283.3 | BA19: 275195.5 | BB19: 342518.38 | BC19: 495436.85 | BD19: 488003.78 | BG19: 264980.42 | BH19: 984610.07 | BJ19: 891146.76 | BK19: 559559.12 | BL19: 307922.05 | BM19: 713160.88 | BN19: 863469.93 | BO19: 180708.74 | BP19: 865025.55 | BQ19: 1629621.2 | BR19: 375916 | BS19: 310268.63 | BT19: 183805.93 | BU19: 195851.55 | BV19: 467325.33 | BW19: 144214.09 | BX19: 280045.47 | BY19: 681125.52 | BZ19: 106128.47 | CA19: 309989.23 | CB19: 121953.92 | CC19: 222176.19 | CD19: 44698.025 | CE19: 564901.83 | CF19: 2105450.1 | CG19: 36145.796 | CI19: 60668.746 | CJ19: 185591.55 | CK19: 294534.05 | CN19: 17685.98 | CO19: 33107.592 | CP19: 230377.74 | CQ19: 367564.6 | CR19: 320147.8 | CS19: 214963.7 | CT19: 86425.037 | CU19: 35847.645 | CV19: 120795.9 | CW19: 52564.448 | CX19: 46075.566 | CY19: 17610.08 | DA19: 78860.012 | DC19: 51717.721 | DD19: 24424.059 | DF19: 33850.43 | DH19: 40644.723 | DI19: 180957.06 | DK19: 263231.3 | DL19: 44516.822 | DN19: 19599.098 | DO19: 10978.274 | DP19: 14724.736 | DR19: 14238.635 | DS19: 18018.208 | DT19: 21146.713 | DV19: 15947.54 | DW19: 9465.0513 | DX19: 38521.284 | DY19: 48003.106 | DZ19: 7984.7473 | EA19: 134.8488 | EC19: 30515.744 | ED19: 15848.099 | EE19: 92021.562 | EF19: 82869.185 | EG19: 116357.35 | EH19: 10984.419 | EI19: 5445.2058 | EJ19: 8768.0907 | EK19: 133810.38 | EL19: 57157.517 | EM19: 6033.7859 | EN19: 22652.901 | EO19: 7633.0046 | EP19: 26228.02 | EQ19: 82060.706 | ER19: 4830.9254 | ES19: 6519.9916 | ET19: 5643.8382 | EV19: 0 | EW19: 99241.831 | EX19: 41887.963 | EY19: 32026.305 | EZ19: 28414.468 | FB19: 8194.9672 | FC19: 28363.107 | FD19: 22207.629 | FE19: 4382.8254 | FF19: 60256.781 | FG19: 25693.21 | FH19: 20443.351 | FI19: 53480.969 | FJ19: 65131.834 | FK19: 20678.758 | FL19: 6143.5681 | FM19: 9592.8763 | FN19: 11185.656 | FO19: 5170.6378 | FP19: 54956.315 | FR19: 5705.6668 | FS19: 15070.562 | FT19: 27654.85 | FU19: 22994.637 | FW19: 17773.628 | FX19: 5257.4661 | FY19: 6807.2862 | GA19: 0 | GE19: 0 | GF19: 638.6101 | GG19: 0
A20: 46145 | B20: 1.4717266e+09 | C20: 3.6882704e+08 | D20: 2.7680069e+08 | E20: 5.2801439e+08 | F20: 1.5688593e+08 | G20: 9662004.7 | H20: 11995605 | I20: 5575639.8 | J20: 9041998.6 | K20: 14543913 | L20: 10171052 | M20: 8650537.6 | N20: 3054623.1 | O20: 3698862.9 | P20: 3463120.2 | Q20: 8436698.8 | R20: 2478908.9 | S20: 2132915.8 | T20: 1566853.4 | U20: 2648016.2 | V20: 4285683.7 | W20: 5057509.3 | X20: 1300202.7 | Y20: 238504.27 | Z20: 3583026.2 | AA20: 2340418.3 | AB20: 1956681.5 | AC20: 3606431.2 | AE20: 1559052.7 | AF20: 2000999.1 | AG20: 424283.64 | AH20: 325299.23 | AI20: 254509.93 | AJ20: 346585.3 | AK20: 807499.06 | AL20: 282370.74 | AM20: 7773064.8 | AN20: 33868.084 | AQ20: 1529569.7 | AR20: 139667.08 | AS20: 93612.41 | AT20: 653590.66 | AU20: 352549.38 | AV20: 309159.19 | AW20: 158493.27 | AX20: 165812.1 | AY20: 62827.079 | AZ20: 36683.218 | BA20: 108931.62 | BB20: 32490.104 | BC20: 453822.09 | BD20: 164524.27 | BG20: 166712.08 | BH20: 8980.7142 | BJ20: 122930.56 | BK20: 76966.312 | BL20: 35369.304 | BM20: 160970.86 | BN20: 34957.424 | BO20: 21461.113 | BP20: 10239.88 | BQ20: 98234.006 | BR20: 38818.74 | BS20: 54022.846 | BT20: 15939.92 | BU20: 197644.08 | BV20: 43162.279 | BW20: 27973.486 | BX20: 283147.17 | BY20: 46905.192 | BZ20: 74177.506 | CA20: 45200.528 | CB20: 2770.501 | CC20: 24846.985 | CD20: 4467.9573 | CE20: 14139.698 | CF20: 97752.955 | CG20: 26826.54 | CI20: 75349.258 | CJ20: 21147.074 | CK20: 31232.555 | CN20: 35538.628 | CO20: 30833.033 | CP20: 55575.623 | CQ20: 4664.9117 | CR20: 15679.887 | CS20: 6974.2756 | CT20: 3315.2395 | CU20: 23877.859 | CV20: 91867.331 | CW20: 39124.563 | CX20: 38437.623 | CY20: 9799.94 | DA20: 49600.51 | DC20: 24308.232 | DD20: 7780.0067 | DF20: 10391.416 | DH20: 47990.392 | DI20: 64032.957 | DK20: 84034.586 | DL20: 24442.178 | DN20: 18349.302 | DO20: 10797.514 | DP20: 36738.853 | DR20: 7821.3223 | DS20: 18663.456 | DT20: 16055.283 | DV20: 8757.7297 | DW20: 5086.2831 | DX20: 13282.655 | DY20: 12405.031 | DZ20: 8021.1634 | EA20: 1041.4546 | EC20: 8898.4704 | ED20: 5342.5481 | EE20: 45284.934 | EF20: 54603.109 | EG20: 15781.286 | EH20: 12479.276 | EI20: 2055.9477 | EJ20: 13067.9 | EK20: 52879.567 | EL20: 63311.721 | EM20: 5869.5208 | EN20: 64395.412 | EO20: 1827.4407 | EP20: 13347.312 | EQ20: 40918.434 | ER20: 4284.6769 | ES20: 4648.4452 | ET20: 3893.6258 | EV20: 0 | EW20: 23808.965 | EX20: 83231.305 | EY20: 85832.369 | EZ20: 9083.531 | FB20: 7967.2617 | FC20: 8374.798 | FD20: 26335.018 | FE20: 9019.123 | FF20: 17243.268 | FG20: 9798.243 | FH20: 5023.8812 | FI20: 24159.369 | FJ20: 10294.876 | FK20: 70181.07 | FL20: 9237.3974 | FM20: 7676.8041 | FN20: 9617.2514 | FO20: 11368.779 | FP20: 60087.671 | FR20: 5729.8109 | FS20: 13196.386 | FT20: 8904.2564 | FU20: 9002.867 | FW20: 4882.0027 | FX20: 4043.514 | FY20: 5467.518 | GA20: 0 | GE20: 1.243 | GF20: 0 | GG20: 0
