Workbook
Name HLP_Current: Assumptions!$C$4
Name HLP_Legacy: Assumptions!$C$5
Name HLP_ChangeDate: Assumptions!$C$6
Name Team_Genesis: Assumptions!$C$17
Name Pre_Cliff_Vested: Assumptions!$C$18
Name Cliff_Date: Assumptions!$C$19
Name Vest_Months: Assumptions!$C$20
Name Monthly_Vest: Assumptions!$C$21
Name Daily_Vest: Assumptions!$C$22
Name Vest_End_Date: Assumptions!$C$23

Sheet Read Me
B1: Hyperliquid — Fee → Revenue DAILY Decomposition
B2: Splits the actual HyperCore revenue into core-perp / HIP-3 / spot, every day, by top-down subtraction.
B3: Generated 2026-05-26. Daily, 2025-01-01 → 2026-05-20.
B5: THE METHOD (everything daily — no monthly aggregation)
B6: • NORTH STAR: the actual HyperCore revenue reported by hyperscreener.asxn.xyz (the $ that funds HYPE buybacks). The model never overrides it — it decomposes it.
B7: • STEP 1 — HIP-3: HIP-3 gross fees and deployer fees come from Loris (loris.tools), daily. HIP-3 protocol revenue = gross fees − deployer fees.
B8: • STEP 2 — Spot: spot revenue comes from DefiLlama (hyperliquid-spot-orderbook), daily.
B9: • STEP 3 — Core perp (the plug): Core perp revenue = HyperCore revenue − HIP-3 protocol revenue − spot revenue. Because it is a residual, the three pieces ALWAYS sum back to the north star exactly.
B10: • STEP 4 — Fees & HLP: revenue is grossed up to protocol fees by adding back the HLP provider share — 1% of perp+spot fees, and 3% before 2025-08-30 (DefiLlama methodology). Protocol fee = revenue ÷ (1 − HLP%).
B11: • CROSS-CHECKS: each segment's implied take-rate (fees ÷ volume, in bps) is shown so you can sanity-check it against the Hyperliquid fee schedule.
B13: WHAT THE NUMBERS SAY (read these before using the model)
B14: • HIP-3 is in GROWTH MODE: gross fees are ~0.7 bps of HIP-3 volume — roughly 4x lower than core perp. HIP-3 deployer fees are zero until 2026-03-21 (deployers took 0% in growth mode), so before that the protocol kept 100% of the (small) HIP-3 fees. HIP-3 is huge in volume but tiny in revenue today.
... B22: TABS
B23: Assumptions | D23: HLP share (1% from 2025-08-30, 3% before). Yellow = editable.
B24: Quarterly Model | D24: Segment-by-segment quarterly view: volumes ($Bn), gross fees ($Mn), take-rates, HyperCore deduction bridge (HLP / Unit / HIP-3 Deployer / Builder), revenue, burns, buyback, supply movements and ending OTS — plus an OTS cross-check vs PURR / CoinGecko at 2026-04-29.
B25: Daily Model | D25: The daily revenue decomposition — volumes → revenue split → implied fees → take-rates. Spot Gross Fees = DefiLlama actual; Unit Protocol Fees = balancing item (Spot Fees − Spot Revenue).
B26: OTS Breakdown | D26: Historical Outstanding Token Supply: supply flows (buyback, emissions, burns, vesting) and the OTS calc per day — the valuation base.
B27: Daily Data | D27: Raw daily inputs from every source, plus the supply reconciliation.
B28: Sources | D28: Each column → its exact source.
B30: Colour legend: | C30: yellow = input | E30: blue = source value | G30: black = formula | I30: green = cross-tab link

Sheet Assumptions
A1: ASSUMPTIONS — yellow cells are inputs you control
B3: Parameter | C3: Value | E3: Basis / notes
B4: HLP provider share — current | C4: 0.01 | D4: =C4 | E4: Share of perp+spot protocol fees paid to HLP liquidity providers, from 2025-08-30. Source: DefiLlama methodology.
B5: HLP provider share — legacy (pre-changeover) | C5: 0.03 | D5: =C5 | E5: HLP share before 2025-08-30 (it was 3%, cut to 1%). Source: DefiLlama methodology.
B6: HLP rate changeover date | C6: 45899 | E6: Date the HLP share dropped from legacy to current.
B9: • Decomposition identity: HyperCore revenue = core perp revenue + HIP-3 protocol revenue + spot revenue (exact, every day).
B10: • HIP-3 (Hyperliquid docs + Loris): users pay ~2x a normal perp fee, but HIP-3 markets run in growth mode — realised HIP-3 fees are very low and the deployer share was 0% until 2026-03-21.
B11: • Hyperliquid fee schedule (reference): perps 0.045%/0.015% taker/maker; spot 0.07%/0.04%; realised rates are far lower due to volume tiers and discounts.
B13: Total HYPE Staked — latest snapshot (HYPE) | C13: 431410000 | E13: May-2026 Total Stake = 431.41M HYPE. Source: ASXN dashboard Total HYPE Staked chart (Active + Inactive). Cross-checks vs HL /info validatorSummaries (431.43M).
B14: Avg Implied APR (observed, validator-network) | C14: 0.0225 | D14: =C14 | E14: Daily Emission × 365 ÷ Total Stake. Hovers in 2.20–2.34% across the full period (averaging ~2.25%) — consistent with HL's published formula yield = 2.37% × √(400M / stake).
B15: Staking data snapshot date | C15: 46143 | E15: Date the ASXN staking chart was read. Monthly granularity (held flat within each month). For audit only.
B17: Core Contributor allocation (genesis, HYPE) | C17: 238000000 | E17: Genesis allocation to core contributors / team: 23.80% × 1B = 238M HYPE. Source: HL tokenomics. Subject to vesting (cliff + linear, staggered per-contributor).
B18: Pre-cliff already vested (HYPE) | C18: 3515062 | E18: Cumulative team-contributor distributions Nov-2025 → Apr-2026 (discretionary early unlocks). Source: insights.unlocks.app + tokenomist.ai unlock-events page. Sum of all monthly events on the 6th: 1.746M + 0 + 1.126M + 0.140M + 0.173M + 0.330M.
B19: Team vesting cliff date | C19: 46179 | E19: Per Tokenomist.ai: next major unlock = 2026-06-06. The main linear-vest period starts here.
B20: Vest duration (months) post-cliff | C20: 24 | E20: 24 months. Stretches the post-cliff schedule to May 2028 (cliff date + 24 months). Reflects most sources saying vesting completes 2027-2028.
B21: Monthly vest post-cliff (HYPE) — DERIVED | C21: =(Team_Genesis-Pre_Cliff_Vested)/Vest_Months | D21: =C21 | E21: FORMULA: (Team_Genesis − Pre_Cliff_Vested) ÷ Vest_Months. Computes ~9.77M HYPE/month (vs Tokenomist's nominal 9.92M — slightly lower because we credit the 3.5M already distributed).
B22: Daily vest post-cliff (HYPE) — DERIVED | C22: =Monthly_Vest/30.4375 | D22: =C22 | E22: FORMULA: Monthly_Vest ÷ 30.4375 days/month (avg). ≈ 321K HYPE/day. For projection rows on OTS Breakdown, put this in col G (Team Tokens Unlocked) for EVERY day between Cliff_Date (2026-06-06) and Vest_End_Date (Cliff_Date + Vest_Months × 30.4375 days ≈ 2028-06-05). Daily-granularity vesting matches the smooth per-contributor vesting nature better than monthly chunks.
B23: Vest end date — DERIVED | C23: =Cliff_Date+Vest_Months*30.4375 | E23: FORMULA: Cliff_Date + Vest_Months × 30.4375. = 2028-06-05. After this date, projection rows should set Team Tokens Unlocked = 0 (all 238M is vested by then).

Sheet Quarterly Model
A1: QUARTERLY MODEL — segment fees, HyperCore deduction bridge, capital deployment & supply movements. Volumes in $Bn, fees in $Mn, HYPE in millions. Every figure is a live SUMIFS from Daily Model / Daily Data / OTS Breakdown — changes upstream flow through. BRIDGE: Total Fees − HLP − Unit − HIP-3 Deployer = HyperCore Revenue (north star, ties to hyperscreener buyback). Recon Δ ≈ 0. Builder/Core is an ON-TOP pass-through fee paid by users directly to front-ends — shown for transparency but NOT in the bridge (it never enters HL's revenue).
D2: CORE PERPS — CRYPTO | G2: HIP-3 | J2: SPOT | M2: HYPERCORE DEDUCTIONS (Gross Fees → HyperCore Revenue) | R2: HYPERCORE | V2: OTHER REVENUE (Burns) | X2: CAPITAL DEPLOYMENT | AA2: SUPPLY MOVEMENTS (HYPE, M) | AE2: OTS COMPOSITION (OTS = Circulating + Core Contributors)
A3: Quarter | B3: Start Date | C3: End Date | D3: Volume ($Bn) | E3: Fees ($Mn) | F3: Take-Rate (bps) | G3: Volume ($Bn) | H3: Fees ($Mn) | I3: Take-Rate (bps) | J3: Volume ($Bn) | K3: Fees ($Mn) | L3: Take-Rate (bps) | M3: HLP ($Mn) | N3: HLP Eff. Rate | O3: Unit / Spot ($Mn) | P3: HIP-3 Deployer ($Mn) | Q3: Builder / Core ($Mn) — on-top | R3: Total Fees ($Mn) | S3: Revenue ($Mn) | T3: Revenue / Fees (%) | U3: Recon Δ ($Mn) | V3: HyperEVM Fees ($Mn) | W3: Auction Burn ($Mn) | X3: Revenue → AF ($Mn) | Y3: HYPE Bought (M) | Z3: Avg HYPE Price ($) | AA3: Staking Emissions | AB3: Team / Vesting | AC3: Fees Burned | AD3: Ending OTS (M HYPE) | AE3: Ending Core Locked (M HYPE) | AF3: Ending Circulating (M HYPE) | AG3: Split Check ≈ 0
A4: Q1 2025 | B4: 45658 | C4: 45747 | D4: =SUMIFS('Daily Data'!$B$4:$B$508,'Daily Data'!$A$4:$A$508,">="&B4,'Daily Data'!$A$4:$A$508,"<="&C4)/1000000000 | E4: =SUMIFS('Daily Model'!$L$4:$L$508,'Daily Model'!$A$4:$A$508,">="&B4,'Daily Model'!$A$4:$A$508,"<="&C4)/1000000 | F4: =IF(D4=0,0,E4/(D4*1000)*10000) | G4: =SUMIFS('Daily Data'!$D$4:$D$508,'Daily Data'!$A$4:$A$508,">="&B4,'Daily Data'!$A$4:$A$508,"<="&C4)/1000000000 | H4: =SUMIFS('Daily Data'!$F$4:$F$508,'Daily Data'!$A$4:$A$508,">="&B4,'Daily Data'!$A$4:$A$508,"<="&C4)/1000000 | I4: =IF(G4=0,0,H4/(G4*1000)*10000) | J4: =SUMIFS('Daily Data'!$C$4:$C$508,'Daily Data'!$A$4:$A$508,">="&B4,'Daily Data'!$A$4:$A$508,"<="&C4)/1000000000 | K4: =SUMIFS('Daily Data'!$I$4:$I$508,'Daily Data'!$A$4:$A$508,">="&B4,'Daily Data'!$A$4:$A$508,"<="&C4)/1000000 | L4: =IF(J4=0,0,K4/(J4*1000)*10000) | M4: =SUMIFS('Daily Model'!$P$4:$P$508,'Daily Model'!$A$4:$A$508,">="&B4,'Daily Model'!$A$4:$A$508,"<="&C4)/1000000 | N4: =IF((E4+H4+K4)=0,0,M4/(E4+H4+K4)) | O4: =SUMIFS('Daily Model'!$N$4:$N$508,'Daily Model'!$A$4:$A$508,">="&B4,'Daily Model'!$A$4:$A$508,"<="&C4)/1000000 | P4: =SUMIFS('Daily Data'!$G$4:$G$508,'Daily Data'!$A$4:$A$508,">="&B4,'Daily Data'!$A$4:$A$508,"<="&C4)/1000000 | Q4: =SUMIFS('Daily Model'!$O$4:$O$508,'Daily Model'!$A$4:$A$508,">="&B4,'Daily Model'!$A$4:$A$508,"<="&C4)/1000000 | R4: =E4+H4+K4 | S4: =SUMIFS('Daily Data'!$E$4:$E$508,'Daily Data'!$A$4:$A$508,">="&B4,'Daily Data'!$A$4:$A$508,"<="&C4)/1000000 | T4: =IF(R4=0,0,S4/R4) | U4: =R4-M4-O4-P4-S4 | V4: =SUMIFS('Daily Data'!$J$4:$J$508,'Daily Data'!$A$4:$A$508,">="&B4,'Daily Data'!$A$4:$A$508,"<="&C4)/1000000 | W4: =SUMIFS('Daily Data'!$K$4:$K$508,'Daily Data'!$A$4:$A$508,">="&B4,'Daily Data'!$A$4:$A$508,"<="&C4)/1000000 | X4: =S4 | Y4: =SUMIFS('Daily Data'!$L$4:$L$508,'Daily Data'!$A$4:$A$508,">="&B4,'Daily Data'!$A$4:$A$508,"<="&C4)/1000000 | Z4: =IF(Y4=0,"",SUMIFS('Daily Data'!$M$4:$M$508,'Daily Data'!$A$4:$A$508,">="&B4,'Daily Data'!$A$4:$A$508,"<="&C4)/1000000/Y4) | AA4: =SUMIFS('Daily Data'!$O$4:$O$508,'Daily Data'!$A$4:$A$508,">="&B4,'Daily Data'!$A$4:$A$508,"<="&C4)/1000000 | AB4: =SUMIFS('OTS Breakdown'!$G$4:$G$508,'OTS Breakdown'!$A$4:$A$508,">="&B4,'OTS Breakdown'!$A$4:$A$508,"<="&C4)/1000000 | AC4: =SUMIFS('Daily Data'!$P$4:$P$508,'Daily Data'!$A$4:$A$508,">="&B4,'Daily Data'!$A$4:$A$508,"<="&C4)/1000000 | AD4: =LOOKUP(2,1/(('OTS Breakdown'!$A$4:$A$508<=C4)*('OTS Breakdown'!$O$4:$O$508<>"")),'OTS Breakdown'!$O$4:$O$508)/1000000 | AE4: =LOOKUP(2,1/(('OTS Breakdown'!$A$4:$A$508<=C4)*('OTS Breakdown'!$AE$4:$AE$508<>"")),'OTS Breakdown'!$AE$4:$AE$508) | AF4: =LOOKUP(2,1/(('OTS Breakdown'!$A$4:$A$508<=C4)*('OTS Breakdown'!$AF$4:$AF$508<>"")),'OTS Breakdown'!$AF$4:$AF$508) | AG4: =AD4-AE4-AF4
A5: Q2 2025 | B5: 45748 | C5: 45838 | D5: =SUMIFS('Daily Data'!$B$4:$B$508,'Daily Data'!$A$4:$A$508,">="&B5,'Daily Data'!$A$4:$A$508,"<="&C5)/1000000000 | E5: =SUMIFS('Daily Model'!$L$4:$L$508,'Daily Model'!$A$4:$A$508,">="&B5,'Daily Model'!$A$4:$A$508,"<="&C5)/1000000 | F5: =IF(D5=0,0,E5/(D5*1000)*10000) | G5: =SUMIFS('Daily Data'!$D$4:$D$508,'Daily Data'!$A$4:$A$508,">="&B5,'Daily Data'!$A$4:$A$508,"<="&C5)/1000000000 | H5: =SUMIFS('Daily Data'!$F$4:$F$508,'Daily Data'!$A$4:$A$508,">="&B5,'Daily Data'!$A$4:$A$508,"<="&C5)/1000000 | I5: =IF(G5=0,0,H5/(G5*1000)*10000) | J5: =SUMIFS('Daily Data'!$C$4:$C$508,'Daily Data'!$A$4:$A$508,">="&B5,'Daily Data'!$A$4:$A$508,"<="&C5)/1000000000 | K5: =SUMIFS('Daily Data'!$I$4:$I$508,'Daily Data'!$A$4:$A$508,">="&B5,'Daily Data'!$A$4:$A$508,"<="&C5)/1000000 | L5: =IF(J5=0,0,K5/(J5*1000)*10000) | M5: =SUMIFS('Daily Model'!$P$4:$P$508,'Daily Model'!$A$4:$A$508,">="&B5,'Daily Model'!$A$4:$A$508,"<="&C5)/1000000 | N5: =IF((E5+H5+K5)=0,0,M5/(E5+H5+K5)) | O5: =SUMIFS('Daily Model'!$N$4:$N$508,'Daily Model'!$A$4:$A$508,">="&B5,'Daily Model'!$A$4:$A$508,"<="&C5)/1000000 | P5: =SUMIFS('Daily Data'!$G$4:$G$508,'Daily Data'!$A$4:$A$508,">="&B5,'Daily Data'!$A$4:$A$508,"<="&C5)/1000000 | Q5: =SUMIFS('Daily Model'!$O$4:$O$508,'Daily Model'!$A$4:$A$508,">="&B5,'Daily Model'!$A$4:$A$508,"<="&C5)/1000000 | R5: =E5+H5+K5 | S5: =SUMIFS('Daily Data'!$E$4:$E$508,'Daily Data'!$A$4:$A$508,">="&B5,'Daily Data'!$A$4:$A$508,"<="&C5)/1000000 | T5: =IF(R5=0,0,S5/R5) | U5: =R5-M5-O5-P5-S5 | V5: =SUMIFS('Daily Data'!$J$4:$J$508,'Daily Data'!$A$4:$A$508,">="&B5,'Daily Data'!$A$4:$A$508,"<="&C5)/1000000 | W5: =SUMIFS('Daily Data'!$K$4:$K$508,'Daily Data'!$A$4:$A$508,">="&B5,'Daily Data'!$A$4:$A$508,"<="&C5)/1000000 | X5: =S5 | Y5: =SUMIFS('Daily Data'!$L$4:$L$508,'Daily Data'!$A$4:$A$508,">="&B5,'Daily Data'!$A$4:$A$508,"<="&C5)/1000000 | Z5: =IF(Y5=0,"",SUMIFS('Daily Data'!$M$4:$M$508,'Daily Data'!$A$4:$A$508,">="&B5,'Daily Data'!$A$4:$A$508,"<="&C5)/1000000/Y5) | AA5: =SUMIFS('Daily Data'!$O$4:$O$508,'Daily Data'!$A$4:$A$508,">="&B5,'Daily Data'!$A$4:$A$508,"<="&C5)/1000000 | AB5: =SUMIFS('OTS Breakdown'!$G$4:$G$508,'OTS Breakdown'!$A$4:$A$508,">="&B5,'OTS Breakdown'!$A$4:$A$508,"<="&C5)/1000000 | AC5: =SUMIFS('Daily Data'!$P$4:$P$508,'Daily Data'!$A$4:$A$508,">="&B5,'Daily Data'!$A$4:$A$508,"<="&C5)/1000000 | AD5: =LOOKUP(2,1/(('OTS Breakdown'!$A$4:$A$508<=C5)*('OTS Breakdown'!$O$4:$O$508<>"")),'OTS Breakdown'!$O$4:$O$508)/1000000 | AE5: =LOOKUP(2,1/(('OTS Breakdown'!$A$4:$A$508<=C5)*('OTS Breakdown'!$AE$4:$AE$508<>"")),'OTS Breakdown'!$AE$4:$AE$508) | AF5: =LOOKUP(2,1/(('OTS Breakdown'!$A$4:$A$508<=C5)*('OTS Breakdown'!$AF$4:$AF$508<>"")),'OTS Breakdown'!$AF$4:$AF$508) | AG5: =AD5-AE5-AF5
A6: Q3 2025 | B6: 45839 | C6: 45930 | D6: =SUMIFS('Daily Data'!$B$4:$B$508,'Daily Data'!$A$4:$A$508,">="&B6,'Daily Data'!$A$4:$A$508,"<="&C6)/1000000000 | E6: =SUMIFS('Daily Model'!$L$4:$L$508,'Daily Model'!$A$4:$A$508,">="&B6,'Daily Model'!$A$4:$A$508,"<="&C6)/1000000 | F6: =IF(D6=0,0,E6/(D6*1000)*10000) | G6: =SUMIFS('Daily Data'!$D$4:$D$508,'Daily Data'!$A$4:$A$508,">="&B6,'Daily Data'!$A$4:$A$508,"<="&C6)/1000000000 | H6: =SUMIFS('Daily Data'!$F$4:$F$508,'Daily Data'!$A$4:$A$508,">="&B6,'Daily Data'!$A$4:$A$508,"<="&C6)/1000000 | I6: =IF(G6=0,0,H6/(G6*1000)*10000) | J6: =SUMIFS('Daily Data'!$C$4:$C$508,'Daily Data'!$A$4:$A$508,">="&B6,'Daily Data'!$A$4:$A$508,"<="&C6)/1000000000 | K6: =SUMIFS('Daily Data'!$I$4:$I$508,'Daily Data'!$A$4:$A$508,">="&B6,'Daily Data'!$A$4:$A$508,"<="&C6)/1000000 | L6: =IF(J6=0,0,K6/(J6*1000)*10000) | M6: =SUMIFS('Daily Model'!$P$4:$P$508,'Daily Model'!$A$4:$A$508,">="&B6,'Daily Model'!$A$4:$A$508,"<="&C6)/1000000 | N6: =IF((E6+H6+K6)=0,0,M6/(E6+H6+K6)) | O6: =SUMIFS('Daily Model'!$N$4:$N$508,'Daily Model'!$A$4:$A$508,">="&B6,'Daily Model'!$A$4:$A$508,"<="&C6)/1000000 | P6: =SUMIFS('Daily Data'!$G$4:$G$508,'Daily Data'!$A$4:$A$508,">="&B6,'Daily Data'!$A$4:$A$508,"<="&C6)/1000000 | Q6: =SUMIFS('Daily Model'!$O$4:$O$508,'Daily Model'!$A$4:$A$508,">="&B6,'Daily Model'!$A$4:$A$508,"<="&C6)/1000000 | R6: =E6+H6+K6 | S6: =SUMIFS('Daily Data'!$E$4:$E$508,'Daily Data'!$A$4:$A$508,">="&B6,'Daily Data'!$A$4:$A$508,"<="&C6)/1000000 | T6: =IF(R6=0,0,S6/R6) | U6: =R6-M6-O6-P6-S6 | V6: =SUMIFS('Daily Data'!$J$4:$J$508,'Daily Data'!$A$4:$A$508,">="&B6,'Daily Data'!$A$4:$A$508,"<="&C6)/1000000 | W6: =SUMIFS('Daily Data'!$K$4:$K$508,'Daily Data'!$A$4:$A$508,">="&B6,'Daily Data'!$A$4:$A$508,"<="&C6)/1000000 | X6: =S6 | Y6: =SUMIFS('Daily Data'!$L$4:$L$508,'Daily Data'!$A$4:$A$508,">="&B6,'Daily Data'!$A$4:$A$508,"<="&C6)/1000000 | Z6: =IF(Y6=0,"",SUMIFS('Daily Data'!$M$4:$M$508,'Daily Data'!$A$4:$A$508,">="&B6,'Daily Data'!$A$4:$A$508,"<="&C6)/1000000/Y6) | AA6: =SUMIFS('Daily Data'!$O$4:$O$508,'Daily Data'!$A$4:$A$508,">="&B6,'Daily Data'!$A$4:$A$508,"<="&C6)/1000000 | AB6: =SUMIFS('OTS Breakdown'!$G$4:$G$508,'OTS Breakdown'!$A$4:$A$508,">="&B6,'OTS Breakdown'!$A$4:$A$508,"<="&C6)/1000000 | AC6: =SUMIFS('Daily Data'!$P$4:$P$508,'Daily Data'!$A$4:$A$508,">="&B6,'Daily Data'!$A$4:$A$508,"<="&C6)/1000000 | AD6: =LOOKUP(2,1/(('OTS Breakdown'!$A$4:$A$508<=C6)*('OTS Breakdown'!$O$4:$O$508<>"")),'OTS Breakdown'!$O$4:$O$508)/1000000 | AE6: =LOOKUP(2,1/(('OTS Breakdown'!$A$4:$A$508<=C6)*('OTS Breakdown'!$AE$4:$AE$508<>"")),'OTS Breakdown'!$AE$4:$AE$508) | AF6: =LOOKUP(2,1/(('OTS Breakdown'!$A$4:$A$508<=C6)*('OTS Breakdown'!$AF$4:$AF$508<>"")),'OTS Breakdown'!$AF$4:$AF$508) | AG6: =AD6-AE6-AF6
A7: Q4 2025 | B7: 45931 | C7: 46022 | D7: =SUMIFS('Daily Data'!$B$4:$B$508,'Daily Data'!$A$4:$A$508,">="&B7,'Daily Data'!$A$4:$A$508,"<="&C7)/1000000000 | E7: =SUMIFS('Daily Model'!$L$4:$L$508,'Daily Model'!$A$4:$A$508,">="&B7,'Daily Model'!$A$4:$A$508,"<="&C7)/1000000 | F7: =IF(D7=0,0,E7/(D7*1000)*10000) | G7: =SUMIFS('Daily Data'!$D$4:$D$508,'Daily Data'!$A$4:$A$508,">="&B7,'Daily Data'!$A$4:$A$508,"<="&C7)/1000000000 | H7: =SUMIFS('Daily Data'!$F$4:$F$508,'Daily Data'!$A$4:$A$508,">="&B7,'Daily Data'!$A$4:$A$508,"<="&C7)/1000000 | I7: =IF(G7=0,0,H7/(G7*1000)*10000) | J7: =SUMIFS('Daily Data'!$C$4:$C$508,'Daily Data'!$A$4:$A$508,">="&B7,'Daily Data'!$A$4:$A$508,"<="&C7)/1000000000 | K7: =SUMIFS('Daily Data'!$I$4:$I$508,'Daily Data'!$A$4:$A$508,">="&B7,'Daily Data'!$A$4:$A$508,"<="&C7)/1000000 | L7: =IF(J7=0,0,K7/(J7*1000)*10000) | M7: =SUMIFS('Daily Model'!$P$4:$P$508,'Daily Model'!$A$4:$A$508,">="&B7,'Daily Model'!$A$4:$A$508,"<="&C7)/1000000 | N7: =IF((E7+H7+K7)=0,0,M7/(E7+H7+K7)) | O7: =SUMIFS('Daily Model'!$N$4:$N$508,'Daily Model'!$A$4:$A$508,">="&B7,'Daily Model'!$A$4:$A$508,"<="&C7)/1000000 | P7: =SUMIFS('Daily Data'!$G$4:$G$508,'Daily Data'!$A$4:$A$508,">="&B7,'Daily Data'!$A$4:$A$508,"<="&C7)/1000000 | Q7: =SUMIFS('Daily Model'!$O$4:$O$508,'Daily Model'!$A$4:$A$508,">="&B7,'Daily Model'!$A$4:$A$508,"<="&C7)/1000000 | R7: =E7+H7+K7 | S7: =SUMIFS('Daily Data'!$E$4:$E$508,'Daily Data'!$A$4:$A$508,">="&B7,'Daily Data'!$A$4:$A$508,"<="&C7)/1000000 | T7: =IF(R7=0,0,S7/R7) | U7: =R7-M7-O7-P7-S7 | V7: =SUMIFS('Daily Data'!$J$4:$J$508,'Daily Data'!$A$4:$A$508,">="&B7,'Daily Data'!$A$4:$A$508,"<="&C7)/1000000 | W7: =SUMIFS('Daily Data'!$K$4:$K$508,'Daily Data'!$A$4:$A$508,">="&B7,'Daily Data'!$A$4:$A$508,"<="&C7)/1000000 | X7: =S7 | Y7: =SUMIFS('Daily Data'!$L$4:$L$508,'Daily Data'!$A$4:$A$508,">="&B7,'Daily Data'!$A$4:$A$508,"<="&C7)/1000000 | Z7: =IF(Y7=0,"",SUMIFS('Daily Data'!$M$4:$M$508,'Daily Data'!$A$4:$A$508,">="&B7,'Daily Data'!$A$4:$A$508,"<="&C7)/1000000/Y7) | AA7: =SUMIFS('Daily Data'!$O$4:$O$508,'Daily Data'!$A$4:$A$508,">="&B7,'Daily Data'!$A$4:$A$508,"<="&C7)/1000000 | AB7: =SUMIFS('OTS Breakdown'!$G$4:$G$508,'OTS Breakdown'!$A$4:$A$508,">="&B7,'OTS Breakdown'!$A$4:$A$508,"<="&C7)/1000000 | AC7: =SUMIFS('Daily Data'!$P$4:$P$508,'Daily Data'!$A$4:$A$508,">="&B7,'Daily Data'!$A$4:$A$508,"<="&C7)/1000000 | AD7: =LOOKUP(2,1/(('OTS Breakdown'!$A$4:$A$508<=C7)*('OTS Breakdown'!$O$4:$O$508<>"")),'OTS Breakdown'!$O$4:$O$508)/1000000 | AE7: =LOOKUP(2,1/(('OTS Breakdown'!$A$4:$A$508<=C7)*('OTS Breakdown'!$AE$4:$AE$508<>"")),'OTS Breakdown'!$AE$4:$AE$508) | AF7: =LOOKUP(2,1/(('OTS Breakdown'!$A$4:$A$508<=C7)*('OTS Breakdown'!$AF$4:$AF$508<>"")),'OTS Breakdown'!$AF$4:$AF$508) | AG7: =AD7-AE7-AF7
A8: Q1 2026 | B8: 46023 | C8: 46112 | D8: =SUMIFS('Daily Data'!$B$4:$B$508,'Daily Data'!$A$4:$A$508,">="&B8,'Daily Data'!$A$4:$A$508,"<="&C8)/1000000000 | E8: =SUMIFS('Daily Model'!$L$4:$L$508,'Daily Model'!$A$4:$A$508,">="&B8,'Daily Model'!$A$4:$A$508,"<="&C8)/1000000 | F8: =IF(D8=0,0,E8/(D8*1000)*10000) | G8: =SUMIFS('Daily Data'!$D$4:$D$508,'Daily Data'!$A$4:$A$508,">="&B8,'Daily Data'!$A$4:$A$508,"<="&C8)/1000000000 | H8: =SUMIFS('Daily Data'!$F$4:$F$508,'Daily Data'!$A$4:$A$508,">="&B8,'Daily Data'!$A$4:$A$508,"<="&C8)/1000000 | I8: =IF(G8=0,0,H8/(G8*1000)*10000) | J8: =SUMIFS('Daily Data'!$C$4:$C$508,'Daily Data'!$A$4:$A$508,">="&B8,'Daily Data'!$A$4:$A$508,"<="&C8)/1000000000 | K8: =SUMIFS('Daily Data'!$I$4:$I$508,'Daily Data'!$A$4:$A$508,">="&B8,'Daily Data'!$A$4:$A$508,"<="&C8)/1000000 | L8: =IF(J8=0,0,K8/(J8*1000)*10000) | M8: =SUMIFS('Daily Model'!$P$4:$P$508,'Daily Model'!$A$4:$A$508,">="&B8,'Daily Model'!$A$4:$A$508,"<="&C8)/1000000 | N8: =IF((E8+H8+K8)=0,0,M8/(E8+H8+K8)) | O8: =SUMIFS('Daily Model'!$N$4:$N$508,'Daily Model'!$A$4:$A$508,">="&B8,'Daily Model'!$A$4:$A$508,"<="&C8)/1000000 | P8: =SUMIFS('Daily Data'!$G$4:$G$508,'Daily Data'!$A$4:$A$508,">="&B8,'Daily Data'!$A$4:$A$508,"<="&C8)/1000000 | Q8: =SUMIFS('Daily Model'!$O$4:$O$508,'Daily Model'!$A$4:$A$508,">="&B8,'Daily Model'!$A$4:$A$508,"<="&C8)/1000000 | R8: =E8+H8+K8 | S8: =SUMIFS('Daily Data'!$E$4:$E$508,'Daily Data'!$A$4:$A$508,">="&B8,'Daily Data'!$A$4:$A$508,"<="&C8)/1000000 | T8: =IF(R8=0,0,S8/R8) | U8: =R8-M8-O8-P8-S8 | V8: =SUMIFS('Daily Data'!$J$4:$J$508,'Daily Data'!$A$4:$A$508,">="&B8,'Daily Data'!$A$4:$A$508,"<="&C8)/1000000 | W8: =SUMIFS('Daily Data'!$K$4:$K$508,'Daily Data'!$A$4:$A$508,">="&B8,'Daily Data'!$A$4:$A$508,"<="&C8)/1000000 | X8: =S8 | Y8: =SUMIFS('Daily Data'!$L$4:$L$508,'Daily Data'!$A$4:$A$508,">="&B8,'Daily Data'!$A$4:$A$508,"<="&C8)/1000000 | Z8: =IF(Y8=0,"",SUMIFS('Daily Data'!$M$4:$M$508,'Daily Data'!$A$4:$A$508,">="&B8,'Daily Data'!$A$4:$A$508,"<="&C8)/1000000/Y8) | AA8: =SUMIFS('Daily Data'!$O$4:$O$508,'Daily Data'!$A$4:$A$508,">="&B8,'Daily Data'!$A$4:$A$508,"<="&C8)/1000000 | AB8: =SUMIFS('OTS Breakdown'!$G$4:$G$508,'OTS Breakdown'!$A$4:$A$508,">="&B8,'OTS Breakdown'!$A$4:$A$508,"<="&C8)/1000000 | AC8: =SUMIFS('Daily Data'!$P$4:$P$508,'Daily Data'!$A$4:$A$508,">="&B8,'Daily Data'!$A$4:$A$508,"<="&C8)/1000000 | AD8: =LOOKUP(2,1/(('OTS Breakdown'!$A$4:$A$508<=C8)*('OTS Breakdown'!$O$4:$O$508<>"")),'OTS Breakdown'!$O$4:$O$508)/1000000 | AE8: =LOOKUP(2,1/(('OTS Breakdown'!$A$4:$A$508<=C8)*('OTS Breakdown'!$AE$4:$AE$508<>"")),'OTS Breakdown'!$AE$4:$AE$508) | AF8: =LOOKUP(2,1/(('OTS Breakdown'!$A$4:$A$508<=C8)*('OTS Breakdown'!$AF$4:$AF$508<>"")),'OTS Breakdown'!$AF$4:$AF$508) | AG8: =AD8-AE8-AF8
A9: Q2 2026 (partial) | B9: 46113 | C9: 46162 | D9: =SUMIFS('Daily Data'!$B$4:$B$508,'Daily Data'!$A$4:$A$508,">="&B9,'Daily Data'!$A$4:$A$508,"<="&C9)/1000000000 | E9: =SUMIFS('Daily Model'!$L$4:$L$508,'Daily Model'!$A$4:$A$508,">="&B9,'Daily Model'!$A$4:$A$508,"<="&C9)/1000000 | F9: =IF(D9=0,0,E9/(D9*1000)*10000) | G9: =SUMIFS('Daily Data'!$D$4:$D$508,'Daily Data'!$A$4:$A$508,">="&B9,'Daily Data'!$A$4:$A$508,"<="&C9)/1000000000 | H9: =SUMIFS('Daily Data'!$F$4:$F$508,'Daily Data'!$A$4:$A$508,">="&B9,'Daily Data'!$A$4:$A$508,"<="&C9)/1000000 | I9: =IF(G9=0,0,H9/(G9*1000)*10000) | J9: =SUMIFS('Daily Data'!$C$4:$C$508,'Daily Data'!$A$4:$A$508,">="&B9,'Daily Data'!$A$4:$A$508,"<="&C9)/1000000000 | K9: =SUMIFS('Daily Data'!$I$4:$I$508,'Daily Data'!$A$4:$A$508,">="&B9,'Daily Data'!$A$4:$A$508,"<="&C9)/1000000 | L9: =IF(J9=0,0,K9/(J9*1000)*10000) | M9: =SUMIFS('Daily Model'!$P$4:$P$508,'Daily Model'!$A$4:$A$508,">="&B9,'Daily Model'!$A$4:$A$508,"<="&C9)/1000000 | N9: =IF((E9+H9+K9)=0,0,M9/(E9+H9+K9)) | O9: =SUMIFS('Daily Model'!$N$4:$N$508,'Daily Model'!$A$4:$A$508,">="&B9,'Daily Model'!$A$4:$A$508,"<="&C9)/1000000 | P9: =SUMIFS('Daily Data'!$G$4:$G$508,'Daily Data'!$A$4:$A$508,">="&B9,'Daily Data'!$A$4:$A$508,"<="&C9)/1000000 | Q9: =SUMIFS('Daily Model'!$O$4:$O$508,'Daily Model'!$A$4:$A$508,">="&B9,'Daily Model'!$A$4:$A$508,"<="&C9)/1000000 | R9: =E9+H9+K9 | S9: =SUMIFS('Daily Data'!$E$4:$E$508,'Daily Data'!$A$4:$A$508,">="&B9,'Daily Data'!$A$4:$A$508,"<="&C9)/1000000 | T9: =IF(R9=0,0,S9/R9) | U9: =R9-M9-O9-P9-S9 | V9: =SUMIFS('Daily Data'!$J$4:$J$508,'Daily Data'!$A$4:$A$508,">="&B9,'Daily Data'!$A$4:$A$508,"<="&C9)/1000000 | W9: =SUMIFS('Daily Data'!$K$4:$K$508,'Daily Data'!$A$4:$A$508,">="&B9,'Daily Data'!$A$4:$A$508,"<="&C9)/1000000 | X9: =S9 | Y9: =SUMIFS('Daily Data'!$L$4:$L$508,'Daily Data'!$A$4:$A$508,">="&B9,'Daily Data'!$A$4:$A$508,"<="&C9)/1000000 | Z9: =IF(Y9=0,"",SUMIFS('Daily Data'!$M$4:$M$508,'Daily Data'!$A$4:$A$508,">="&B9,'Daily Data'!$A$4:$A$508,"<="&C9)/1000000/Y9) | AA9: =SUMIFS('Daily Data'!$O$4:$O$508,'Daily Data'!$A$4:$A$508,">="&B9,'Daily Data'!$A$4:$A$508,"<="&C9)/1000000 | AB9: =SUMIFS('OTS Breakdown'!$G$4:$G$508,'OTS Breakdown'!$A$4:$A$508,">="&B9,'OTS Breakdown'!$A$4:$A$508,"<="&C9)/1000000 | AC9: =SUMIFS('Daily Data'!$P$4:$P$508,'Daily Data'!$A$4:$A$508,">="&B9,'Daily Data'!$A$4:$A$508,"<="&C9)/1000000 | AD9: =LOOKUP(2,1/(('OTS Breakdown'!$A$4:$A$508<=C9)*('OTS Breakdown'!$O$4:$O$508<>"")),'OTS Breakdown'!$O$4:$O$508)/1000000 | AE9: =LOOKUP(2,1/(('OTS Breakdown'!$A$4:$A$508<=C9)*('OTS Breakdown'!$AE$4:$AE$508<>"")),'OTS Breakdown'!$AE$4:$AE$508) | AF9: =LOOKUP(2,1/(('OTS Breakdown'!$A$4:$A$508<=C9)*('OTS Breakdown'!$AF$4:$AF$508<>"")),'OTS Breakdown'!$AF$4:$AF$508) | AG9: =AD9-AE9-AF9
A12: OTS CROSS-CHECK — reconciles our OTS definition to the public sources (PURR US Equity NAV per HYPE; CoinGecko circulating supply)
A13: Snapshot date | D13: 46141 | G13: Cross-check anchor (matches PURR US Equity public NAV statement of 29-Apr-2026 referenced by the user).
A14: ASXN-style OTS (Initial 1B − Future Emission Reserve − Hyper Foundation − AF − Community Grants − Cumulative Burns) | D14: =LOOKUP(2,1/(('OTS Breakdown'!$A$4:$A$508=DATE(2026,4,29))*('OTS Breakdown'!$O$4:$O$508<>"")),'OTS Breakdown'!$O$4:$O$508)/1000000 | G14: This model's OTS. The HYPE valuation base. ≈ 477.2M.
A15: Hyperscreener circulating supply (HYPE) | D15: =LOOKUP(2,1/(('Daily Data'!$A$4:$A$508=DATE(2026,4,29))*('Daily Data'!$R$4:$R$508<>"")),'Daily Data'!$R$4:$R$508)/1000000 | G15: Hyperscreener /buyback/daily-burn currentDaySupply minus reserves. ≈ 298.7M.
A16: CoinGecko-style circulating = Total Supply − Future Emission Reserve | D16: =(LOOKUP(2,1/(('Daily Data'!$A$4:$A$508=DATE(2026,4,29))*('Daily Data'!$S$4:$S$508<>"")),'Daily Data'!$S$4:$S$508)-(LOOKUP(2,1/(('OTS Breakdown'!$A$4:$A$508=DATE(2026,4,29))*('OTS Breakdown'!$J$4:$J$508<>"")),'OTS Breakdown'!$J$4:$J$508)))/1000000 | G16: CoinGecko methodology subtracts only the staking emission reserve from total supply (does not exclude HF / AF / Community Grants). ≈ 584.0M.
A17: PURR US Equity — implied HYPE outstanding (per public NAV statement, 29-Apr-2026) | G17: Enter the disclosed figure here (NOT auto-pulled — PURR is the OTC HYPE wrapper). Then compare to our ASXN-style OTS above. Difference is the methodology gap (PURR typically uses a fully-diluted-ex-future-emissions basis closer to ASXN).
A18: Reconciliation: ASXN OTS − Circulating (hyperscreener) | D18: =LOOKUP(2,1/(('OTS Breakdown'!$A$4:$A$508=DATE(2026,4,29))*('OTS Breakdown'!$O$4:$O$508<>"")),'OTS Breakdown'!$O$4:$O$508)/1000000-(LOOKUP(2,1/(('Daily Data'!$A$4:$A$508=DATE(2026,4,29))*('Daily Data'!$R$4:$R$508<>"")),'Daily Data'!$R$4:$R$508))/1000000 | G18: ≈178M HYPE gap = team / core-contributor locked allocation (~238M genesis less ~3.5M discretionary unlocks so far) + small Foundation budget movements. The three reserves explicitly carved out of OTS (HF 60 + AF 44 + CG 3 = 107M) are already subtracted from OTS, so the gap to hyperscreener circulating is the still-locked team bucket. CoinGecko's 584M sits above ASXN because CoinGecko subtracts only the staking emission reserve from total supply.
A20: Notes: (i) Core Perp Fees = HC core perp revenue grossed up by HLP (Daily Model col L). (ii) HIP-3 Fees = Loris gross fees; HIP-3 Deployer = Loris (zero before 2026-03-21). (iii) Spot Fees = DefiLlama dailyFees (TOTAL spot fees); the prior mismatch between Daily Model spot fees and Daily Data spot fees is now resolved — both equal DefiLlama actual. Unit/Spot deduction = DefiLlama dailyFees − dailyHoldersRevenue (the Unit/Hyperunit on-top fee, the balancing item). (iv) HLP cut is CALCULATED, not extracted — no public daily HLP-revenue feed exists. Formula: HLP cut = (Core Perp Fees + HIP-3 Gross + Spot Fees) × HLP rate; rate = 3% before 2025-08-30, 1% after (per DefiLlama hyperliquid-spot-orderbook methodology — "1% of the spot fees go to HLP vault" — and the same 1%/3% applies to perps and HIP-3 gross). Daily Model cols Q/R/S show the HLP split across the three segments; col P is their sum. Col N "HLP Eff. Rate" = HLP $ ÷ (Core + HIP-3 + Spot) — should print 1% post-2025-08-30, 3% before, or a blend mid-Aug-25 (Q3 ≈ 2.4%). Spot bridge: Spot Fees (DefiLlama) = Spot Rev (post-HLP, post-Unit) + Unit + HLP_spot → Unit = Spot Fees × (1 − HLP rate) − Spot Rev. (v) Builder/Core = hyperscreener actual builder code fees, top-20 builders (daily from 2025-09-13; blank-treated-as-0 before). These are EXTRA fees front-ends charge on top of protocol fees and pass 100% to themselves — they do NOT reduce HL's revenue, so they are excluded from the Total Fees → Revenue bridge. (vi) Revenue (R) ties exactly to hyperscreener daily HC Rev sum (the daily-totals match the user asked about); Recon Δ (T) ≈ 0 confirms the segment fees + deductions reconcile. (vii) Avg HYPE Price = USD buyback ÷ HYPE bought (volume-weighted realised price, not period-average mark). (viii) Team / Vesting = ACTUAL discretionary unlock claims (insights.unlocks.app / tokenomist) — not the theoretical ~9.92M/month schedule. (ix) Ending OTS uses LOOKUP into OTS Breakdown col O at quarter-end. (x) Q2 2026 is partial (through 2026-05-20 — the last day with full Loris/hyperscreener data).

Sheet Daily Model
A1: HYPERLIQUID — DAILY FEE → REVENUE DECOMPOSITION (HyperCore revenue split into core perp / HIP-3 / spot)
B2: VOLUME | E2: REVENUE DECOMPOSITION | K2: IMPLIED FEES | T2: TAKE-RATE CROSS-CHECK
A3: Date | B3: Core Perp Volume ($) | C3: HIP-3 Volume ($) | D3: Spot Volume ($) | E3: HyperCore Revenue — north star ($) | F3: HIP-3 Gross Fees ($) | G3: HIP-3 Deployer Fees ($) | H3: HIP-3 Protocol Revenue in HC (post-HLP, post-Dep) ($) | I3: Spot Revenue ($) — post-HLP, post-Unit | J3: Core Perp Revenue — plug, post-HLP ($) | K3: HLP Rate Applied | L3: Core Perp Protocol Fees ($) | M3: Spot Gross Fees ($) — DefiLlama | N3: Unit Protocol Fees ($) — Spot × (1−HLP) − Spot Rev | O3: Builder Code Fees ($) | P3: HLP Cut — TOTAL ($) | Q3: HLP — Core ($) | R3: HLP — HIP-3 ($) | S3: HLP — Spot ($) | T3: Core Perp Take Rate (bps) | U3: HIP-3 Take Rate (bps) | V3: Spot Take Rate (bps)
A4: 45658 | B4: ='Daily Data'!B4 | C4: ='Daily Data'!D4 | D4: ='Daily Data'!C4 | E4: =IF('Daily Data'!E4="","",'Daily Data'!E4) | F4: =IF($E4="","",'Daily Data'!F4) | G4: =IF($E4="","",'Daily Data'!G4) | H4: =IF($E4="","",(1-K4)*F4-G4) | I4: =IF($E4="","",'Daily Data'!H4) | J4: =IF($E4="","",E4-H4-I4) | K4: =IF($E4="","",IF(A4<HLP_ChangeDate,HLP_Legacy,HLP_Current)) | L4: =IF($E4="","",J4/(1-K4)) | M4: =IF($E4="","",'Daily Data'!I4) | N4: =IF($E4="","",M4*(1-K4)-I4) | P4: =IF($E4="","",(L4+F4+M4)*K4) | Q4: =IF($E4="","",L4*K4) | R4: =IF($E4="","",F4*K4) | S4: =IF($E4="","",M4*K4) | T4: =IF(OR($E4="",B4=0),"",L4/B4*10000) | U4: =IF(OR($E4="",C4=0),"",F4/C4*10000) | V4: =IF(OR($E4="",D4=0),"",M4/D4*10000)
A5: 45659 | B5: ='Daily Data'!B5 | C5: ='Daily Data'!D5 | D5: ='Daily Data'!C5 | E5: =IF('Daily Data'!E5="","",'Daily Data'!E5) | F5: =IF($E5="","",'Daily Data'!F5) | G5: =IF($E5="","",'Daily Data'!G5) | H5: =IF($E5="","",(1-K5)*F5-G5) | I5: =IF($E5="","",'Daily Data'!H5) | J5: =IF($E5="","",E5-H5-I5) | K5: =IF($E5="","",IF(A5<HLP_ChangeDate,HLP_Legacy,HLP_Current)) | L5: =IF($E5="","",J5/(1-K5)) | M5: =IF($E5="","",'Daily Data'!I5) | N5: =IF($E5="","",M5*(1-K5)-I5) | P5: =IF($E5="","",(L5+F5+M5)*K5) | Q5: =IF($E5="","",L5*K5) | R5: =IF($E5="","",F5*K5) | S5: =IF($E5="","",M5*K5) | T5: =IF(OR($E5="",B5=0),"",L5/B5*10000) | U5: =IF(OR($E5="",C5=0),"",F5/C5*10000) | V5: =IF(OR($E5="",D5=0),"",M5/D5*10000)
A6: 45660 | B6: ='Daily Data'!B6 | C6: ='Daily Data'!D6 | D6: ='Daily Data'!C6 | E6: =IF('Daily Data'!E6="","",'Daily Data'!E6) | F6: =IF($E6="","",'Daily Data'!F6) | G6: =IF($E6="","",'Daily Data'!G6) | H6: =IF($E6="","",(1-K6)*F6-G6) | I6: =IF($E6="","",'Daily Data'!H6) | J6: =IF($E6="","",E6-H6-I6) | K6: =IF($E6="","",IF(A6<HLP_ChangeDate,HLP_Legacy,HLP_Current)) | L6: =IF($E6="","",J6/(1-K6)) | M6: =IF($E6="","",'Daily Data'!I6) | N6: =IF($E6="","",M6*(1-K6)-I6) | P6: =IF($E6="","",(L6+F6+M6)*K6) | Q6: =IF($E6="","",L6*K6) | R6: =IF($E6="","",F6*K6) | S6: =IF($E6="","",M6*K6) | T6: =IF(OR($E6="",B6=0),"",L6/B6*10000) | U6: =IF(OR($E6="",C6=0),"",F6/C6*10000) | V6: =IF(OR($E6="",D6=0),"",M6/D6*10000)
A7: 45661 | B7: ='Daily Data'!B7 | C7: ='Daily Data'!D7 | D7: ='Daily Data'!C7 | E7: =IF('Daily Data'!E7="","",'Daily Data'!E7) | F7: =IF($E7="","",'Daily Data'!F7) | G7: =IF($E7="","",'Daily Data'!G7) | H7: =IF($E7="","",(1-K7)*F7-G7) | I7: =IF($E7="","",'Daily Data'!H7) | J7: =IF($E7="","",E7-H7-I7) | K7: =IF($E7="","",IF(A7<HLP_ChangeDate,HLP_Legacy,HLP_Current)) | L7: =IF($E7="","",J7/(1-K7)) | M7: =IF($E7="","",'Daily Data'!I7) | N7: =IF($E7="","",M7*(1-K7)-I7) | P7: =IF($E7="","",(L7+F7+M7)*K7) | Q7: =IF($E7="","",L7*K7) | R7: =IF($E7="","",F7*K7) | S7: =IF($E7="","",M7*K7) | T7: =IF(OR($E7="",B7=0),"",L7/B7*10000) | U7: =IF(OR($E7="",C7=0),"",F7/C7*10000) | V7: =IF(OR($E7="",D7=0),"",M7/D7*10000)
A8: 45662 | B8: ='Daily Data'!B8 | C8: ='Daily Data'!D8 | D8: ='Daily Data'!C8 | E8: =IF('Daily Data'!E8="","",'Daily Data'!E8) | F8: =IF($E8="","",'Daily Data'!F8) | G8: =IF($E8="","",'Daily Data'!G8) | H8: =IF($E8="","",(1-K8)*F8-G8) | I8: =IF($E8="","",'Daily Data'!H8) | J8: =IF($E8="","",E8-H8-I8) | K8: =IF($E8="","",IF(A8<HLP_ChangeDate,HLP_Legacy,HLP_Current)) | L8: =IF($E8="","",J8/(1-K8)) | M8: =IF($E8="","",'Daily Data'!I8) | N8: =IF($E8="","",M8*(1-K8)-I8) | P8: =IF($E8="","",(L8+F8+M8)*K8) | Q8: =IF($E8="","",L8*K8) | R8: =IF($E8="","",F8*K8) | S8: =IF($E8="","",M8*K8) | T8: =IF(OR($E8="",B8=0),"",L8/B8*10000) | U8: =IF(OR($E8="",C8=0),"",F8/C8*10000) | V8: =IF(OR($E8="",D8=0),"",M8/D8*10000)
A9: 45663 | B9: ='Daily Data'!B9 | C9: ='Daily Data'!D9 | D9: ='Daily Data'!C9 | E9: =IF('Daily Data'!E9="","",'Daily Data'!E9) | F9: =IF($E9="","",'Daily Data'!F9) | G9: =IF($E9="","",'Daily Data'!G9) | H9: =IF($E9="","",(1-K9)*F9-G9) | I9: =IF($E9="","",'Daily Data'!H9) | J9: =IF($E9="","",E9-H9-I9) | K9: =IF($E9="","",IF(A9<HLP_ChangeDate,HLP_Legacy,HLP_Current)) | L9: =IF($E9="","",J9/(1-K9)) | M9: =IF($E9="","",'Daily Data'!I9) | N9: =IF($E9="","",M9*(1-K9)-I9) | P9: =IF($E9="","",(L9+F9+M9)*K9) | Q9: =IF($E9="","",L9*K9) | R9: =IF($E9="","",F9*K9) | S9: =IF($E9="","",M9*K9) | T9: =IF(OR($E9="",B9=0),"",L9/B9*10000) | U9: =IF(OR($E9="",C9=0),"",F9/C9*10000) | V9: =IF(OR($E9="",D9=0),"",M9/D9*10000)
A10: 45664 | B10: ='Daily Data'!B10 | C10: ='Daily Data'!D10 | D10: ='Daily Data'!C10 | E10: =IF('Daily Data'!E10="","",'Daily Data'!E10) | F10: =IF($E10="","",'Daily Data'!F10) | G10: =IF($E10="","",'Daily Data'!G10) | H10: =IF($E10="","",(1-K10)*F10-G10) | I10: =IF($E10="","",'Daily Data'!H10) | J10: =IF($E10="","",E10-H10-I10) | K10: =IF($E10="","",IF(A10<HLP_ChangeDate,HLP_Legacy,HLP_Current)) | L10: =IF($E10="","",J10/(1-K10)) | M10: =IF($E10="","",'Daily Data'!I10) | N10: =IF($E10="","",M10*(1-K10)-I10) | P10: =IF($E10="","",(L10+F10+M10)*K10) | Q10: =IF($E10="","",L10*K10) | R10: =IF($E10="","",F10*K10) | S10: =IF($E10="","",M10*K10) | T10: =IF(OR($E10="",B10=0),"",L10/B10*10000) | U10: =IF(OR($E10="",C10=0),"",F10/C10*10000) | V10: =IF(OR($E10="",D10=0),"",M10/D10*10000)
A11: 45665 | B11: ='Daily Data'!B11 | C11: ='Daily Data'!D11 | D11: ='Daily Data'!C11 | E11: =IF('Daily Data'!E11="","",'Daily Data'!E11) | F11: =IF($E11="","",'Daily Data'!F11) | G11: =IF($E11="","",'Daily Data'!G11) | H11: =IF($E11="","",(1-K11)*F11-G11) | I11: =IF($E11="","",'Daily Data'!H11) | J11: =IF($E11="","",E11-H11-I11) | K11: =IF($E11="","",IF(A11<HLP_ChangeDate,HLP_Legacy,HLP_Current)) | L11: =IF($E11="","",J11/(1-K11)) | M11: =IF($E11="","",'Daily Data'!I11) | N11: =IF($E11="","",M11*(1-K11)-I11) | P11: =IF($E11="","",(L11+F11+M11)*K11) | Q11: =IF($E11="","",L11*K11) | R11: =IF($E11="","",F11*K11) | S11: =IF($E11="","",M11*K11) | T11: =IF(OR($E11="",B11=0),"",L11/B11*10000) | U11: =IF(OR($E11="",C11=0),"",F11/C11*10000) | V11: =IF(OR($E11="",D11=0),"",M11/D11*10000)
A12: 45666 | B12: ='Daily Data'!B12 | C12: ='Daily Data'!D12 | D12: ='Daily Data'!C12 | E12: =IF('Daily Data'!E12="","",'Daily Data'!E12) | F12: =IF($E12="","",'Daily Data'!F12) | G12: =IF($E12="","",'Daily Data'!G12) | H12: =IF($E12="","",(1-K12)*F12-G12) | I12: =IF($E12="","",'Daily Data'!H12) | J12: =IF($E12="","",E12-H12-I12) | K12: =IF($E12="","",IF(A12<HLP_ChangeDate,HLP_Legacy,HLP_Current)) | L12: =IF($E12="","",J12/(1-K12)) | M12: =IF($E12="","",'Daily Data'!I12) | N12: =IF($E12="","",M12*(1-K12)-I12) | P12: =IF($E12="","",(L12+F12+M12)*K12) | Q12: =IF($E12="","",L12*K12) | R12: =IF($E12="","",F12*K12) | S12: =IF($E12="","",M12*K12) | T12: =IF(OR($E12="",B12=0),"",L12/B12*10000) | U12: =IF(OR($E12="",C12=0),"",F12/C12*10000) | V12: =IF(OR($E12="",D12=0),"",M12/D12*10000)
A13: 45667 | B13: ='Daily Data'!B13 | C13: ='Daily Data'!D13 | D13: ='Daily Data'!C13 | E13: =IF('Daily Data'!E13="","",'Daily Data'!E13) | F13: =IF($E13="","",'Daily Data'!F13) | G13: =IF($E13="","",'Daily Data'!G13) | H13: =IF($E13="","",(1-K13)*F13-G13) | I13: =IF($E13="","",'Daily Data'!H13) | J13: =IF($E13="","",E13-H13-I13) | K13: =IF($E13="","",IF(A13<HLP_ChangeDate,HLP_Legacy,HLP_Current)) | L13: =IF($E13="","",J13/(1-K13)) | M13: =IF($E13="","",'Daily Data'!I13) | N13: =IF($E13="","",M13*(1-K13)-I13) | P13: =IF($E13="","",(L13+F13+M13)*K13) | Q13: =IF($E13="","",L13*K13) | R13: =IF($E13="","",F13*K13) | S13: =IF($E13="","",M13*K13) | T13: =IF(OR($E13="",B13=0),"",L13/B13*10000) | U13: =IF(OR($E13="",C13=0),"",F13/C13*10000) | V13: =IF(OR($E13="",D13=0),"",M13/D13*10000)
A14: 45668 | B14: ='Daily Data'!B14 | C14: ='Daily Data'!D14 | D14: ='Daily Data'!C14 | E14: =IF('Daily Data'!E14="","",'Daily Data'!E14) | F14: =IF($E14="","",'Daily Data'!F14) | G14: =IF($E14="","",'Daily Data'!G14) | H14: =IF($E14="","",(1-K14)*F14-G14) | I14: =IF($E14="","",'Daily Data'!H14) | J14: =IF($E14="","",E14-H14-I14) | K14: =IF($E14="","",IF(A14<HLP_ChangeDate,HLP_Legacy,HLP_Current)) | L14: =IF($E14="","",J14/(1-K14)) | M14: =IF($E14="","",'Daily Data'!I14) | N14: =IF($E14="","",M14*(1-K14)-I14) | P14: =IF($E14="","",(L14+F14+M14)*K14) | Q14: =IF($E14="","",L14*K14) | R14: =IF($E14="","",F14*K14) | S14: =IF($E14="","",M14*K14) | T14: =IF(OR($E14="",B14=0),"",L14/B14*10000) | U14: =IF(OR($E14="",C14=0),"",F14/C14*10000) | V14: =IF(OR($E14="",D14=0),"",M14/D14*10000)
A15: 45669 | B15: ='Daily Data'!B15 | C15: ='Daily Data'!D15 | D15: ='Daily Data'!C15 | E15: =IF('Daily Data'!E15="","",'Daily Data'!E15) | F15: =IF($E15="","",'Daily Data'!F15) | G15: =IF($E15="","",'Daily Data'!G15) | H15: =IF($E15="","",(1-K15)*F15-G15) | I15: =IF($E15="","",'Daily Data'!H15) | J15: =IF($E15="","",E15-H15-I15) | K15: =IF($E15="","",IF(A15<HLP_ChangeDate,HLP_Legacy,HLP_Current)) | L15: =IF($E15="","",J15/(1-K15)) | M15: =IF($E15="","",'Daily Data'!I15) | N15: =IF($E15="","",M15*(1-K15)-I15) | P15: =IF($E15="","",(L15+F15+M15)*K15) | Q15: =IF($E15="","",L15*K15) | R15: =IF($E15="","",F15*K15) | S15: =IF($E15="","",M15*K15) | T15: =IF(OR($E15="",B15=0),"",L15/B15*10000) | U15: =IF(OR($E15="",C15=0),"",F15/C15*10000) | V15: =IF(OR($E15="",D15=0),"",M15/D15*10000)
... A258: 45912 | B258: ='Daily Data'!B258 | C258: ='Daily Data'!D258 | D258: ='Daily Data'!C258 | E258: =IF('Daily Data'!E258="","",'Daily Data'!E258) | F258: =IF($E258="","",'Daily Data'!F258) | G258: =IF($E258="","",'Daily Data'!G258) | H258: =IF($E258="","",(1-K258)*F258-G258) | I258: =IF($E258="","",'Daily Data'!H258) | J258: =IF($E258="","",E258-H258-I258) | K258: =IF($E258="","",IF(A258<HLP_ChangeDate,HLP_Legacy,HLP_Current)) | L258: =IF($E258="","",J258/(1-K258)) | M258: =IF($E258="","",'Daily Data'!I258) | N258: =IF($E258="","",M258*(1-K258)-I258) | P258: =IF($E258="","",(L258+F258+M258)*K258) | Q258: =IF($E258="","",L258*K258) | R258: =IF($E258="","",F258*K258) | S258: =IF($E258="","",M258*K258) | T258: =IF(OR($E258="",B258=0),"",L258/B258*10000) | U258: =IF(OR($E258="",C258=0),"",F258/C258*10000) | V258: =IF(OR($E258="",D258=0),"",M258/D258*10000)
A259: 45913 | B259: ='Daily Data'!B259 | C259: ='Daily Data'!D259 | D259: ='Daily Data'!C259 | E259: =IF('Daily Data'!E259="","",'Daily Data'!E259) | F259: =IF($E259="","",'Daily Data'!F259) | G259: =IF($E259="","",'Daily Data'!G259) | H259: =IF($E259="","",(1-K259)*F259-G259) | I259: =IF($E259="","",'Daily Data'!H259) | J259: =IF($E259="","",E259-H259-I259) | K259: =IF($E259="","",IF(A259<HLP_ChangeDate,HLP_Legacy,HLP_Current)) | L259: =IF($E259="","",J259/(1-K259)) | M259: =IF($E259="","",'Daily Data'!I259) | N259: =IF($E259="","",M259*(1-K259)-I259) | O259: 335679 | P259: =IF($E259="","",(L259+F259+M259)*K259) | Q259: =IF($E259="","",L259*K259) | R259: =IF($E259="","",F259*K259) | S259: =IF($E259="","",M259*K259) | T259: =IF(OR($E259="",B259=0),"",L259/B259*10000) | U259: =IF(OR($E259="",C259=0),"",F259/C259*10000) | V259: =IF(OR($E259="",D259=0),"",M259/D259*10000)
A260: 45914 | B260: ='Daily Data'!B260 | C260: ='Daily Data'!D260 | D260: ='Daily Data'!C260 | E260: =IF('Daily Data'!E260="","",'Daily Data'!E260) | F260: =IF($E260="","",'Daily Data'!F260) | G260: =IF($E260="","",'Daily Data'!G260) | H260: =IF($E260="","",(1-K260)*F260-G260) | I260: =IF($E260="","",'Daily Data'!H260) | J260: =IF($E260="","",E260-H260-I260) | K260: =IF($E260="","",IF(A260<HLP_ChangeDate,HLP_Legacy,HLP_Current)) | L260: =IF($E260="","",J260/(1-K260)) | M260: =IF($E260="","",'Daily Data'!I260) | N260: =IF($E260="","",M260*(1-K260)-I260) | O260: 997056 | P260: =IF($E260="","",(L260+F260+M260)*K260) | Q260: =IF($E260="","",L260*K260) | R260: =IF($E260="","",F260*K260) | S260: =IF($E260="","",M260*K260) | T260: =IF(OR($E260="",B260=0),"",L260/B260*10000) | U260: =IF(OR($E260="",C260=0),"",F260/C260*10000) | V260: =IF(OR($E260="",D260=0),"",M260/D260*10000)
A261: 45915 | B261: ='Daily Data'!B261 | C261: ='Daily Data'!D261 | D261: ='Daily Data'!C261 | E261: =IF('Daily Data'!E261="","",'Daily Data'!E261) | F261: =IF($E261="","",'Daily Data'!F261) | G261: =IF($E261="","",'Daily Data'!G261) | H261: =IF($E261="","",(1-K261)*F261-G261) | I261: =IF($E261="","",'Daily Data'!H261) | J261: =IF($E261="","",E261-H261-I261) | K261: =IF($E261="","",IF(A261<HLP_ChangeDate,HLP_Legacy,HLP_Current)) | L261: =IF($E261="","",J261/(1-K261)) | M261: =IF($E261="","",'Daily Data'!I261) | N261: =IF($E261="","",M261*(1-K261)-I261) | O261: 507449 | P261: =IF($E261="","",(L261+F261+M261)*K261) | Q261: =IF($E261="","",L261*K261) | R261: =IF($E261="","",F261*K261) | S261: =IF($E261="","",M261*K261) | T261: =IF(OR($E261="",B261=0),"",L261/B261*10000) | U261: =IF(OR($E261="",C261=0),"",F261/C261*10000) | V261: =IF(OR($E261="",D261=0),"",M261/D261*10000)
A262: 45916 | B262: ='Daily Data'!B262 | C262: ='Daily Data'!D262 | D262: ='Daily Data'!C262 | E262: =IF('Daily Data'!E262="","",'Daily Data'!E262) | F262: =IF($E262="","",'Daily Data'!F262) | G262: =IF($E262="","",'Daily Data'!G262) | H262: =IF($E262="","",(1-K262)*F262-G262) | I262: =IF($E262="","",'Daily Data'!H262) | J262: =IF($E262="","",E262-H262-I262) | K262: =IF($E262="","",IF(A262<HLP_ChangeDate,HLP_Legacy,HLP_Current)) | L262: =IF($E262="","",J262/(1-K262)) | M262: =IF($E262="","",'Daily Data'!I262) | N262: =IF($E262="","",M262*(1-K262)-I262) | O262: 439663 | P262: =IF($E262="","",(L262+F262+M262)*K262) | Q262: =IF($E262="","",L262*K262) | R262: =IF($E262="","",F262*K262) | S262: =IF($E262="","",M262*K262) | T262: =IF(OR($E262="",B262=0),"",L262/B262*10000) | U262: =IF(OR($E262="",C262=0),"",F262/C262*10000) | V262: =IF(OR($E262="",D262=0),"",M262/D262*10000)
A263: 45917 | B263: ='Daily Data'!B263 | C263: ='Daily Data'!D263 | D263: ='Daily Data'!C263 | E263: =IF('Daily Data'!E263="","",'Daily Data'!E263) | F263: =IF($E263="","",'Daily Data'!F263) | G263: =IF($E263="","",'Daily Data'!G263) | H263: =IF($E263="","",(1-K263)*F263-G263) | I263: =IF($E263="","",'Daily Data'!H263) | J263: =IF($E263="","",E263-H263-I263) | K263: =IF($E263="","",IF(A263<HLP_ChangeDate,HLP_Legacy,HLP_Current)) | L263: =IF($E263="","",J263/(1-K263)) | M263: =IF($E263="","",'Daily Data'!I263) | N263: =IF($E263="","",M263*(1-K263)-I263) | O263: 649107 | P263: =IF($E263="","",(L263+F263+M263)*K263) | Q263: =IF($E263="","",L263*K263) | R263: =IF($E263="","",F263*K263) | S263: =IF($E263="","",M263*K263) | T263: =IF(OR($E263="",B263=0),"",L263/B263*10000) | U263: =IF(OR($E263="",C263=0),"",F263/C263*10000) | V263: =IF(OR($E263="",D263=0),"",M263/D263*10000)
A264: 45918 | B264: ='Daily Data'!B264 | C264: ='Daily Data'!D264 | D264: ='Daily Data'!C264 | E264: =IF('Daily Data'!E264="","",'Daily Data'!E264) | F264: =IF($E264="","",'Daily Data'!F264) | G264: =IF($E264="","",'Daily Data'!G264) | H264: =IF($E264="","",(1-K264)*F264-G264) | I264: =IF($E264="","",'Daily Data'!H264) | J264: =IF($E264="","",E264-H264-I264) | K264: =IF($E264="","",IF(A264<HLP_ChangeDate,HLP_Legacy,HLP_Current)) | L264: =IF($E264="","",J264/(1-K264)) | M264: =IF($E264="","",'Daily Data'!I264) | N264: =IF($E264="","",M264*(1-K264)-I264) | O264: 542586 | P264: =IF($E264="","",(L264+F264+M264)*K264) | Q264: =IF($E264="","",L264*K264) | R264: =IF($E264="","",F264*K264) | S264: =IF($E264="","",M264*K264) | T264: =IF(OR($E264="",B264=0),"",L264/B264*10000) | U264: =IF(OR($E264="",C264=0),"",F264/C264*10000) | V264: =IF(OR($E264="",D264=0),"",M264/D264*10000)
A265: 45919 | B265: ='Daily Data'!B265 | C265: ='Daily Data'!D265 | D265: ='Daily Data'!C265 | E265: =IF('Daily Data'!E265="","",'Daily Data'!E265) | F265: =IF($E265="","",'Daily Data'!F265) | G265: =IF($E265="","",'Daily Data'!G265) | H265: =IF($E265="","",(1-K265)*F265-G265) | I265: =IF($E265="","",'Daily Data'!H265) | J265: =IF($E265="","",E265-H265-I265) | K265: =IF($E265="","",IF(A265<HLP_ChangeDate,HLP_Legacy,HLP_Current)) | L265: =IF($E265="","",J265/(1-K265)) | M265: =IF($E265="","",'Daily Data'!I265) | N265: =IF($E265="","",M265*(1-K265)-I265) | O265: 366033 | P265: =IF($E265="","",(L265+F265+M265)*K265) | Q265: =IF($E265="","",L265*K265) | R265: =IF($E265="","",F265*K265) | S265: =IF($E265="","",M265*K265) | T265: =IF(OR($E265="",B265=0),"",L265/B265*10000) | U265: =IF(OR($E265="",C265=0),"",F265/C265*10000) | V265: =IF(OR($E265="",D265=0),"",M265/D265*10000)
A266: 45920 | B266: ='Daily Data'!B266 | C266: ='Daily Data'!D266 | D266: ='Daily Data'!C266 | E266: =IF('Daily Data'!E266="","",'Daily Data'!E266) | F266: =IF($E266="","",'Daily Data'!F266) | G266: =IF($E266="","",'Daily Data'!G266) | H266: =IF($E266="","",(1-K266)*F266-G266) | I266: =IF($E266="","",'Daily Data'!H266) | J266: =IF($E266="","",E266-H266-I266) | K266: =IF($E266="","",IF(A266<HLP_ChangeDate,HLP_Legacy,HLP_Current)) | L266: =IF($E266="","",J266/(1-K266)) | M266: =IF($E266="","",'Daily Data'!I266) | N266: =IF($E266="","",M266*(1-K266)-I266) | O266: 299433 | P266: =IF($E266="","",(L266+F266+M266)*K266) | Q266: =IF($E266="","",L266*K266) | R266: =IF($E266="","",F266*K266) | S266: =IF($E266="","",M266*K266) | T266: =IF(OR($E266="",B266=0),"",L266/B266*10000) | U266: =IF(OR($E266="",C266=0),"",F266/C266*10000) | V266: =IF(OR($E266="",D266=0),"",M266/D266*10000)
A267: 45921 | B267: ='Daily Data'!B267 | C267: ='Daily Data'!D267 | D267: ='Daily Data'!C267 | E267: =IF('Daily Data'!E267="","",'Daily Data'!E267) | F267: =IF($E267="","",'Daily Data'!F267) | G267: =IF($E267="","",'Daily Data'!G267) | H267: =IF($E267="","",(1-K267)*F267-G267) | I267: =IF($E267="","",'Daily Data'!H267) | J267: =IF($E267="","",E267-H267-I267) | K267: =IF($E267="","",IF(A267<HLP_ChangeDate,HLP_Legacy,HLP_Current)) | L267: =IF($E267="","",J267/(1-K267)) | M267: =IF($E267="","",'Daily Data'!I267) | N267: =IF($E267="","",M267*(1-K267)-I267) | O267: 230812 | P267: =IF($E267="","",(L267+F267+M267)*K267) | Q267: =IF($E267="","",L267*K267) | R267: =IF($E267="","",F267*K267) | S267: =IF($E267="","",M267*K267) | T267: =IF(OR($E267="",B267=0),"",L267/B267*10000) | U267: =IF(OR($E267="",C267=0),"",F267/C267*10000) | V267: =IF(OR($E267="",D267=0),"",M267/D267*10000)
A268: 45922 | B268: ='Daily Data'!B268 | C268: ='Daily Data'!D268 | D268: ='Daily Data'!C268 | E268: =IF('Daily Data'!E268="","",'Daily Data'!E268) | F268: =IF($E268="","",'Daily Data'!F268) | G268: =IF($E268="","",'Daily Data'!G268) | H268: =IF($E268="","",(1-K268)*F268-G268) | I268: =IF($E268="","",'Daily Data'!H268) | J268: =IF($E268="","",E268-H268-I268) | K268: =IF($E268="","",IF(A268<HLP_ChangeDate,HLP_Legacy,HLP_Current)) | L268: =IF($E268="","",J268/(1-K268)) | M268: =IF($E268="","",'Daily Data'!I268) | N268: =IF($E268="","",M268*(1-K268)-I268) | O268: 262234 | P268: =IF($E268="","",(L268+F268+M268)*K268) | Q268: =IF($E268="","",L268*K268) | R268: =IF($E268="","",F268*K268) | S268: =IF($E268="","",M268*K268) | T268: =IF(OR($E268="",B268=0),"",L268/B268*10000) | U268: =IF(OR($E268="",C268=0),"",F268/C268*10000) | V268: =IF(OR($E268="",D268=0),"",M268/D268*10000)
A269: 45923 | B269: ='Daily Data'!B269 | C269: ='Daily Data'!D269 | D269: ='Daily Data'!C269 | E269: =IF('Daily Data'!E269="","",'Daily Data'!E269) | F269: =IF($E269="","",'Daily Data'!F269) | G269: =IF($E269="","",'Daily Data'!G269) | H269: =IF($E269="","",(1-K269)*F269-G269) | I269: =IF($E269="","",'Daily Data'!H269) | J269: =IF($E269="","",E269-H269-I269) | K269: =IF($E269="","",IF(A269<HLP_ChangeDate,HLP_Legacy,HLP_Current)) | L269: =IF($E269="","",J269/(1-K269)) | M269: =IF($E269="","",'Daily Data'!I269) | N269: =IF($E269="","",M269*(1-K269)-I269) | O269: 208485 | P269: =IF($E269="","",(L269+F269+M269)*K269) | Q269: =IF($E269="","",L269*K269) | R269: =IF($E269="","",F269*K269) | S269: =IF($E269="","",M269*K269) | T269: =IF(OR($E269="",B269=0),"",L269/B269*10000) | U269: =IF(OR($E269="",C269=0),"",F269/C269*10000) | V269: =IF(OR($E269="",D269=0),"",M269/D269*10000)
A270: 45924 | B270: ='Daily Data'!B270 | C270: ='Daily Data'!D270 | D270: ='Daily Data'!C270 | E270: =IF('Daily Data'!E270="","",'Daily Data'!E270) | F270: =IF($E270="","",'Daily Data'!F270) | G270: =IF($E270="","",'Daily Data'!G270) | H270: =IF($E270="","",(1-K270)*F270-G270) | I270: =IF($E270="","",'Daily Data'!H270) | J270: =IF($E270="","",E270-H270-I270) | K270: =IF($E270="","",IF(A270<HLP_ChangeDate,HLP_Legacy,HLP_Current)) | L270: =IF($E270="","",J270/(1-K270)) | M270: =IF($E270="","",'Daily Data'!I270) | N270: =IF($E270="","",M270*(1-K270)-I270) | O270: 194550 | P270: =IF($E270="","",(L270+F270+M270)*K270) | Q270: =IF($E270="","",L270*K270) | R270: =IF($E270="","",F270*K270) | S270: =IF($E270="","",M270*K270) | T270: =IF(OR($E270="",B270=0),"",L270/B270*10000) | U270: =IF(OR($E270="",C270=0),"",F270/C270*10000) | V270: =IF(OR($E270="",D270=0),"",M270/D270*10000)
... A508: 46162 | B508: ='Daily Data'!B508 | C508: ='Daily Data'!D508 | D508: ='Daily Data'!C508 | E508: =IF('Daily Data'!E508="","",'Daily Data'!E508) | F508: =IF($E508="","",'Daily Data'!F508) | G508: =IF($E508="","",'Daily Data'!G508) | H508: =IF($E508="","",(1-K508)*F508-G508) | I508: =IF($E508="","",'Daily Data'!H508) | J508: =IF($E508="","",E508-H508-I508) | K508: =IF($E508="","",IF(A508<HLP_ChangeDate,HLP_Legacy,HLP_Current)) | L508: =IF($E508="","",J508/(1-K508)) | M508: =IF($E508="","",'Daily Data'!I508) | N508: =IF($E508="","",M508*(1-K508)-I508) | O508: 89113 | P508: =IF($E508="","",(L508+F508+M508)*K508) | Q508: =IF($E508="","",L508*K508) | R508: =IF($E508="","",F508*K508) | S508: =IF($E508="","",M508*K508) | T508: =IF(OR($E508="",B508=0),"",L508/B508*10000) | U508: =IF(OR($E508="",C508=0),"",F508/C508*10000) | V508: =IF(OR($E508="",D508=0),"",M508/D508*10000)

Sheet OTS Breakdown
A1: OTS BREAKDOWN — historical Outstanding Token Supply, daily 2025-01-01 → 2026-05-20. Cols B–P = the schedule itself; cols Q–Y = formula verification + burn decomposition (audit + projection). For PROJECTION: project Buyback (D) from HC Rev / HYPE price, project Daily Emission (E), project the three burn streams (W/X/Y); then S,Q,U give projected AF, FE, CumBurns, which feed OTS (O).
B2: SUPPLY FLOWS | I2: OUTSTANDING TOKEN SUPPLY (OTS = 1bn HYPE − the five buckets) | Q2: FORMULA VERIFICATION (running balances; should ≈ 0) | W2: BURN DECOMPOSITION (Daily Burn = EVM + Auction + AF) | Z2: STAKING (ASXN actuals + implied APR) | AE2: OTS COMPOSITION (OTS = Circulating + Core Contributors)
A3: Date | B3: Revenue → Buyback ($) | C3: HYPE Price ($) | D3: HYPE Bought Back (HYPE) | E3: Emissions / Staking Rewards (HYPE) | F3: Fees Burned (HYPE) | G3: Team Tokens Unlocked (HYPE) | H3: Cumulative Team Vested (HYPE) | I3: Initial Supply (HYPE) | J3: (−) Future Emissions Reserve (HYPE) | K3: (−) Hyper Foundation (HYPE) | L3: (−) Assistance Fund (HYPE) | M3: (−) Community Grants (HYPE) | N3: (−) Cumulative Fees Burnt (HYPE) | O3: =Outstanding Token Supply (HYPE) | P3: OTS Value ($) | Q3: FE — Formula (running) | R3: FE — Match (Data−Formula) | S3: AF — Pure Buyback Formula | T3: AF — Match (Data−Formula) | U3: CumBurns — Running Sum | V3: CumBurns — Match (Data−Formula) | W3: Burn: EVM gas (HYPE) | X3: Burn: HIP-1 auction (HYPE) | Y3: Burn: AF / other (HYPE) — residual | Z3: Active Stake (M HYPE) | AA3: Inactive Stake (M HYPE) | AB3: Total Stake (M HYPE) | AC3: Implied Staking APR | AD3: % of OTS Staked | AE3: Team Locked Remaining (M HYPE) | AF3: Circulating Supply (M HYPE)
A4: 45658 | B4: =IF('Daily Data'!E4="","",'Daily Data'!E4) | C4: 24 | D4: 48753.47 | E4: 24499.354 | F4: 941.1022 | H4: =SUM($G$4:G4) | I4: 1000000000 | J4: 4.2798028e+08 | K4: 60000000 | L4: 11719551 | M4: 3000000 | N4: 111035.77 | O4: =IF(OR(I4="",J4="",L4="",N4=""),"",I4-J4-K4-L4-M4-N4) | P4: =IF(OR(O4="",C4=""),"",O4*C4) | Q4: =J4 | R4: =IF(OR(J4="",Q4=""),"",J4-Q4) | S4: =L4 | T4: =IF(OR(L4="",S4=""),"",L4-S4) | U4: =N4 | V4: =IF(OR(N4="",U4=""),"",N4-U4) | W4: =IF(OR(C4="",C4=0,'Daily Data'!J4=""),"",'Daily Data'!J4/C4) | X4: =IF(OR(C4="",C4=0,'Daily Data'!K4=""),"",'Daily Data'!K4/C4) | Y4: =IF(OR(F4="",W4="",X4=""),"",F4-W4-X4) | Z4: 363.65 | AA4: 64.17 | AB4: =Z4+AA4 | AC4: =IF(OR(E4="",E4=0,AB4=""),"",E4*365/(AB4*1000000)) | AD4: =IF(OR(O4="",O4=0,AB4=""),"",(AB4*1000000)/O4) | AE4: =IF(H4="","",(Team_Genesis-H4)/1000000) | AF4: =IF(OR(O4="",AE4=""),"",(O4-AE4*1000000)/1000000)
A5: 45659 | B5: =IF('Daily Data'!E5="","",'Daily Data'!E5) | C5: 26.31 | D5: 37230.03 | E5: 24851.902 | F5: 920.9016 | H5: =SUM($G$4:G5) | I5: 1000000000 | J5: =J4-E5 | K5: 60000000 | L5: 11756781 | M5: 3000000 | N5: 111956.67 | O5: =IF(OR(I5="",J5="",L5="",N5=""),"",I5-J5-K5-L5-M5-N5) | P5: =IF(OR(O5="",C5=""),"",O5*C5) | Q5: =Q4-E5 | R5: =IF(OR(J5="",Q5=""),"",J5-Q5) | S5: =IF(D5="",S4,S4+D5) | T5: =IF(OR(L5="",S5=""),"",L5-S5) | U5: =IF(F5="",U4,U4+F5) | V5: =IF(OR(N5="",U5=""),"",N5-U5) | W5: =IF(OR(C5="",C5=0,'Daily Data'!J5=""),"",'Daily Data'!J5/C5) | X5: =IF(OR(C5="",C5=0,'Daily Data'!K5=""),"",'Daily Data'!K5/C5) | Y5: =IF(OR(F5="",W5="",X5=""),"",F5-W5-X5) | Z5: 363.65 | AA5: 64.17 | AB5: =Z5+AA5 | AC5: =IF(OR(E5="",E5=0,AB5=""),"",E5*365/(AB5*1000000)) | AD5: =IF(OR(O5="",O5=0,AB5=""),"",(AB5*1000000)/O5) | AE5: =IF(H5="","",(Team_Genesis-H5)/1000000) | AF5: =IF(OR(O5="",AE5=""),"",(O5-AE5*1000000)/1000000)
A6: 45660 | B6: =IF('Daily Data'!E6="","",'Daily Data'!E6) | C6: 23.15 | D6: 55732.01 | E6: 25219.868 | F6: 905.5316 | H6: =SUM($G$4:G6) | I6: 1000000000 | J6: =J5-E6 | K6: 60000000 | L6: 11812513 | M6: 3000000 | N6: 112862.2 | O6: =IF(OR(I6="",J6="",L6="",N6=""),"",I6-J6-K6-L6-M6-N6) | P6: =IF(OR(O6="",C6=""),"",O6*C6) | Q6: =Q5-E6 | R6: =IF(OR(J6="",Q6=""),"",J6-Q6) | S6: =IF(D6="",S5,S5+D6) | T6: =IF(OR(L6="",S6=""),"",L6-S6) | U6: =IF(F6="",U5,U5+F6) | V6: =IF(OR(N6="",U6=""),"",N6-U6) | W6: =IF(OR(C6="",C6=0,'Daily Data'!J6=""),"",'Daily Data'!J6/C6) | X6: =IF(OR(C6="",C6=0,'Daily Data'!K6=""),"",'Daily Data'!K6/C6) | Y6: =IF(OR(F6="",W6="",X6=""),"",F6-W6-X6) | Z6: 363.65 | AA6: 64.17 | AB6: =Z6+AA6 | AC6: =IF(OR(E6="",E6=0,AB6=""),"",E6*365/(AB6*1000000)) | AD6: =IF(OR(O6="",O6=0,AB6=""),"",(AB6*1000000)/O6) | AE6: =IF(H6="","",(Team_Genesis-H6)/1000000) | AF6: =IF(OR(O6="",AE6=""),"",(O6-AE6*1000000)/1000000)
A7: 45661 | B7: =IF('Daily Data'!E7="","",'Daily Data'!E7) | C7: 24.43 | D7: 34281.41 | E7: 25452.778 | F7: 1232.8801 | H7: =SUM($G$4:G7) | I7: 1000000000 | J7: =J6-E7 | K7: 60000000 | L7: 11846794 | M7: 3000000 | N7: 114095.08 | O7: =IF(OR(I7="",J7="",L7="",N7=""),"",I7-J7-K7-L7-M7-N7) | P7: =IF(OR(O7="",C7=""),"",O7*C7) | Q7: =Q6-E7 | R7: =IF(OR(J7="",Q7=""),"",J7-Q7) | S7: =IF(D7="",S6,S6+D7) | T7: =IF(OR(L7="",S7=""),"",L7-S7) | U7: =IF(F7="",U6,U6+F7) | V7: =IF(OR(N7="",U7=""),"",N7-U7) | W7: =IF(OR(C7="",C7=0,'Daily Data'!J7=""),"",'Daily Data'!J7/C7) | X7: =IF(OR(C7="",C7=0,'Daily Data'!K7=""),"",'Daily Data'!K7/C7) | Y7: =IF(OR(F7="",W7="",X7=""),"",F7-W7-X7) | Z7: 363.65 | AA7: 64.17 | AB7: =Z7+AA7 | AC7: =IF(OR(E7="",E7=0,AB7=""),"",E7*365/(AB7*1000000)) | AD7: =IF(OR(O7="",O7=0,AB7=""),"",(AB7*1000000)/O7) | AE7: =IF(H7="","",(Team_Genesis-H7)/1000000) | AF7: =IF(OR(O7="",AE7=""),"",(O7-AE7*1000000)/1000000)
A8: 45662 | B8: =IF('Daily Data'!E8="","",'Daily Data'!E8) | C8: 25.02 | D8: 42553.47 | E8: 25665.111 | F8: 617.3145 | H8: =SUM($G$4:G8) | I8: 1000000000 | J8: =J7-E8 | K8: 60000000 | L8: 11889348 | M8: 3000000 | N8: 114712.4 | O8: =IF(OR(I8="",J8="",L8="",N8=""),"",I8-J8-K8-L8-M8-N8) | P8: =IF(OR(O8="",C8=""),"",O8*C8) | Q8: =Q7-E8 | R8: =IF(OR(J8="",Q8=""),"",J8-Q8) | S8: =IF(D8="",S7,S7+D8) | T8: =IF(OR(L8="",S8=""),"",L8-S8) | U8: =IF(F8="",U7,U7+F8) | V8: =IF(OR(N8="",U8=""),"",N8-U8) | W8: =IF(OR(C8="",C8=0,'Daily Data'!J8=""),"",'Daily Data'!J8/C8) | X8: =IF(OR(C8="",C8=0,'Daily Data'!K8=""),"",'Daily Data'!K8/C8) | Y8: =IF(OR(F8="",W8="",X8=""),"",F8-W8-X8) | Z8: 363.65 | AA8: 64.17 | AB8: =Z8+AA8 | AC8: =IF(OR(E8="",E8=0,AB8=""),"",E8*365/(AB8*1000000)) | AD8: =IF(OR(O8="",O8=0,AB8=""),"",(AB8*1000000)/O8) | AE8: =IF(H8="","",(Team_Genesis-H8)/1000000) | AF8: =IF(OR(O8="",AE8=""),"",(O8-AE8*1000000)/1000000)
A9: 45663 | B9: =IF('Daily Data'!E9="","",'Daily Data'!E9) | C9: 24.4 | D9: 43787.34 | E9: 25789.885 | F9: 447.5855 | H9: =SUM($G$4:G9) | I9: 1000000000 | J9: =J8-E9 | K9: 60000000 | L9: 11933135 | M9: 3000000 | N9: 115159.98 | O9: =IF(OR(I9="",J9="",L9="",N9=""),"",I9-J9-K9-L9-M9-N9) | P9: =IF(OR(O9="",C9=""),"",O9*C9) | Q9: =Q8-E9 | R9: =IF(OR(J9="",Q9=""),"",J9-Q9) | S9: =IF(D9="",S8,S8+D9) | T9: =IF(OR(L9="",S9=""),"",L9-S9) | U9: =IF(F9="",U8,U8+F9) | V9: =IF(OR(N9="",U9=""),"",N9-U9) | W9: =IF(OR(C9="",C9=0,'Daily Data'!J9=""),"",'Daily Data'!J9/C9) | X9: =IF(OR(C9="",C9=0,'Daily Data'!K9=""),"",'Daily Data'!K9/C9) | Y9: =IF(OR(F9="",W9="",X9=""),"",F9-W9-X9) | Z9: 363.65 | AA9: 64.17 | AB9: =Z9+AA9 | AC9: =IF(OR(E9="",E9=0,AB9=""),"",E9*365/(AB9*1000000)) | AD9: =IF(OR(O9="",O9=0,AB9=""),"",(AB9*1000000)/O9) | AE9: =IF(H9="","",(Team_Genesis-H9)/1000000) | AF9: =IF(OR(O9="",AE9=""),"",(O9-AE9*1000000)/1000000)
A10: 45664 | B10: =IF('Daily Data'!E10="","",'Daily Data'!E10) | C10: 25.23 | D10: 58651.7 | E10: 25854.611 | F10: 718.7295 | H10: =SUM($G$4:G10) | I10: 1000000000 | J10: =J9-E10 | K10: 60000000 | L10: 11991787 | M10: 3000000 | N10: 115878.71 | O10: =IF(OR(I10="",J10="",L10="",N10=""),"",I10-J10-K10-L10-M10-N10) | P10: =IF(OR(O10="",C10=""),"",O10*C10) | Q10: =Q9-E10 | R10: =IF(OR(J10="",Q10=""),"",J10-Q10) | S10: =IF(D10="",S9,S9+D10) | T10: =IF(OR(L10="",S10=""),"",L10-S10) | U10: =IF(F10="",U9,U9+F10) | V10: =IF(OR(N10="",U10=""),"",N10-U10) | W10: =IF(OR(C10="",C10=0,'Daily Data'!J10=""),"",'Daily Data'!J10/C10) | X10: =IF(OR(C10="",C10=0,'Daily Data'!K10=""),"",'Daily Data'!K10/C10) | Y10: =IF(OR(F10="",W10="",X10=""),"",F10-W10-X10) | Z10: 363.65 | AA10: 64.17 | AB10: =Z10+AA10 | AC10: =IF(OR(E10="",E10=0,AB10=""),"",E10*365/(AB10*1000000)) | AD10: =IF(OR(O10="",O10=0,AB10=""),"",(AB10*1000000)/O10) | AE10: =IF(H10="","",(Team_Genesis-H10)/1000000) | AF10: =IF(OR(O10="",AE10=""),"",(O10-AE10*1000000)/1000000)
