Workbook

Sheet Daily Model
A1: HYPERLIQUID (HYPE) — DAILY MODEL. Volumes -> Gross Fees -> Fee→Revenue bridge (−HLP, −Unit, −HIP-3 deployer; builder is on-top) -> Revenue per segment (sum = HyperCore = hyperscreener) -> + HyperEVM + Auction = Total Revenue. Then AF/supply & OTS. Daily 2024-11-30 → 2026-06-04. Hover headers for source. blue=source · black=formula · green=cross-check
B2: VOLUME ($) | F2: HIP-3 VOLUME BY CATEGORY ($) | M2: GROSS FEES ($) [user-paid] | R2: FEE → REVENUE BRIDGE [deductions, $] | Z2: REVENUE TO HYPERCORE ($) | AG2: IMPLIED TAKE-RATE (bps) | AJ2: OTHER REVENUE ($) | AM2: ASSISTANCE FUND & SUPPLY | AV2: OTS (Hyperliquid Strategies basis)
A3: Date | B3: Core Crypto Perp Vol ($) | C3: HIP-3 Perp Vol ($) | D3: Spot Vol ($) | E3: HIP-4 Vol ($) | F3: HIP-3 Commodities ($) | G3: HIP-3 Crypto ($) | H3: HIP-3 FX ($) | I3: HIP-3 Indices ($) | J3: HIP-3 Pre-IPO ($) | K3: HIP-3 Stocks ($) | L3: HIP-3 Cat Total ($) | M3: Core Crypto Perp Fees ($) | N3: HIP-3 Gross Fees ($) | O3: Spot Fees incl Unit ($) | P3: HIP-4 Fees ($) | Q3: Total Gross Fees ($) | R3: HLP Rate | S3: (-) HLP on Core Perp ($) | T3: (-) HLP on HIP-3 ($) | U3: (-) HLP on Spot ($) | V3: (-) Unit Protocol Fees ($) | W3: (-) HIP-3 Deployer Fees ($) | X3: Total Deductions ($) | Y3: Builder Code Fees [on-top, not deducted] ($) | Z3: Core Crypto Perp Revenue ($) | AA3: HIP-3 Revenue ($) | AB3: Spot Revenue ($) | AC3: HIP-4 Revenue ($) | AD3: =HyperCore Revenue (model) ($) | AE3: HyperCore Revenue [hyperscreener] ($) | AF3: Check: model - hyperscreener ($) | AG3: Core Perp Take-Rate (bps) | AH3: HIP-3 Take-Rate (bps) | AI3: Spot Take-Rate (bps) | AJ3: HyperEVM Burn ($) | AK3: Auction Burn ($) | AL3: Total Revenue ($) | AM3: Revenue -> AF ($) | AN3: Buyback HYPE | AO3: Buyback Avg Price ($) | AP3: AF HYPE Balance | AQ3: Staking Emissions (HYPE) | AR3: Fee Burn (HYPE) | AS3: Team Tokens Unlocked (HYPE) | AT3: HYPE Staked (M) | AU3: Implied Staking Yield | AV3: (-) Future Emissions & CR (HYPE) | AW3: (-) Hyper Foundation (HYPE) | AX3: (-) Assistance Fund (HYPE) | AY3: (-) Community Grants (HYPE) | AZ3: (-) HC&EVM Fee Burns (HYPE) | BA3: =OTS (HYPE) | BB3: Core Contributors Locked (M) | BC3: Circulating Token Supply (M) | BD3: OTS Value ($)
A4: 45626 | B4: 1.9278396e+09 | D4: 460835741 | R4: 0.03 | AG4: =IF(OR(B4="",B4=0,M4=""),"",M4/B4*10000) | AH4: =IF(OR(C4="",C4=0),"",N4/C4*10000) | AI4: =IF(OR(D4="",D4=0),"",O4/D4*10000) | AP4: 8714980.2 | AQ4: 0 | AR4: 32364.464 | AV4: 0 | AW4: 60100000 | AX4: 8714980.2 | AY4: 3100000 | AZ4: =1000000000-999967635.536 | BA4: =1000000000-AV4-AW4-AX4-AY4-AZ4 | BB4: 244.9 | BC4: =BA4/1000000-BB4 | BD4: =BA4*8.64
A5: 45627 | B5: 2.2309523e+09 | D5: 382137710 | R5: 0.03 | AG5: =IF(OR(B5="",B5=0,M5=""),"",M5/B5*10000) | AH5: =IF(OR(C5="",C5=0),"",N5/C5*10000) | AI5: =IF(OR(D5="",D5=0),"",O5/D5*10000) | AP5: 9336088.4 | AQ5: 0 | AR5: 10604.896 | AV5: 0 | AW5: 60100000 | AX5: 9336088.4 | AY5: 3100000 | AZ5: =1000000000-999957030.64 | BA5: =1000000000-AV5-AW5-AX5-AY5-AZ5 | BB5: 244.9 | BC5: =BA5/1000000-BB5 | BD5: =BA5*8.9
A6: 45628 | B6: 5.3331258e+09 | D6: 320571512 | R6: 0.03 | AG6: =IF(OR(B6="",B6=0,M6=""),"",M6/B6*10000) | AH6: =IF(OR(C6="",C6=0),"",N6/C6*10000) | AI6: =IF(OR(D6="",D6=0),"",O6/D6*10000) | AP6: 9336088.4 | AQ6: 0 | AR6: 2916.6523 | AV6: 0 | AW6: 60100000 | AX6: 9336088.4 | AY6: 3100000 | AZ6: =1000000000-999954113.9877 | BA6: =1000000000-AV6-AW6-AX6-AY6-AZ6 | BB6: 244.9 | BC6: =BA6/1000000-BB6 | BD6: =BA6*8.66
A7: 45629 | B7: 4.8819819e+09 | D7: 302890343 | R7: 0.03 | AG7: =IF(OR(B7="",B7=0,M7=""),"",M7/B7*10000) | AH7: =IF(OR(C7="",C7=0),"",N7/C7*10000) | AI7: =IF(OR(D7="",D7=0),"",O7/D7*10000) | AP7: 9933598.1 | AQ7: 0 | AR7: 3632.1998 | AV7: 0 | AW7: 60100000 | AX7: 9933598.1 | AY7: 3100000 | AZ7: =1000000000-999950481.7879 | BA7: =1000000000-AV7-AW7-AX7-AY7-AZ7 | BB7: 244.9 | BC7: =BA7/1000000-BB7 | BD7: =BA7*8.96
A8: 45630 | B8: 6.2259185e+09 | D8: 318696984 | R8: 0.03 | AG8: =IF(OR(B8="",B8=0,M8=""),"",M8/B8*10000) | AH8: =IF(OR(C8="",C8=0),"",N8/C8*10000) | AI8: =IF(OR(D8="",D8=0),"",O8/D8*10000) | AP8: 10009960 | AQ8: 0 | AR8: 3743.7999 | AV8: 0 | AW8: 60100000 | AX8: 10009960 | AY8: 3100000 | AZ8: =1000000000-999946737.988 | BA8: =1000000000-AV8-AW8-AX8-AY8-AZ8 | BB8: 244.9 | BC8: =BA8/1000000-BB8 | BD8: =BA8*11.08
A9: 45631 | B9: 9.7895628e+09 | D9: 323114172 | R9: 0.03 | AG9: =IF(OR(B9="",B9=0,M9=""),"",M9/B9*10000) | AH9: =IF(OR(C9="",C9=0),"",N9/C9*10000) | AI9: =IF(OR(D9="",D9=0),"",O9/D9*10000) | AP9: 10009960 | AQ9: 0 | AR9: 4041.2964 | AV9: 0 | AW9: 60100000 | AX9: 10009960 | AY9: 3100000 | AZ9: =1000000000-999942696.6916 | BA9: =1000000000-AV9-AW9-AX9-AY9-AZ9 | BB9: 244.9 | BC9: =BA9/1000000-BB9 | BD9: =BA9*11.4
A10: 45632 | B10: 7.8114744e+09 | D10: 218646771 | R10: 0.03 | AG10: =IF(OR(B10="",B10=0,M10=""),"",M10/B10*10000) | AH10: =IF(OR(C10="",C10=0),"",N10/C10*10000) | AI10: =IF(OR(D10="",D10=0),"",O10/D10*10000) | AP10: 10428491 | AQ10: 0 | AR10: 3472.5047 | AV10: 0 | AW10: 60100000 | AX10: 10428491 | AY10: 3100000 | AZ10: =1000000000-999939224.1869 | BA10: =1000000000-AV10-AW10-AX10-AY10-AZ10 | BB10: 244.9 | BC10: =BA10/1000000-BB10 | BD10: =BA10*12.69
A11: 45633 | B11: 2.8624379e+09 | D11: 182104753 | R11: 0.03 | AG11: =IF(OR(B11="",B11=0,M11=""),"",M11/B11*10000) | AH11: =IF(OR(C11="",C11=0),"",N11/C11*10000) | AI11: =IF(OR(D11="",D11=0),"",O11/D11*10000) | AP11: 10428491 | AQ11: 0 | AR11: 2255.2254 | AV11: 0 | AW11: 60100000 | AX11: 10428491 | AY11: 3100000 | AZ11: =1000000000-999936968.9615 | BA11: =1000000000-AV11-AW11-AX11-AY11-AZ11 | BB11: 244.9 | BC11: =BA11/1000000-BB11 | BD11: =BA11*13.83
A12: 45634 | B12: 3.2527988e+09 | D12: 136064768 | R12: 0.03 | AG12: =IF(OR(B12="",B12=0,M12=""),"",M12/B12*10000) | AH12: =IF(OR(C12="",C12=0),"",N12/C12*10000) | AI12: =IF(OR(D12="",D12=0),"",O12/D12*10000) | AP12: 10428491 | AQ12: 0 | AR12: 1897.8347 | AV12: 0 | AW12: 60100000 | AX12: 10428491 | AY12: 3100000 | AZ12: =1000000000-999935071.1268 | BA12: =1000000000-AV12-AW12-AX12-AY12-AZ12 | BB12: 244.9 | BC12: =BA12/1000000-BB12 | BD12: =BA12*14.12
A13: 45635 | B13: 5.3063589e+09 | D13: 270676721 | R13: 0.03 | AG13: =IF(OR(B13="",B13=0,M13=""),"",M13/B13*10000) | AH13: =IF(OR(C13="",C13=0),"",N13/C13*10000) | AI13: =IF(OR(D13="",D13=0),"",O13/D13*10000) | AP13: 10654299 | AQ13: 0 | AR13: 1284.1908 | AV13: 0 | AW13: 60100000 | AX13: 10654299 | AY13: 3100000 | AZ13: =1000000000-999933786.9361 | BA13: =1000000000-AV13-AW13-AX13-AY13-AZ13 | BB13: 244.9 | BC13: =BA13/1000000-BB13 | BD13: =BA13*14.02
A14: 45636 | B14: 1.0009954e+10 | D14: 208129108 | R14: 0.03 | AG14: =IF(OR(B14="",B14=0,M14=""),"",M14/B14*10000) | AH14: =IF(OR(C14="",C14=0),"",N14/C14*10000) | AI14: =IF(OR(D14="",D14=0),"",O14/D14*10000) | AP14: 10654299 | AQ14: 0 | AR14: 2527.2104 | AV14: 0 | AW14: 60100000 | AX14: 10654299 | AY14: 3100000 | AZ14: =1000000000-999931259.7256 | BA14: =1000000000-AV14-AW14-AX14-AY14-AZ14 | BB14: 244.9 | BC14: =BA14/1000000-BB14 | BD14: =BA14*13.54
A15: 45637 | B15: 3.9793992e+09 | D15: 211797447 | R15: 0.03 | AG15: =IF(OR(B15="",B15=0,M15=""),"",M15/B15*10000) | AH15: =IF(OR(C15="",C15=0),"",N15/C15*10000) | AI15: =IF(OR(D15="",D15=0),"",O15/D15*10000) | AP15: 10654299 | AQ15: 0 | AR15: 2003.998 | AV15: 0 | AW15: 60100000 | AX15: 10654299 | AY15: 3100000 | AZ15: =1000000000-999929255.7277 | BA15: =1000000000-AV15-AW15-AX15-AY15-AZ15 | BB15: 244.9 | BC15: =BA15/1000000-BB15 | BD15: =BA15*13.56
A16: 45638 | B16: 4.8390459e+09 | D16: 324908474 | R16: 0.03 | AG16: =IF(OR(B16="",B16=0,M16=""),"",M16/B16*10000) | AH16: =IF(OR(C16="",C16=0),"",N16/C16*10000) | AI16: =IF(OR(D16="",D16=0),"",O16/D16*10000) | AP16: 10654299 | AQ16: 0 | AR16: 1932.7073 | AV16: 0 | AW16: 60100000 | AX16: 10654299 | AY16: 3100000 | AZ16: =1000000000-999927323.0204 | BA16: =1000000000-AV16-AW16-AX16-AY16-AZ16 | BB16: 244.9 | BC16: =BA16/1000000-BB16 | BD16: =BA16*16.11
A17: 45639 | B17: 4.2533193e+09 | D17: 334237923 | R17: 0.03 | AG17: =IF(OR(B17="",B17=0,M17=""),"",M17/B17*10000) | AH17: =IF(OR(C17="",C17=0),"",N17/C17*10000) | AI17: =IF(OR(D17="",D17=0),"",O17/D17*10000) | AP17: 10662922 | AQ17: 0 | AR17: 2435.2699 | AV17: 0 | AW17: 60100000 | AX17: 10662922 | AY17: 3100000 | AZ17: =1000000000-999924887.7505 | BA17: =1000000000-AV17-AW17-AX17-AY17-AZ17 | BB17: 244.9 | BC17: =BA17/1000000-BB17 | BD17: =BA17*18.04
A18: 45640 | B18: 3.1705221e+09 | D18: 546075604 | R18: 0.03 | AG18: =IF(OR(B18="",B18=0,M18=""),"",M18/B18*10000) | AH18: =IF(OR(C18="",C18=0),"",N18/C18*10000) | AI18: =IF(OR(D18="",D18=0),"",O18/D18*10000) | AP18: 10761181 | AQ18: 0 | AR18: 1602.2514 | AV18: 0 | AW18: 60100000 | AX18: 10761181 | AY18: 3100000 | AZ18: =1000000000-999923285.4991 | BA18: =1000000000-AV18-AW18-AX18-AY18-AZ18 | BB18: 244.9 | BC18: =BA18/1000000-BB18 | BD18: =BA18*19.49
A19: 45641 | B19: 3.786629e+09 | D19: 517821521 | R19: 0.03 | AG19: =IF(OR(B19="",B19=0,M19=""),"",M19/B19*10000) | AH19: =IF(OR(C19="",C19=0),"",N19/C19*10000) | AI19: =IF(OR(D19="",D19=0),"",O19/D19*10000) | AP19: 10761181 | AQ19: 0 | AR19: 2857.882 | AV19: 0 | AW19: 60100000 | AX19: 10761181 | AY19: 3100000 | AZ19: =1000000000-999920427.6171 | BA19: =1000000000-AV19-AW19-AX19-AY19-AZ19 | BB19: 244.9 | BC19: =BA19/1000000-BB19 | BD19: =BA19*24.15
A20: 45642 | B20: 6.2672948e+09 | D20: 552491542 | R20: 0.03 | AG20: =IF(OR(B20="",B20=0,M20=""),"",M20/B20*10000) | AH20: =IF(OR(C20="",C20=0),"",N20/C20*10000) | AI20: =IF(OR(D20="",D20=0),"",O20/D20*10000) | AP20: 10761181 | AQ20: 0 | AR20: 2419.5935 | AV20: 0 | AW20: 60100000 | AX20: 10761181 | AY20: 3100000 | AZ20: =1000000000-999918008.0235 | BA20: =1000000000-AV20-AW20-AX20-AY20-AZ20 | BB20: 244.9 | BC20: =BA20/1000000-BB20 | BD20: =BA20*23.88
A21: 45643 | B21: 5.5938649e+09 | D21: 533018011 | R21: 0.03 | AG21: =IF(OR(B21="",B21=0,M21=""),"",M21/B21*10000) | AH21: =IF(OR(C21="",C21=0),"",N21/C21*10000) | AI21: =IF(OR(D21="",D21=0),"",O21/D21*10000) | AP21: 10789059 | AQ21: 0 | AR21: 2278.9176 | AV21: 0 | AW21: 60100000 | AX21: 10789059 | AY21: 3100000 | AZ21: =1000000000-999915729.1059 | BA21: =1000000000-AV21-AW21-AX21-AY21-AZ21 | BB21: 244.9 | BC21: =BA21/1000000-BB21 | BD21: =BA21*27.24
A22: 45644 | B22: 8.540539e+09 | D22: 472394527 | R22: 0.03 | AG22: =IF(OR(B22="",B22=0,M22=""),"",M22/B22*10000) | AH22: =IF(OR(C22="",C22=0),"",N22/C22*10000) | AI22: =IF(OR(D22="",D22=0),"",O22/D22*10000) | AP22: 10927485 | AQ22: 0 | AR22: 2263.4293 | AV22: 0 | AW22: 60100000 | AX22: 10927485 | AY22: 3100000 | AZ22: =1000000000-999913465.6766 | BA22: =1000000000-AV22-AW22-AX22-AY22-AZ22 | BB22: 244.9 | BC22: =BA22/1000000-BB22 | BD22: =BA22*25.57
A23: 45645 | B23: 1.1512982e+10 | D23: 564194362 | R23: 0.03 | AG23: =IF(OR(B23="",B23=0,M23=""),"",M23/B23*10000) | AH23: =IF(OR(C23="",C23=0),"",N23/C23*10000) | AI23: =IF(OR(D23="",D23=0),"",O23/D23*10000) | AP23: 11039806 | AQ23: 0 | AR23: 2427.0823 | AV23: 0 | AW23: 60100000 | AX23: 11039806 | AY23: 3100000 | AZ23: =1000000000-999911038.5943 | BA23: =1000000000-AV23-AW23-AX23-AY23-AZ23 | BB23: 244.9 | BC23: =BA23/1000000-BB23 | BD23: =BA23*23.22
A24: 45646 | B24: 9.8785211e+09 | D24: 703781781 | R24: 0.03 | AG24: =IF(OR(B24="",B24=0,M24=""),"",M24/B24*10000) | AH24: =IF(OR(C24="",C24=0),"",N24/C24*10000) | AI24: =IF(OR(D24="",D24=0),"",O24/D24*10000) | AP24: 11180484 | AQ24: 0 | AR24: 2863.6836 | AV24: 0 | AW24: 60100000 | AX24: 11180484 | AY24: 3100000 | AZ24: =1000000000-999908174.9107 | BA24: =1000000000-AV24-AW24-AX24-AY24-AZ24 | BB24: 244.9 | BC24: =BA24/1000000-BB24 | BD24: =BA24*24.92
A25: 45647 | B25: 5.2030282e+09 | D25: 527191283 | R25: 0.03 | AG25: =IF(OR(B25="",B25=0,M25=""),"",M25/B25*10000) | AH25: =IF(OR(C25="",C25=0),"",N25/C25*10000) | AI25: =IF(OR(D25="",D25=0),"",O25/D25*10000) | AP25: 11244814 | AQ25: 0 | AR25: 3033.9608 | AV25: 0 | AW25: 60100000 | AX25: 11244814 | AY25: 3100000 | AZ25: =1000000000-999905140.9499 | BA25: =1000000000-AV25-AW25-AX25-AY25-AZ25 | BB25: 244.9 | BC25: =BA25/1000000-BB25 | BD25: =BA25*29.74
A26: 45648 | B26: 4.6867317e+09 | D26: 471634786 | R26: 0.03 | AG26: =IF(OR(B26="",B26=0,M26=""),"",M26/B26*10000) | AH26: =IF(OR(C26="",C26=0),"",N26/C26*10000) | AI26: =IF(OR(D26="",D26=0),"",O26/D26*10000) | AP26: 11290999 | AQ26: 0 | AR26: 2044.5791 | AV26: 0 | AW26: 60100000 | AX26: 11290999 | AY26: 3100000 | AZ26: =1000000000-999903096.3708 | BA26: =1000000000-AV26-AW26-AX26-AY26-AZ26 | BB26: 244.9 | BC26: =BA26/1000000-BB26 | BD26: =BA26*32.02
A27: 45649 | B27: 6.1684635e+09 | D27: 375034673 | O27: 96254 | R27: 0.03 | AG27: =IF(OR(B27="",B27=0,M27=""),"",M27/B27*10000) | AH27: =IF(OR(C27="",C27=0),"",N27/C27*10000) | AI27: =IF(OR(D27="",D27=0),"",O27/D27*10000) | AP27: 11346521 | AQ27: 0 | AR27: 2041.5641 | AV27: 0 | AW27: 60100000 | AX27: 11346521 | AY27: 3100000 | AZ27: =1000000000-999901054.8066 | BA27: =1000000000-AV27-AW27-AX27-AY27-AZ27 | BB27: 244.9 | BC27: =BA27/1000000-BB27 | BD27: =BA27*28.47
A28: 45650 | B28: 4.4015652e+09 | D28: 319403848 | O28: 47315 | R28: 0.03 | AG28: =IF(OR(B28="",B28=0,M28=""),"",M28/B28*10000) | AH28: =IF(OR(C28="",C28=0),"",N28/C28*10000) | AI28: =IF(OR(D28="",D28=0),"",O28/D28*10000) | AP28: 11396463 | AQ28: 0 | AR28: 3190.5125 | AV28: 0 | AW28: 60100000 | AX28: 11396463 | AY28: 3100000 | AZ28: =1000000000-999897864.2941 | BA28: =1000000000-AV28-AW28-AX28-AY28-AZ28 | BB28: 244.9 | BC28: =BA28/1000000-BB28 | BD28: =BA28*28.6
A29: 45651 | B29: 3.0900267e+09 | D29: 310480616 | O29: 43561 | R29: 0.03 | AG29: =IF(OR(B29="",B29=0,M29=""),"",M29/B29*10000) | AH29: =IF(OR(C29="",C29=0),"",N29/C29*10000) | AI29: =IF(OR(D29="",D29=0),"",O29/D29*10000) | AP29: 11439370 | AQ29: 0 | AR29: 1832.8323 | AV29: 0 | AW29: 60100000 | AX29: 11439370 | AY29: 3100000 | AZ29: =1000000000-999896031.4618 | BA29: =1000000000-AV29-AW29-AX29-AY29-AZ29 | BB29: 244.9 | BC29: =BA29/1000000-BB29 | BD29: =BA29*29.78
A30: 45652 | B30: 3.8974652e+09 | D30: 214091088 | O30: 44254 | R30: 0.03 | AG30: =IF(OR(B30="",B30=0,M30=""),"",M30/B30*10000) | AH30: =IF(OR(C30="",C30=0),"",N30/C30*10000) | AI30: =IF(OR(D30="",D30=0),"",O30/D30*10000) | AP30: 11468143 | AQ30: 0 | AR30: 1373.0965 | AV30: 0 | AW30: 60100000 | AX30: 11468143 | AY30: 3100000 | AZ30: =1000000000-999894658.3653 | BA30: =1000000000-AV30-AW30-AX30-AY30-AZ30 | BB30: 244.9 | BC30: =BA30/1000000-BB30 | BD30: =BA30*26.55
A31: 45653 | B31: 3.8894731e+09 | D31: 216391282 | O31: 28523 | R31: 0.03 | AG31: =IF(OR(B31="",B31=0,M31=""),"",M31/B31*10000) | AH31: =IF(OR(C31="",C31=0),"",N31/C31*10000) | AI31: =IF(OR(D31="",D31=0),"",O31/D31*10000) | AP31: 11513537 | AQ31: 0 | AR31: 1476.4802 | AV31: 0 | AW31: 60100000 | AX31: 11513537 | AY31: 3100000 | AZ31: =1000000000-999893181.8852 | BA31: =1000000000-AV31-AW31-AX31-AY31-AZ31 | BB31: 244.9 | BC31: =BA31/1000000-BB31 | BD31: =BA31*27.22
A32: 45654 | B32: 2.0771914e+09 | D32: 212391739 | O32: 28430 | R32: 0.03 | AG32: =IF(OR(B32="",B32=0,M32=""),"",M32/B32*10000) | AH32: =IF(OR(C32="",C32=0),"",N32/C32*10000) | AI32: =IF(OR(D32="",D32=0),"",O32/D32*10000) | AP32: 11560234 | AQ32: 0 | AR32: 1019.7076 | AT32: 301.00122 | AV32: 0 | AW32: 60100000 | AX32: 11560234 | AY32: 3100000 | AZ32: =1000000000-999892162.1776 | BA32: =1000000000-AV32-AW32-AX32-AY32-AZ32 | BB32: 244.9 | BC32: =BA32/1000000-BB32 | BD32: =BA32*27.11
A33: 45655 | B33: 1.9659316e+09 | D33: 342862746 | O33: 31496 | R33: 0.03 | AG33: =IF(OR(B33="",B33=0,M33=""),"",M33/B33*10000) | AH33: =IF(OR(C33="",C33=0),"",N33/C33*10000) | AI33: =IF(OR(D33="",D33=0),"",O33/D33*10000) | AP33: 11594187 | AQ33: 0 | AR33: 774.4857 | AT33: 301.02439 | AV33: 4.2805004e+08 | AW33: 60100000 | AX33: 11594187 | AY33: 3100000 | AZ33: =1000000000-999891387.692 | BA33: =1000000000-AV33-AW33-AX33-AY33-AZ33 | BB33: 244.9 | BC33: =BA33/1000000-BB33 | BD33: =BA33*29.26
A34: 45656 | B34: 4.6971711e+09 | D34: 267028183 | O34: 49113 | R34: 0.03 | AG34: =IF(OR(B34="",B34=0,M34=""),"",M34/B34*10000) | AH34: =IF(OR(C34="",C34=0),"",N34/C34*10000) | AI34: =IF(OR(D34="",D34=0),"",O34/D34*10000) | AP34: 11626219 | AQ34: 22225.362 | AR34: 611.8805 | AT34: 301.10728 | AU34: 0.02518994 | AV34: 4.2802781e+08 | AW34: 60100000 | AX34: 11626219 | AY34: 3100000 | AZ34: =1000000000-999890775.8115 | BA34: =1000000000-AV34-AW34-AX34-AY34-AZ34 | BB34: 244.9 | BC34: =BA34/1000000-BB34 | BD34: =BA34*27.44
A35: 45657 | B35: 3.4505145e+09 | D35: 225503235 | O35: 42962 | R35: 0.03 | AG35: =IF(OR(B35="",B35=0,M35=""),"",M35/B35*10000) | AH35: =IF(OR(C35="",C35=0),"",N35/C35*10000) | AI35: =IF(OR(D35="",D35=0),"",O35/D35*10000) | AP35: 11670797 | AQ35: 23028.588 | AR35: 870.4787 | AT35: 352.79856 | AU35: 0.02334773 | AV35: 4.2800478e+08 | AW35: 60100000 | AX35: 11670797 | AY35: 3100000 | AZ35: =1000000000-999889905.3328 | BA35: =1000000000-AV35-AW35-AX35-AY35-AZ35 | BB35: 244.9 | BC35: =BA35/1000000-BB35 | BD35: =BA35*26.95
A36: 45658 | B36: 2.1572568e+09 | D36: 256438336 | O36: 30141 | R36: 0.03 | AG36: =IF(OR(B36="",B36=0,M36=""),"",M36/B36*10000) | AH36: =IF(OR(C36="",C36=0),"",N36/C36*10000) | AI36: =IF(OR(D36="",D36=0),"",O36/D36*10000) | AP36: 11719551 | AQ36: 24499.354 | AR36: 941.1022 | AT36: 372.98553 | AU36: 0.02271528 | AV36: 4.2798028e+08 | AW36: 60100000 | AX36: 11719551 | AY36: 3100000 | AZ36: =1000000000-999888964.2307 | BA36: =1000000000-AV36-AW36-AX36-AY36-AZ36 | BB36: 244.9 | BC36: =BA36/1000000-BB36 | BD36: =BA36*24
A37: 45659 | B37: 3.6458162e+09 | D37: 267239456 | O37: 41666 | R37: 0.03 | AG37: =IF(OR(B37="",B37=0,M37=""),"",M37/B37*10000) | AH37: =IF(OR(C37="",C37=0),"",N37/C37*10000) | AI37: =IF(OR(D37="",D37=0),"",O37/D37*10000) | AP37: 11756781 | AQ37: 24851.902 | AR37: 920.9016 | AT37: 380.75278 | AU37: 0.02249743 | AV37: 4.2795543e+08 | AW37: 60100000 | AX37: 11756781 | AY37: 3100000 | AZ37: =1000000000-999888043.3291 | BA37: =1000000000-AV37-AW37-AX37-AY37-AZ37 | BB37: 244.9 | BC37: =BA37/1000000-BB37 | BD37: =BA37*26.31
A38: 45660 | B38: 3.5731603e+09 | D38: 176550030 | O38: 37005 | R38: 0.03 | AG38: =IF(OR(B38="",B38=0,M38=""),"",M38/B38*10000) | AH38: =IF(OR(C38="",C38=0),"",N38/C38*10000) | AI38: =IF(OR(D38="",D38=0),"",O38/D38*10000) | AP38: 11812513 | AQ38: 25219.868 | AR38: 905.5316 | AT38: 390.38936 | AU38: 0.02223263 | AV38: 4.2793021e+08 | AW38: 60100000 | AX38: 11812513 | AY38: 3100000 | AZ38: =1000000000-999887137.7975 | BA38: =1000000000-AV38-AW38-AX38-AY38-AZ38 | BB38: 244.9 | BC38: =BA38/1000000-BB38 | BD38: =BA38*23.15
A39: 45661 | B39: 2.5062676e+09 | D39: 119410641 | O39: 25377 | R39: 0.03 | AG39: =IF(OR(B39="",B39=0,M39=""),"",M39/B39*10000) | AH39: =IF(OR(C39="",C39=0),"",N39/C39*10000) | AI39: =IF(OR(D39="",D39=0),"",O39/D39*10000) | AP39: 11846794 | AQ39: 25452.778 | AR39: 1232.8801 | AT39: 395.40416 | AU39: 0.02224488 | AV39: 4.2790476e+08 | AW39: 60100000 | AX39: 11846794 | AY39: 3100000 | AZ39: =1000000000-999885904.9174 | BA39: =1000000000-AV39-AW39-AX39-AY39-AZ39 | BB39: 244.9 | BC39: =BA39/1000000-BB39 | BD39: =BA39*24.43
A40: 45662 | B40: 2.149149e+09 | D40: 174388254 | O40: 19262 | R40: 0.03 | AG40: =IF(OR(B40="",B40=0,M40=""),"",M40/B40*10000) | AH40: =IF(OR(C40="",C40=0),"",N40/C40*10000) | AI40: =IF(OR(D40="",D40=0),"",O40/D40*10000) | AP40: 11889348 | AQ40: 25665.111 | AR40: 617.3145 | AT40: 401.89251 | AU40: 0.02206674 | AV40: 4.2787909e+08 | AW40: 60100000 | AX40: 11889348 | AY40: 3100000 | AZ40: =1000000000-999885287.603 | BA40: =1000000000-AV40-AW40-AX40-AY40-AZ40 | BB40: 244.9 | BC40: =BA40/1000000-BB40 | BD40: =BA40*25.02
...

Sheet Quarterly Model
A1: HYPERLIQUID (HYPE) — QUARTERLY MODEL. Same columns as Daily. Flows summed (SUMIFS); stocks/rates at period-end; OTS at quarter-end.
D2: VOLUME ($) | H2: HIP-3 VOLUME BY CATEGORY ($) | O2: GROSS FEES ($) [user-paid] | T2: FEE → REVENUE BRIDGE [deductions, $] | AB2: REVENUE TO HYPERCORE ($) | AI2: IMPLIED TAKE-RATE (bps) | AL2: OTHER REVENUE ($) | AO2: ASSISTANCE FUND & SUPPLY | AX2: OTS (Hyperliquid Strategies basis)
A3: Quarter | B3: Start | C3: End | D3: Core Crypto Perp Vol ($) | E3: HIP-3 Perp Vol ($) | F3: Spot Vol ($) | G3: HIP-4 Vol ($) | H3: HIP-3 Commodities ($) | I3: HIP-3 Crypto ($) | J3: HIP-3 FX ($) | K3: HIP-3 Indices ($) | L3: HIP-3 Pre-IPO ($) | M3: HIP-3 Stocks ($) | N3: HIP-3 Cat Total ($) | O3: Core Crypto Perp Fees ($) | P3: HIP-3 Gross Fees ($) | Q3: Spot Fees incl Unit ($) | R3: HIP-4 Fees ($) | S3: Total Gross Fees ($) | T3: HLP Rate | U3: (-) HLP on Core Perp ($) | V3: (-) HLP on HIP-3 ($) | W3: (-) HLP on Spot ($) | X3: (-) Unit Protocol Fees ($) | Y3: (-) HIP-3 Deployer Fees ($) | Z3: Total Deductions ($) | AA3: Builder Code Fees [on-top, not deducted] ($) | AB3: Core Crypto Perp Revenue ($) | AC3: HIP-3 Revenue ($) | AD3: Spot Revenue ($) | AE3: HIP-4 Revenue ($) | AF3: =HyperCore Revenue (model) ($) | AG3: HyperCore Revenue [hyperscreener] ($) | AH3: Check: model - hyperscreener ($) | AI3: Core Perp Take-Rate (bps) | AJ3: HIP-3 Take-Rate (bps) | AK3: Spot Take-Rate (bps) | AL3: HyperEVM Burn ($) | AM3: Auction Burn ($) | AN3: Total Revenue ($) | AO3: Revenue -> AF ($) | AP3: Buyback HYPE | AQ3: Buyback Avg Price ($) | AR3: AF HYPE Balance | AS3: Staking Emissions (HYPE) | AT3: Fee Burn (HYPE) | AU3: Team Tokens Unlocked (HYPE) | AV3: HYPE Staked (M) | AW3: Implied Staking Yield | AX3: (-) Future Emissions & CR (HYPE) | AY3: (-) Hyper Foundation (HYPE) | AZ3: (-) Assistance Fund (HYPE) | BA3: (-) Community Grants (HYPE) | BB3: (-) HC&EVM Fee Burns (HYPE) | BC3: =OTS (HYPE) | BD3: Core Contributors Locked (M) | BE3: Circulating Token Supply (M) | BF3: OTS Value ($)
A4: Q4 2024 (Nov-Dec) | B4: 45626 | C4: 45657 | D4: =SUMIFS('Daily Model'!$B$4:$B$555,'Daily Model'!$A$4:$A$555,">="&$B4,'Daily Model'!$A$4:$A$555,"<="&$C4) | E4: =SUMIFS('Daily Model'!$C$4:$C$555,'Daily Model'!$A$4:$A$555,">="&$B4,'Daily Model'!$A$4:$A$555,"<="&$C4) | F4: =SUMIFS('Daily Model'!$D$4:$D$555,'Daily Model'!$A$4:$A$555,">="&$B4,'Daily Model'!$A$4:$A$555,"<="&$C4) | G4: =SUMIFS('Daily Model'!$E$4:$E$555,'Daily Model'!$A$4:$A$555,">="&$B4,'Daily Model'!$A$4:$A$555,"<="&$C4) | H4: =SUMIFS('Daily Model'!$F$4:$F$555,'Daily Model'!$A$4:$A$555,">="&$B4,'Daily Model'!$A$4:$A$555,"<="&$C4) | I4: =SUMIFS('Daily Model'!$G$4:$G$555,'Daily Model'!$A$4:$A$555,">="&$B4,'Daily Model'!$A$4:$A$555,"<="&$C4) | J4: =SUMIFS('Daily Model'!$H$4:$H$555,'Daily Model'!$A$4:$A$555,">="&$B4,'Daily Model'!$A$4:$A$555,"<="&$C4) | K4: =SUMIFS('Daily Model'!$I$4:$I$555,'Daily Model'!$A$4:$A$555,">="&$B4,'Daily Model'!$A$4:$A$555,"<="&$C4) | L4: =SUMIFS('Daily Model'!$J$4:$J$555,'Daily Model'!$A$4:$A$555,">="&$B4,'Daily Model'!$A$4:$A$555,"<="&$C4) | M4: =SUMIFS('Daily Model'!$K$4:$K$555,'Daily Model'!$A$4:$A$555,">="&$B4,'Daily Model'!$A$4:$A$555,"<="&$C4) | N4: =SUMIFS('Daily Model'!$L$4:$L$555,'Daily Model'!$A$4:$A$555,">="&$B4,'Daily Model'!$A$4:$A$555,"<="&$C4) | O4: =SUMIFS('Daily Model'!$M$4:$M$555,'Daily Model'!$A$4:$A$555,">="&$B4,'Daily Model'!$A$4:$A$555,"<="&$C4) | P4: =SUMIFS('Daily Model'!$N$4:$N$555,'Daily Model'!$A$4:$A$555,">="&$B4,'Daily Model'!$A$4:$A$555,"<="&$C4) | Q4: =SUMIFS('Daily Model'!$O$4:$O$555,'Daily Model'!$A$4:$A$555,">="&$B4,'Daily Model'!$A$4:$A$555,"<="&$C4) | R4: =SUMIFS('Daily Model'!$P$4:$P$555,'Daily Model'!$A$4:$A$555,">="&$B4,'Daily Model'!$A$4:$A$555,"<="&$C4) | S4: =SUMIFS('Daily Model'!$Q$4:$Q$555,'Daily Model'!$A$4:$A$555,">="&$B4,'Daily Model'!$A$4:$A$555,"<="&$C4) | U4: =SUMIFS('Daily Model'!$S$4:$S$555,'Daily Model'!$A$4:$A$555,">="&$B4,'Daily Model'!$A$4:$A$555,"<="&$C4) | V4: =SUMIFS('Daily Model'!$T$4:$T$555,'Daily Model'!$A$4:$A$555,">="&$B4,'Daily Model'!$A$4:$A$555,"<="&$C4) | W4: =SUMIFS('Daily Model'!$U$4:$U$555,'Daily Model'!$A$4:$A$555,">="&$B4,'Daily Model'!$A$4:$A$555,"<="&$C4) | X4: =SUMIFS('Daily Model'!$V$4:$V$555,'Daily Model'!$A$4:$A$555,">="&$B4,'Daily Model'!$A$4:$A$555,"<="&$C4) | Y4: =SUMIFS('Daily Model'!$W$4:$W$555,'Daily Model'!$A$4:$A$555,">="&$B4,'Daily Model'!$A$4:$A$555,"<="&$C4) | Z4: =SUMIFS('Daily Model'!$X$4:$X$555,'Daily Model'!$A$4:$A$555,">="&$B4,'Daily Model'!$A$4:$A$555,"<="&$C4) | AA4: =SUMIFS('Daily Model'!$Y$4:$Y$555,'Daily Model'!$A$4:$A$555,">="&$B4,'Daily Model'!$A$4:$A$555,"<="&$C4) | AB4: =SUMIFS('Daily Model'!$Z$4:$Z$555,'Daily Model'!$A$4:$A$555,">="&$B4,'Daily Model'!$A$4:$A$555,"<="&$C4) | AC4: =SUMIFS('Daily Model'!$AA$4:$AA$555,'Daily Model'!$A$4:$A$555,">="&$B4,'Daily Model'!$A$4:$A$555,"<="&$C4) | AD4: =SUMIFS('Daily Model'!$AB$4:$AB$555,'Daily Model'!$A$4:$A$555,">="&$B4,'Daily Model'!$A$4:$A$555,"<="&$C4) | AE4: =SUMIFS('Daily Model'!$AC$4:$AC$555,'Daily Model'!$A$4:$A$555,">="&$B4,'Daily Model'!$A$4:$A$555,"<="&$C4) | AF4: =SUMIFS('Daily Model'!$AD$4:$AD$555,'Daily Model'!$A$4:$A$555,">="&$B4,'Daily Model'!$A$4:$A$555,"<="&$C4) | AG4: =SUMIFS('Daily Model'!$AE$4:$AE$555,'Daily Model'!$A$4:$A$555,">="&$B4,'Daily Model'!$A$4:$A$555,"<="&$C4) | AH4: =AF4-AG4 | AI4: =IF(D4=0,"",O4/D4*10000) | AJ4: =IF(E4=0,"",P4/E4*10000) | AK4: =IF(F4=0,"",Q4/F4*10000) | AL4: =SUMIFS('Daily Model'!$AJ$4:$AJ$555,'Daily Model'!$A$4:$A$555,">="&$B4,'Daily Model'!$A$4:$A$555,"<="&$C4) | AM4: =SUMIFS('Daily Model'!$AK$4:$AK$555,'Daily Model'!$A$4:$A$555,">="&$B4,'Daily Model'!$A$4:$A$555,"<="&$C4) | AN4: =SUMIFS('Daily Model'!$AL$4:$AL$555,'Daily Model'!$A$4:$A$555,">="&$B4,'Daily Model'!$A$4:$A$555,"<="&$C4) | AO4: =SUMIFS('Daily Model'!$AM$4:$AM$555,'Daily Model'!$A$4:$A$555,">="&$B4,'Daily Model'!$A$4:$A$555,"<="&$C4) | AP4: =SUMIFS('Daily Model'!$AN$4:$AN$555,'Daily Model'!$A$4:$A$555,">="&$B4,'Daily Model'!$A$4:$A$555,"<="&$C4) | AQ4: =IF(AP4=0,"",AO4/AP4) | AR4: 11670797 | AS4: =SUMIFS('Daily Model'!$AQ$4:$AQ$555,'Daily Model'!$A$4:$A$555,">="&$B4,'Daily Model'!$A$4:$A$555,"<="&$C4) | AT4: =SUMIFS('Daily Model'!$AR$4:$AR$555,'Daily Model'!$A$4:$A$555,">="&$B4,'Daily Model'!$A$4:$A$555,"<="&$C4) | AU4: =SUMIFS('Daily Model'!$AS$4:$AS$555,'Daily Model'!$A$4:$A$555,">="&$B4,'Daily Model'!$A$4:$A$555,"<="&$C4) | AV4: 352.7986 | AW4: 0.0233 | AX4: 4.2800478e+08 | AY4: 60100000 | AZ4: 11670797 | BA4: 3100000 | BB4: 110094.67 | BC4: 4.9701433e+08 | BD4: 244.9 | BE4: 252.1143 | BF4: 1.3394536e+10
A5: Q1 2025 | B5: 45658 | C5: 45747 | D5: =SUMIFS('Daily Model'!$B$4:$B$555,'Daily Model'!$A$4:$A$555,">="&$B5,'Daily Model'!$A$4:$A$555,"<="&$C5) | E5: =SUMIFS('Daily Model'!$C$4:$C$555,'Daily Model'!$A$4:$A$555,">="&$B5,'Daily Model'!$A$4:$A$555,"<="&$C5) | F5: =SUMIFS('Daily Model'!$D$4:$D$555,'Daily Model'!$A$4:$A$555,">="&$B5,'Daily Model'!$A$4:$A$555,"<="&$C5) | G5: =SUMIFS('Daily Model'!$E$4:$E$555,'Daily Model'!$A$4:$A$555,">="&$B5,'Daily Model'!$A$4:$A$555,"<="&$C5) | H5: =SUMIFS('Daily Model'!$F$4:$F$555,'Daily Model'!$A$4:$A$555,">="&$B5,'Daily Model'!$A$4:$A$555,"<="&$C5) | I5: =SUMIFS('Daily Model'!$G$4:$G$555,'Daily Model'!$A$4:$A$555,">="&$B5,'Daily Model'!$A$4:$A$555,"<="&$C5) | J5: =SUMIFS('Daily Model'!$H$4:$H$555,'Daily Model'!$A$4:$A$555,">="&$B5,'Daily Model'!$A$4:$A$555,"<="&$C5) | K5: =SUMIFS('Daily Model'!$I$4:$I$555,'Daily Model'!$A$4:$A$555,">="&$B5,'Daily Model'!$A$4:$A$555,"<="&$C5) | L5: =SUMIFS('Daily Model'!$J$4:$J$555,'Daily Model'!$A$4:$A$555,">="&$B5,'Daily Model'!$A$4:$A$555,"<="&$C5) | M5: =SUMIFS('Daily Model'!$K$4:$K$555,'Daily Model'!$A$4:$A$555,">="&$B5,'Daily Model'!$A$4:$A$555,"<="&$C5) | N5: =SUMIFS('Daily Model'!$L$4:$L$555,'Daily Model'!$A$4:$A$555,">="&$B5,'Daily Model'!$A$4:$A$555,"<="&$C5) | O5: =SUMIFS('Daily Model'!$M$4:$M$555,'Daily Model'!$A$4:$A$555,">="&$B5,'Daily Model'!$A$4:$A$555,"<="&$C5) | P5: =SUMIFS('Daily Model'!$N$4:$N$555,'Daily Model'!$A$4:$A$555,">="&$B5,'Daily Model'!$A$4:$A$555,"<="&$C5) | Q5: =SUMIFS('Daily Model'!$O$4:$O$555,'Daily Model'!$A$4:$A$555,">="&$B5,'Daily Model'!$A$4:$A$555,"<="&$C5) | R5: =SUMIFS('Daily Model'!$P$4:$P$555,'Daily Model'!$A$4:$A$555,">="&$B5,'Daily Model'!$A$4:$A$555,"<="&$C5) | S5: =SUMIFS('Daily Model'!$Q$4:$Q$555,'Daily Model'!$A$4:$A$555,">="&$B5,'Daily Model'!$A$4:$A$555,"<="&$C5) | U5: =SUMIFS('Daily Model'!$S$4:$S$555,'Daily Model'!$A$4:$A$555,">="&$B5,'Daily Model'!$A$4:$A$555,"<="&$C5) | V5: =SUMIFS('Daily Model'!$T$4:$T$555,'Daily Model'!$A$4:$A$555,">="&$B5,'Daily Model'!$A$4:$A$555,"<="&$C5) | W5: =SUMIFS('Daily Model'!$U$4:$U$555,'Daily Model'!$A$4:$A$555,">="&$B5,'Daily Model'!$A$4:$A$555,"<="&$C5) | X5: =SUMIFS('Daily Model'!$V$4:$V$555,'Daily Model'!$A$4:$A$555,">="&$B5,'Daily Model'!$A$4:$A$555,"<="&$C5) | Y5: =SUMIFS('Daily Model'!$W$4:$W$555,'Daily Model'!$A$4:$A$555,">="&$B5,'Daily Model'!$A$4:$A$555,"<="&$C5) | Z5: =SUMIFS('Daily Model'!$X$4:$X$555,'Daily Model'!$A$4:$A$555,">="&$B5,'Daily Model'!$A$4:$A$555,"<="&$C5) | AA5: =SUMIFS('Daily Model'!$Y$4:$Y$555,'Daily Model'!$A$4:$A$555,">="&$B5,'Daily Model'!$A$4:$A$555,"<="&$C5) | AB5: =SUMIFS('Daily Model'!$Z$4:$Z$555,'Daily Model'!$A$4:$A$555,">="&$B5,'Daily Model'!$A$4:$A$555,"<="&$C5) | AC5: =SUMIFS('Daily Model'!$AA$4:$AA$555,'Daily Model'!$A$4:$A$555,">="&$B5,'Daily Model'!$A$4:$A$555,"<="&$C5) | AD5: =SUMIFS('Daily Model'!$AB$4:$AB$555,'Daily Model'!$A$4:$A$555,">="&$B5,'Daily Model'!$A$4:$A$555,"<="&$C5) | AE5: =SUMIFS('Daily Model'!$AC$4:$AC$555,'Daily Model'!$A$4:$A$555,">="&$B5,'Daily Model'!$A$4:$A$555,"<="&$C5) | AF5: =SUMIFS('Daily Model'!$AD$4:$AD$555,'Daily Model'!$A$4:$A$555,">="&$B5,'Daily Model'!$A$4:$A$555,"<="&$C5) | AG5: =SUMIFS('Daily Model'!$AE$4:$AE$555,'Daily Model'!$A$4:$A$555,">="&$B5,'Daily Model'!$A$4:$A$555,"<="&$C5) | AH5: =AF5-AG5 | AI5: =IF(D5=0,"",O5/D5*10000) | AJ5: =IF(E5=0,"",P5/E5*10000) | AK5: =IF(F5=0,"",Q5/F5*10000) | AL5: =SUMIFS('Daily Model'!$AJ$4:$AJ$555,'Daily Model'!$A$4:$A$555,">="&$B5,'Daily Model'!$A$4:$A$555,"<="&$C5) | AM5: =SUMIFS('Daily Model'!$AK$4:$AK$555,'Daily Model'!$A$4:$A$555,">="&$B5,'Daily Model'!$A$4:$A$555,"<="&$C5) | AN5: =SUMIFS('Daily Model'!$AL$4:$AL$555,'Daily Model'!$A$4:$A$555,">="&$B5,'Daily Model'!$A$4:$A$555,"<="&$C5) | AO5: =SUMIFS('Daily Model'!$AM$4:$AM$555,'Daily Model'!$A$4:$A$555,">="&$B5,'Daily Model'!$A$4:$A$555,"<="&$C5) | AP5: =SUMIFS('Daily Model'!$AN$4:$AN$555,'Daily Model'!$A$4:$A$555,">="&$B5,'Daily Model'!$A$4:$A$555,"<="&$C5) | AQ5: =IF(AP5=0,"",AO5/AP5) | AR5: 18407964 | AS5: =SUMIFS('Daily Model'!$AQ$4:$AQ$555,'Daily Model'!$A$4:$A$555,">="&$B5,'Daily Model'!$A$4:$A$555,"<="&$C5) | AT5: =SUMIFS('Daily Model'!$AR$4:$AR$555,'Daily Model'!$A$4:$A$555,">="&$B5,'Daily Model'!$A$4:$A$555,"<="&$C5) | AU5: =SUMIFS('Daily Model'!$AS$4:$AS$555,'Daily Model'!$A$4:$A$555,">="&$B5,'Daily Model'!$A$4:$A$555,"<="&$C5) | AV5: 421.3321 | AW5: 0.0217 | AX5: 4.2563427e+08 | AY5: 60100000 | AZ5: 18407964 | BA5: 3100000 | BB5: 195016.42 | BC5: 4.9256275e+08 | BD5: 244.9 | BE5: 247.6628 | BF5: 6.1471832e+09
A6: Q2 2025 | B6: 45748 | C6: 45838 | D6: =SUMIFS('Daily Model'!$B$4:$B$555,'Daily Model'!$A$4:$A$555,">="&$B6,'Daily Model'!$A$4:$A$555,"<="&$C6) | E6: =SUMIFS('Daily Model'!$C$4:$C$555,'Daily Model'!$A$4:$A$555,">="&$B6,'Daily Model'!$A$4:$A$555,"<="&$C6) | F6: =SUMIFS('Daily Model'!$D$4:$D$555,'Daily Model'!$A$4:$A$555,">="&$B6,'Daily Model'!$A$4:$A$555,"<="&$C6) | G6: =SUMIFS('Daily Model'!$E$4:$E$555,'Daily Model'!$A$4:$A$555,">="&$B6,'Daily Model'!$A$4:$A$555,"<="&$C6) | H6: =SUMIFS('Daily Model'!$F$4:$F$555,'Daily Model'!$A$4:$A$555,">="&$B6,'Daily Model'!$A$4:$A$555,"<="&$C6) | I6: =SUMIFS('Daily Model'!$G$4:$G$555,'Daily Model'!$A$4:$A$555,">="&$B6,'Daily Model'!$A$4:$A$555,"<="&$C6) | J6: =SUMIFS('Daily Model'!$H$4:$H$555,'Daily Model'!$A$4:$A$555,">="&$B6,'Daily Model'!$A$4:$A$555,"<="&$C6) | K6: =SUMIFS('Daily Model'!$I$4:$I$555,'Daily Model'!$A$4:$A$555,">="&$B6,'Daily Model'!$A$4:$A$555,"<="&$C6) | L6: =SUMIFS('Daily Model'!$J$4:$J$555,'Daily Model'!$A$4:$A$555,">="&$B6,'Daily Model'!$A$4:$A$555,"<="&$C6) | M6: =SUMIFS('Daily Model'!$K$4:$K$555,'Daily Model'!$A$4:$A$555,">="&$B6,'Daily Model'!$A$4:$A$555,"<="&$C6) | N6: =SUMIFS('Daily Model'!$L$4:$L$555,'Daily Model'!$A$4:$A$555,">="&$B6,'Daily Model'!$A$4:$A$555,"<="&$C6) | O6: =SUMIFS('Daily Model'!$M$4:$M$555,'Daily Model'!$A$4:$A$555,">="&$B6,'Daily Model'!$A$4:$A$555,"<="&$C6) | P6: =SUMIFS('Daily Model'!$N$4:$N$555,'Daily Model'!$A$4:$A$555,">="&$B6,'Daily Model'!$A$4:$A$555,"<="&$C6) | Q6: =SUMIFS('Daily Model'!$O$4:$O$555,'Daily Model'!$A$4:$A$555,">="&$B6,'Daily Model'!$A$4:$A$555,"<="&$C6) | R6: =SUMIFS('Daily Model'!$P$4:$P$555,'Daily Model'!$A$4:$A$555,">="&$B6,'Daily Model'!$A$4:$A$555,"<="&$C6) | S6: =SUMIFS('Daily Model'!$Q$4:$Q$555,'Daily Model'!$A$4:$A$555,">="&$B6,'Daily Model'!$A$4:$A$555,"<="&$C6) | U6: =SUMIFS('Daily Model'!$S$4:$S$555,'Daily Model'!$A$4:$A$555,">="&$B6,'Daily Model'!$A$4:$A$555,"<="&$C6) | V6: =SUMIFS('Daily Model'!$T$4:$T$555,'Daily Model'!$A$4:$A$555,">="&$B6,'Daily Model'!$A$4:$A$555,"<="&$C6) | W6: =SUMIFS('Daily Model'!$U$4:$U$555,'Daily Model'!$A$4:$A$555,">="&$B6,'Daily Model'!$A$4:$A$555,"<="&$C6) | X6: =SUMIFS('Daily Model'!$V$4:$V$555,'Daily Model'!$A$4:$A$555,">="&$B6,'Daily Model'!$A$4:$A$555,"<="&$C6) | Y6: =SUMIFS('Daily Model'!$W$4:$W$555,'Daily Model'!$A$4:$A$555,">="&$B6,'Daily Model'!$A$4:$A$555,"<="&$C6) | Z6: =SUMIFS('Daily Model'!$X$4:$X$555,'Daily Model'!$A$4:$A$555,">="&$B6,'Daily Model'!$A$4:$A$555,"<="&$C6) | AA6: =SUMIFS('Daily Model'!$Y$4:$Y$555,'Daily Model'!$A$4:$A$555,">="&$B6,'Daily Model'!$A$4:$A$555,"<="&$C6) | AB6: =SUMIFS('Daily Model'!$Z$4:$Z$555,'Daily Model'!$A$4:$A$555,">="&$B6,'Daily Model'!$A$4:$A$555,"<="&$C6) | AC6: =SUMIFS('Daily Model'!$AA$4:$AA$555,'Daily Model'!$A$4:$A$555,">="&$B6,'Daily Model'!$A$4:$A$555,"<="&$C6) | AD6: =SUMIFS('Daily Model'!$AB$4:$AB$555,'Daily Model'!$A$4:$A$555,">="&$B6,'Daily Model'!$A$4:$A$555,"<="&$C6) | AE6: =SUMIFS('Daily Model'!$AC$4:$AC$555,'Daily Model'!$A$4:$A$555,">="&$B6,'Daily Model'!$A$4:$A$555,"<="&$C6) | AF6: =SUMIFS('Daily Model'!$AD$4:$AD$555,'Daily Model'!$A$4:$A$555,">="&$B6,'Daily Model'!$A$4:$A$555,"<="&$C6) | AG6: =SUMIFS('Daily Model'!$AE$4:$AE$555,'Daily Model'!$A$4:$A$555,">="&$B6,'Daily Model'!$A$4:$A$555,"<="&$C6) | AH6: =AF6-AG6 | AI6: =IF(D6=0,"",O6/D6*10000) | AJ6: =IF(E6=0,"",P6/E6*10000) | AK6: =IF(F6=0,"",Q6/F6*10000) | AL6: =SUMIFS('Daily Model'!$AJ$4:$AJ$555,'Daily Model'!$A$4:$A$555,">="&$B6,'Daily Model'!$A$4:$A$555,"<="&$C6) | AM6: =SUMIFS('Daily Model'!$AK$4:$AK$555,'Daily Model'!$A$4:$A$555,">="&$B6,'Daily Model'!$A$4:$A$555,"<="&$C6) | AN6: =SUMIFS('Daily Model'!$AL$4:$AL$555,'Daily Model'!$A$4:$A$555,">="&$B6,'Daily Model'!$A$4:$A$555,"<="&$C6) | AO6: =SUMIFS('Daily Model'!$AM$4:$AM$555,'Daily Model'!$A$4:$A$555,">="&$B6,'Daily Model'!$A$4:$A$555,"<="&$C6) | AP6: =SUMIFS('Daily Model'!$AN$4:$AN$555,'Daily Model'!$A$4:$A$555,">="&$B6,'Daily Model'!$A$4:$A$555,"<="&$C6) | AQ6: =IF(AP6=0,"",AO6/AP6) | AR6: 25508876 | AS6: =SUMIFS('Daily Model'!$AQ$4:$AQ$555,'Daily Model'!$A$4:$A$555,">="&$B6,'Daily Model'!$A$4:$A$555,"<="&$C6) | AT6: =SUMIFS('Daily Model'!$AR$4:$AR$555,'Daily Model'!$A$4:$A$555,">="&$B6,'Daily Model'!$A$4:$A$555,"<="&$C6) | AU6: =SUMIFS('Daily Model'!$AS$4:$AS$555,'Daily Model'!$A$4:$A$555,">="&$B6,'Daily Model'!$A$4:$A$555,"<="&$C6) | AV6: 422.0714 | AW6: 0.0217 | AX6: 4.2324595e+08 | AY6: 60100000 | AZ6: 25508876 | BA6: 3100000 | BB6: 309088.56 | BC6: 4.8773608e+08 | BD6: 244.9 | BE6: 242.8361 | BF6: 1.9280207e+10
A7: Q3 2025 | B7: 45839 | C7: 45930 | D7: =SUMIFS('Daily Model'!$B$4:$B$555,'Daily Model'!$A$4:$A$555,">="&$B7,'Daily Model'!$A$4:$A$555,"<="&$C7) | E7: =SUMIFS('Daily Model'!$C$4:$C$555,'Daily Model'!$A$4:$A$555,">="&$B7,'Daily Model'!$A$4:$A$555,"<="&$C7) | F7: =SUMIFS('Daily Model'!$D$4:$D$555,'Daily Model'!$A$4:$A$555,">="&$B7,'Daily Model'!$A$4:$A$555,"<="&$C7) | G7: =SUMIFS('Daily Model'!$E$4:$E$555,'Daily Model'!$A$4:$A$555,">="&$B7,'Daily Model'!$A$4:$A$555,"<="&$C7) | H7: =SUMIFS('Daily Model'!$F$4:$F$555,'Daily Model'!$A$4:$A$555,">="&$B7,'Daily Model'!$A$4:$A$555,"<="&$C7) | I7: =SUMIFS('Daily Model'!$G$4:$G$555,'Daily Model'!$A$4:$A$555,">="&$B7,'Daily Model'!$A$4:$A$555,"<="&$C7) | J7: =SUMIFS('Daily Model'!$H$4:$H$555,'Daily Model'!$A$4:$A$555,">="&$B7,'Daily Model'!$A$4:$A$555,"<="&$C7) | K7: =SUMIFS('Daily Model'!$I$4:$I$555,'Daily Model'!$A$4:$A$555,">="&$B7,'Daily Model'!$A$4:$A$555,"<="&$C7) | L7: =SUMIFS('Daily Model'!$J$4:$J$555,'Daily Model'!$A$4:$A$555,">="&$B7,'Daily Model'!$A$4:$A$555,"<="&$C7) | M7: =SUMIFS('Daily Model'!$K$4:$K$555,'Daily Model'!$A$4:$A$555,">="&$B7,'Daily Model'!$A$4:$A$555,"<="&$C7) | N7: =SUMIFS('Daily Model'!$L$4:$L$555,'Daily Model'!$A$4:$A$555,">="&$B7,'Daily Model'!$A$4:$A$555,"<="&$C7) | O7: =SUMIFS('Daily Model'!$M$4:$M$555,'Daily Model'!$A$4:$A$555,">="&$B7,'Daily Model'!$A$4:$A$555,"<="&$C7) | P7: =SUMIFS('Daily Model'!$N$4:$N$555,'Daily Model'!$A$4:$A$555,">="&$B7,'Daily Model'!$A$4:$A$555,"<="&$C7) | Q7: =SUMIFS('Daily Model'!$O$4:$O$555,'Daily Model'!$A$4:$A$555,">="&$B7,'Daily Model'!$A$4:$A$555,"<="&$C7) | R7: =SUMIFS('Daily Model'!$P$4:$P$555,'Daily Model'!$A$4:$A$555,">="&$B7,'Daily Model'!$A$4:$A$555,"<="&$C7) | S7: =SUMIFS('Daily Model'!$Q$4:$Q$555,'Daily Model'!$A$4:$A$555,">="&$B7,'Daily Model'!$A$4:$A$555,"<="&$C7) | U7: =SUMIFS('Daily Model'!$S$4:$S$555,'Daily Model'!$A$4:$A$555,">="&$B7,'Daily Model'!$A$4:$A$555,"<="&$C7) | V7: =SUMIFS('Daily Model'!$T$4:$T$555,'Daily Model'!$A$4:$A$555,">="&$B7,'Daily Model'!$A$4:$A$555,"<="&$C7) | W7: =SUMIFS('Daily Model'!$U$4:$U$555,'Daily Model'!$A$4:$A$555,">="&$B7,'Daily Model'!$A$4:$A$555,"<="&$C7) | X7: =SUMIFS('Daily Model'!$V$4:$V$555,'Daily Model'!$A$4:$A$555,">="&$B7,'Daily Model'!$A$4:$A$555,"<="&$C7) | Y7: =SUMIFS('Daily Model'!$W$4:$W$555,'Daily Model'!$A$4:$A$555,">="&$B7,'Daily Model'!$A$4:$A$555,"<="&$C7) | Z7: =SUMIFS('Daily Model'!$X$4:$X$555,'Daily Model'!$A$4:$A$555,">="&$B7,'Daily Model'!$A$4:$A$555,"<="&$C7) | AA7: =SUMIFS('Daily Model'!$Y$4:$Y$555,'Daily Model'!$A$4:$A$555,">="&$B7,'Daily Model'!$A$4:$A$555,"<="&$C7) | AB7: =SUMIFS('Daily Model'!$Z$4:$Z$555,'Daily Model'!$A$4:$A$555,">="&$B7,'Daily Model'!$A$4:$A$555,"<="&$C7) | AC7: =SUMIFS('Daily Model'!$AA$4:$AA$555,'Daily Model'!$A$4:$A$555,">="&$B7,'Daily Model'!$A$4:$A$555,"<="&$C7) | AD7: =SUMIFS('Daily Model'!$AB$4:$AB$555,'Daily Model'!$A$4:$A$555,">="&$B7,'Daily Model'!$A$4:$A$555,"<="&$C7) | AE7: =SUMIFS('Daily Model'!$AC$4:$AC$555,'Daily Model'!$A$4:$A$555,">="&$B7,'Daily Model'!$A$4:$A$555,"<="&$C7) | AF7: =SUMIFS('Daily Model'!$AD$4:$AD$555,'Daily Model'!$A$4:$A$555,">="&$B7,'Daily Model'!$A$4:$A$555,"<="&$C7) | AG7: =SUMIFS('Daily Model'!$AE$4:$AE$555,'Daily Model'!$A$4:$A$555,">="&$B7,'Daily Model'!$A$4:$A$555,"<="&$C7) | AH7: =AF7-AG7 | AI7: =IF(D7=0,"",O7/D7*10000) | AJ7: =IF(E7=0,"",P7/E7*10000) | AK7: =IF(F7=0,"",Q7/F7*10000) | AL7: =SUMIFS('Daily Model'!$AJ$4:$AJ$555,'Daily Model'!$A$4:$A$555,">="&$B7,'Daily Model'!$A$4:$A$555,"<="&$C7) | AM7: =SUMIFS('Daily Model'!$AK$4:$AK$555,'Daily Model'!$A$4:$A$555,">="&$B7,'Daily Model'!$A$4:$A$555,"<="&$C7) | AN7: =SUMIFS('Daily Model'!$AL$4:$AL$555,'Daily Model'!$A$4:$A$555,">="&$B7,'Daily Model'!$A$4:$A$555,"<="&$C7) | AO7: =SUMIFS('Daily Model'!$AM$4:$AM$555,'Daily Model'!$A$4:$A$555,">="&$B7,'Daily Model'!$A$4:$A$555,"<="&$C7) | AP7: =SUMIFS('Daily Model'!$AN$4:$AN$555,'Daily Model'!$A$4:$A$555,">="&$B7,'Daily Model'!$A$4:$A$555,"<="&$C7) | AQ7: =IF(AP7=0,"",AO7/AP7) | AR7: 31785059 | AS7: =SUMIFS('Daily Model'!$AQ$4:$AQ$555,'Daily Model'!$A$4:$A$555,">="&$B7,'Daily Model'!$A$4:$A$555,"<="&$C7) | AT7: =SUMIFS('Daily Model'!$AR$4:$AR$555,'Daily Model'!$A$4:$A$555,">="&$B7,'Daily Model'!$A$4:$A$555,"<="&$C7) | AU7: =SUMIFS('Daily Model'!$AS$4:$AS$555,'Daily Model'!$A$4:$A$555,">="&$B7,'Daily Model'!$A$4:$A$555,"<="&$C7) | AV7: 425.4931 | AW7: 0.0216 | AX7: 4.2082436e+08 | AY7: 60100000 | AZ7: 31785059 | BA7: 3100000 | BB7: 424925.91 | BC7: 4.8376566e+08 | BD7: 244.9 | BE7: 238.8657 | BF7: 2.2306435e+10
A8: Q4 2025 | B8: 45931 | C8: 46022 | D8: =SUMIFS('Daily Model'!$B$4:$B$555,'Daily Model'!$A$4:$A$555,">="&$B8,'Daily Model'!$A$4:$A$555,"<="&$C8) | E8: =SUMIFS('Daily Model'!$C$4:$C$555,'Daily Model'!$A$4:$A$555,">="&$B8,'Daily Model'!$A$4:$A$555,"<="&$C8) | F8: =SUMIFS('Daily Model'!$D$4:$D$555,'Daily Model'!$A$4:$A$555,">="&$B8,'Daily Model'!$A$4:$A$555,"<="&$C8) | G8: =SUMIFS('Daily Model'!$E$4:$E$555,'Daily Model'!$A$4:$A$555,">="&$B8,'Daily Model'!$A$4:$A$555,"<="&$C8) | H8: =SUMIFS('Daily Model'!$F$4:$F$555,'Daily Model'!$A$4:$A$555,">="&$B8,'Daily Model'!$A$4:$A$555,"<="&$C8) | I8: =SUMIFS('Daily Model'!$G$4:$G$555,'Daily Model'!$A$4:$A$555,">="&$B8,'Daily Model'!$A$4:$A$555,"<="&$C8) | J8: =SUMIFS('Daily Model'!$H$4:$H$555,'Daily Model'!$A$4:$A$555,">="&$B8,'Daily Model'!$A$4:$A$555,"<="&$C8) | K8: =SUMIFS('Daily Model'!$I$4:$I$555,'Daily Model'!$A$4:$A$555,">="&$B8,'Daily Model'!$A$4:$A$555,"<="&$C8) | L8: =SUMIFS('Daily Model'!$J$4:$J$555,'Daily Model'!$A$4:$A$555,">="&$B8,'Daily Model'!$A$4:$A$555,"<="&$C8) | M8: =SUMIFS('Daily Model'!$K$4:$K$555,'Daily Model'!$A$4:$A$555,">="&$B8,'Daily Model'!$A$4:$A$555,"<="&$C8) | N8: =SUMIFS('Daily Model'!$L$4:$L$555,'Daily Model'!$A$4:$A$555,">="&$B8,'Daily Model'!$A$4:$A$555,"<="&$C8) | O8: =SUMIFS('Daily Model'!$M$4:$M$555,'Daily Model'!$A$4:$A$555,">="&$B8,'Daily Model'!$A$4:$A$555,"<="&$C8) | P8: =SUMIFS('Daily Model'!$N$4:$N$555,'Daily Model'!$A$4:$A$555,">="&$B8,'Daily Model'!$A$4:$A$555,"<="&$C8) | Q8: =SUMIFS('Daily Model'!$O$4:$O$555,'Daily Model'!$A$4:$A$555,">="&$B8,'Daily Model'!$A$4:$A$555,"<="&$C8) | R8: =SUMIFS('Daily Model'!$P$4:$P$555,'Daily Model'!$A$4:$A$555,">="&$B8,'Daily Model'!$A$4:$A$555,"<="&$C8) | S8: =SUMIFS('Daily Model'!$Q$4:$Q$555,'Daily Model'!$A$4:$A$555,">="&$B8,'Daily Model'!$A$4:$A$555,"<="&$C8) | U8: =SUMIFS('Daily Model'!$S$4:$S$555,'Daily Model'!$A$4:$A$555,">="&$B8,'Daily Model'!$A$4:$A$555,"<="&$C8) | V8: =SUMIFS('Daily Model'!$T$4:$T$555,'Daily Model'!$A$4:$A$555,">="&$B8,'Daily Model'!$A$4:$A$555,"<="&$C8) | W8: =SUMIFS('Daily Model'!$U$4:$U$555,'Daily Model'!$A$4:$A$555,">="&$B8,'Daily Model'!$A$4:$A$555,"<="&$C8) | X8: =SUMIFS('Daily Model'!$V$4:$V$555,'Daily Model'!$A$4:$A$555,">="&$B8,'Daily Model'!$A$4:$A$555,"<="&$C8) | Y8: =SUMIFS('Daily Model'!$W$4:$W$555,'Daily Model'!$A$4:$A$555,">="&$B8,'Daily Model'!$A$4:$A$555,"<="&$C8) | Z8: =SUMIFS('Daily Model'!$X$4:$X$555,'Daily Model'!$A$4:$A$555,">="&$B8,'Daily Model'!$A$4:$A$555,"<="&$C8) | AA8: =SUMIFS('Daily Model'!$Y$4:$Y$555,'Daily Model'!$A$4:$A$555,">="&$B8,'Daily Model'!$A$4:$A$555,"<="&$C8) | AB8: =SUMIFS('Daily Model'!$Z$4:$Z$555,'Daily Model'!$A$4:$A$555,">="&$B8,'Daily Model'!$A$4:$A$555,"<="&$C8) | AC8: =SUMIFS('Daily Model'!$AA$4:$AA$555,'Daily Model'!$A$4:$A$555,">="&$B8,'Daily Model'!$A$4:$A$555,"<="&$C8) | AD8: =SUMIFS('Daily Model'!$AB$4:$AB$555,'Daily Model'!$A$4:$A$555,">="&$B8,'Daily Model'!$A$4:$A$555,"<="&$C8) | AE8: =SUMIFS('Daily Model'!$AC$4:$AC$555,'Daily Model'!$A$4:$A$555,">="&$B8,'Daily Model'!$A$4:$A$555,"<="&$C8) | AF8: =SUMIFS('Daily Model'!$AD$4:$AD$555,'Daily Model'!$A$4:$A$555,">="&$B8,'Daily Model'!$A$4:$A$555,"<="&$C8) | AG8: =SUMIFS('Daily Model'!$AE$4:$AE$555,'Daily Model'!$A$4:$A$555,">="&$B8,'Daily Model'!$A$4:$A$555,"<="&$C8) | AH8: =AF8-AG8 | AI8: =IF(D8=0,"",O8/D8*10000) | AJ8: =IF(E8=0,"",P8/E8*10000) | AK8: =IF(F8=0,"",Q8/F8*10000) | AL8: =SUMIFS('Daily Model'!$AJ$4:$AJ$555,'Daily Model'!$A$4:$A$555,">="&$B8,'Daily Model'!$A$4:$A$555,"<="&$C8) | AM8: =SUMIFS('Daily Model'!$AK$4:$AK$555,'Daily Model'!$A$4:$A$555,">="&$B8,'Daily Model'!$A$4:$A$555,"<="&$C8) | AN8: =SUMIFS('Daily Model'!$AL$4:$AL$555,'Daily Model'!$A$4:$A$555,">="&$B8,'Daily Model'!$A$4:$A$555,"<="&$C8) | AO8: =SUMIFS('Daily Model'!$AM$4:$AM$555,'Daily Model'!$A$4:$A$555,">="&$B8,'Daily Model'!$A$4:$A$555,"<="&$C8) | AP8: =SUMIFS('Daily Model'!$AN$4:$AN$555,'Daily Model'!$A$4:$A$555,">="&$B8,'Daily Model'!$A$4:$A$555,"<="&$C8) | AQ8: =IF(AP8=0,"",AO8/AP8) | AR8: 37855112 | AS8: =SUMIFS('Daily Model'!$AQ$4:$AQ$555,'Daily Model'!$A$4:$A$555,">="&$B8,'Daily Model'!$A$4:$A$555,"<="&$C8) | AT8: =SUMIFS('Daily Model'!$AR$4:$AR$555,'Daily Model'!$A$4:$A$555,">="&$B8,'Daily Model'!$A$4:$A$555,"<="&$C8) | AU8: =SUMIFS('Daily Model'!$AS$4:$AS$555,'Daily Model'!$A$4:$A$555,">="&$B8,'Daily Model'!$A$4:$A$555,"<="&$C8) | AV8: 432.3217 | AW8: 0.0214 | AX8: 4.1841903e+08 | AY8: 60100000 | AZ8: 37855112 | BA8: 3100000 | BB8: 552936.25 | BC8: 4.7997292e+08 | BD8: 243.1543 | BE8: 236.8187 | BF8: 1.24121e+10
A9: Q1 2026 | B9: 46023 | C9: 46112 | D9: =SUMIFS('Daily Model'!$B$4:$B$555,'Daily Model'!$A$4:$A$555,">="&$B9,'Daily Model'!$A$4:$A$555,"<="&$C9) | E9: =SUMIFS('Daily Model'!$C$4:$C$555,'Daily Model'!$A$4:$A$555,">="&$B9,'Daily Model'!$A$4:$A$555,"<="&$C9) | F9: =SUMIFS('Daily Model'!$D$4:$D$555,'Daily Model'!$A$4:$A$555,">="&$B9,'Daily Model'!$A$4:$A$555,"<="&$C9) | G9: =SUMIFS('Daily Model'!$E$4:$E$555,'Daily Model'!$A$4:$A$555,">="&$B9,'Daily Model'!$A$4:$A$555,"<="&$C9) | H9: =SUMIFS('Daily Model'!$F$4:$F$555,'Daily Model'!$A$4:$A$555,">="&$B9,'Daily Model'!$A$4:$A$555,"<="&$C9) | I9: =SUMIFS('Daily Model'!$G$4:$G$555,'Daily Model'!$A$4:$A$555,">="&$B9,'Daily Model'!$A$4:$A$555,"<="&$C9) | J9: =SUMIFS('Daily Model'!$H$4:$H$555,'Daily Model'!$A$4:$A$555,">="&$B9,'Daily Model'!$A$4:$A$555,"<="&$C9) | K9: =SUMIFS('Daily Model'!$I$4:$I$555,'Daily Model'!$A$4:$A$555,">="&$B9,'Daily Model'!$A$4:$A$555,"<="&$C9) | L9: =SUMIFS('Daily Model'!$J$4:$J$555,'Daily Model'!$A$4:$A$555,">="&$B9,'Daily Model'!$A$4:$A$555,"<="&$C9) | M9: =SUMIFS('Daily Model'!$K$4:$K$555,'Daily Model'!$A$4:$A$555,">="&$B9,'Daily Model'!$A$4:$A$555,"<="&$C9) | N9: =SUMIFS('Daily Model'!$L$4:$L$555,'Daily Model'!$A$4:$A$555,">="&$B9,'Daily Model'!$A$4:$A$555,"<="&$C9) | O9: =SUMIFS('Daily Model'!$M$4:$M$555,'Daily Model'!$A$4:$A$555,">="&$B9,'Daily Model'!$A$4:$A$555,"<="&$C9) | P9: =SUMIFS('Daily Model'!$N$4:$N$555,'Daily Model'!$A$4:$A$555,">="&$B9,'Daily Model'!$A$4:$A$555,"<="&$C9) | Q9: =SUMIFS('Daily Model'!$O$4:$O$555,'Daily Model'!$A$4:$A$555,">="&$B9,'Daily Model'!$A$4:$A$555,"<="&$C9) | R9: =SUMIFS('Daily Model'!$P$4:$P$555,'Daily Model'!$A$4:$A$555,">="&$B9,'Daily Model'!$A$4:$A$555,"<="&$C9) | S9: =SUMIFS('Daily Model'!$Q$4:$Q$555,'Daily Model'!$A$4:$A$555,">="&$B9,'Daily Model'!$A$4:$A$555,"<="&$C9) | U9: =SUMIFS('Daily Model'!$S$4:$S$555,'Daily Model'!$A$4:$A$555,">="&$B9,'Daily Model'!$A$4:$A$555,"<="&$C9) | V9: =SUMIFS('Daily Model'!$T$4:$T$555,'Daily Model'!$A$4:$A$555,">="&$B9,'Daily Model'!$A$4:$A$555,"<="&$C9) | W9: =SUMIFS('Daily Model'!$U$4:$U$555,'Daily Model'!$A$4:$A$555,">="&$B9,'Daily Model'!$A$4:$A$555,"<="&$C9) | X9: =SUMIFS('Daily Model'!$V$4:$V$555,'Daily Model'!$A$4:$A$555,">="&$B9,'Daily Model'!$A$4:$A$555,"<="&$C9) | Y9: =SUMIFS('Daily Model'!$W$4:$W$555,'Daily Model'!$A$4:$A$555,">="&$B9,'Daily Model'!$A$4:$A$555,"<="&$C9) | Z9: =SUMIFS('Daily Model'!$X$4:$X$555,'Daily Model'!$A$4:$A$555,">="&$B9,'Daily Model'!$A$4:$A$555,"<="&$C9) | AA9: =SUMIFS('Daily Model'!$Y$4:$Y$555,'Daily Model'!$A$4:$A$555,">="&$B9,'Daily Model'!$A$4:$A$555,"<="&$C9) | AB9: =SUMIFS('Daily Model'!$Z$4:$Z$555,'Daily Model'!$A$4:$A$555,">="&$B9,'Daily Model'!$A$4:$A$555,"<="&$C9) | AC9: =SUMIFS('Daily Model'!$AA$4:$AA$555,'Daily Model'!$A$4:$A$555,">="&$B9,'Daily Model'!$A$4:$A$555,"<="&$C9) | AD9: =SUMIFS('Daily Model'!$AB$4:$AB$555,'Daily Model'!$A$4:$A$555,">="&$B9,'Daily Model'!$A$4:$A$555,"<="&$C9) | AE9: =SUMIFS('Daily Model'!$AC$4:$AC$555,'Daily Model'!$A$4:$A$555,">="&$B9,'Daily Model'!$A$4:$A$555,"<="&$C9) | AF9: =SUMIFS('Daily Model'!$AD$4:$AD$555,'Daily Model'!$A$4:$A$555,">="&$B9,'Daily Model'!$A$4:$A$555,"<="&$C9) | AG9: =SUMIFS('Daily Model'!$AE$4:$AE$555,'Daily Model'!$A$4:$A$555,">="&$B9,'Daily Model'!$A$4:$A$555,"<="&$C9) | AH9: =AF9-AG9 | AI9: =IF(D9=0,"",O9/D9*10000) | AJ9: =IF(E9=0,"",P9/E9*10000) | AK9: =IF(F9=0,"",Q9/F9*10000) | AL9: =SUMIFS('Daily Model'!$AJ$4:$AJ$555,'Daily Model'!$A$4:$A$555,">="&$B9,'Daily Model'!$A$4:$A$555,"<="&$C9) | AM9: =SUMIFS('Daily Model'!$AK$4:$AK$555,'Daily Model'!$A$4:$A$555,">="&$B9,'Daily Model'!$A$4:$A$555,"<="&$C9) | AN9: =SUMIFS('Daily Model'!$AL$4:$AL$555,'Daily Model'!$A$4:$A$555,">="&$B9,'Daily Model'!$A$4:$A$555,"<="&$C9) | AO9: =SUMIFS('Daily Model'!$AM$4:$AM$555,'Daily Model'!$A$4:$A$555,">="&$B9,'Daily Model'!$A$4:$A$555,"<="&$C9) | AP9: =SUMIFS('Daily Model'!$AN$4:$AN$555,'Daily Model'!$A$4:$A$555,">="&$B9,'Daily Model'!$A$4:$A$555,"<="&$C9) | AQ9: =IF(AP9=0,"",AO9/AP9) | AR9: 42797055 | AS9: =SUMIFS('Daily Model'!$AQ$4:$AQ$555,'Daily Model'!$A$4:$A$555,">="&$B9,'Daily Model'!$A$4:$A$555,"<="&$C9) | AT9: =SUMIFS('Daily Model'!$AR$4:$AR$555,'Daily Model'!$A$4:$A$555,">="&$B9,'Daily Model'!$A$4:$A$555,"<="&$C9) | AU9: =SUMIFS('Daily Model'!$AS$4:$AS$555,'Daily Model'!$A$4:$A$555,">="&$B9,'Daily Model'!$A$4:$A$555,"<="&$C9) | AV9: 434.6766 | AW9: 0.0214 | AX9: 4.1603739e+08 | AY9: 60100000 | AZ9: 42797055 | BA9: 3100000 | BB9: 731922.87 | BC9: 4.7723363e+08 | BD9: 241.7149 | BE9: 235.5187 | BF9: 1.7586059e+10
A10: Q2 2026 (to 06-04) | B10: 46113 | C10: 46177 | D10: =SUMIFS('Daily Model'!$B$4:$B$555,'Daily Model'!$A$4:$A$555,">="&$B10,'Daily Model'!$A$4:$A$555,"<="&$C10) | E10: =SUMIFS('Daily Model'!$C$4:$C$555,'Daily Model'!$A$4:$A$555,">="&$B10,'Daily Model'!$A$4:$A$555,"<="&$C10) | F10: =SUMIFS('Daily Model'!$D$4:$D$555,'Daily Model'!$A$4:$A$555,">="&$B10,'Daily Model'!$A$4:$A$555,"<="&$C10) | G10: =SUMIFS('Daily Model'!$E$4:$E$555,'Daily Model'!$A$4:$A$555,">="&$B10,'Daily Model'!$A$4:$A$555,"<="&$C10) | H10: =SUMIFS('Daily Model'!$F$4:$F$555,'Daily Model'!$A$4:$A$555,">="&$B10,'Daily Model'!$A$4:$A$555,"<="&$C10) | I10: =SUMIFS('Daily Model'!$G$4:$G$555,'Daily Model'!$A$4:$A$555,">="&$B10,'Daily Model'!$A$4:$A$555,"<="&$C10) | J10: =SUMIFS('Daily Model'!$H$4:$H$555,'Daily Model'!$A$4:$A$555,">="&$B10,'Daily Model'!$A$4:$A$555,"<="&$C10) | K10: =SUMIFS('Daily Model'!$I$4:$I$555,'Daily Model'!$A$4:$A$555,">="&$B10,'Daily Model'!$A$4:$A$555,"<="&$C10) | L10: =SUMIFS('Daily Model'!$J$4:$J$555,'Daily Model'!$A$4:$A$555,">="&$B10,'Daily Model'!$A$4:$A$555,"<="&$C10) | M10: =SUMIFS('Daily Model'!$K$4:$K$555,'Daily Model'!$A$4:$A$555,">="&$B10,'Daily Model'!$A$4:$A$555,"<="&$C10) | N10: =SUMIFS('Daily Model'!$L$4:$L$555,'Daily Model'!$A$4:$A$555,">="&$B10,'Daily Model'!$A$4:$A$555,"<="&$C10) | O10: =SUMIFS('Daily Model'!$M$4:$M$555,'Daily Model'!$A$4:$A$555,">="&$B10,'Daily Model'!$A$4:$A$555,"<="&$C10) | P10: =SUMIFS('Daily Model'!$N$4:$N$555,'Daily Model'!$A$4:$A$555,">="&$B10,'Daily Model'!$A$4:$A$555,"<="&$C10) | Q10: =SUMIFS('Daily Model'!$O$4:$O$555,'Daily Model'!$A$4:$A$555,">="&$B10,'Daily Model'!$A$4:$A$555,"<="&$C10) | R10: =SUMIFS('Daily Model'!$P$4:$P$555,'Daily Model'!$A$4:$A$555,">="&$B10,'Daily Model'!$A$4:$A$555,"<="&$C10) | S10: =SUMIFS('Daily Model'!$Q$4:$Q$555,'Daily Model'!$A$4:$A$555,">="&$B10,'Daily Model'!$A$4:$A$555,"<="&$C10) | U10: =SUMIFS('Daily Model'!$S$4:$S$555,'Daily Model'!$A$4:$A$555,">="&$B10,'Daily Model'!$A$4:$A$555,"<="&$C10) | V10: =SUMIFS('Daily Model'!$T$4:$T$555,'Daily Model'!$A$4:$A$555,">="&$B10,'Daily Model'!$A$4:$A$555,"<="&$C10) | W10: =SUMIFS('Daily Model'!$U$4:$U$555,'Daily Model'!$A$4:$A$555,">="&$B10,'Daily Model'!$A$4:$A$555,"<="&$C10) | X10: =SUMIFS('Daily Model'!$V$4:$V$555,'Daily Model'!$A$4:$A$555,">="&$B10,'Daily Model'!$A$4:$A$555,"<="&$C10) | Y10: =SUMIFS('Daily Model'!$W$4:$W$555,'Daily Model'!$A$4:$A$555,">="&$B10,'Daily Model'!$A$4:$A$555,"<="&$C10) | Z10: =SUMIFS('Daily Model'!$X$4:$X$555,'Daily Model'!$A$4:$A$555,">="&$B10,'Daily Model'!$A$4:$A$555,"<="&$C10) | AA10: =SUMIFS('Daily Model'!$Y$4:$Y$555,'Daily Model'!$A$4:$A$555,">="&$B10,'Daily Model'!$A$4:$A$555,"<="&$C10) | AB10: =SUMIFS('Daily Model'!$Z$4:$Z$555,'Daily Model'!$A$4:$A$555,">="&$B10,'Daily Model'!$A$4:$A$555,"<="&$C10) | AC10: =SUMIFS('Daily Model'!$AA$4:$AA$555,'Daily Model'!$A$4:$A$555,">="&$B10,'Daily Model'!$A$4:$A$555,"<="&$C10) | AD10: =SUMIFS('Daily Model'!$AB$4:$AB$555,'Daily Model'!$A$4:$A$555,">="&$B10,'Daily Model'!$A$4:$A$555,"<="&$C10) | AE10: =SUMIFS('Daily Model'!$AC$4:$AC$555,'Daily Model'!$A$4:$A$555,">="&$B10,'Daily Model'!$A$4:$A$555,"<="&$C10) | AF10: =SUMIFS('Daily Model'!$AD$4:$AD$555,'Daily Model'!$A$4:$A$555,">="&$B10,'Daily Model'!$A$4:$A$555,"<="&$C10) | AG10: =SUMIFS('Daily Model'!$AE$4:$AE$555,'Daily Model'!$A$4:$A$555,">="&$B10,'Daily Model'!$A$4:$A$555,"<="&$C10) | AH10: =AF10-AG10 | AI10: =IF(D10=0,"",O10/D10*10000) | AJ10: =IF(E10=0,"",P10/E10*10000) | AK10: =IF(F10=0,"",Q10/F10*10000) | AL10: =SUMIFS('Daily Model'!$AJ$4:$AJ$555,'Daily Model'!$A$4:$A$555,">="&$B10,'Daily Model'!$A$4:$A$555,"<="&$C10) | AM10: =SUMIFS('Daily Model'!$AK$4:$AK$555,'Daily Model'!$A$4:$A$555,">="&$B10,'Daily Model'!$A$4:$A$555,"<="&$C10) | AN10: =SUMIFS('Daily Model'!$AL$4:$AL$555,'Daily Model'!$A$4:$A$555,">="&$B10,'Daily Model'!$A$4:$A$555,"<="&$C10) | AO10: =SUMIFS('Daily Model'!$AM$4:$AM$555,'Daily Model'!$A$4:$A$555,">="&$B10,'Daily Model'!$A$4:$A$555,"<="&$C10) | AP10: =SUMIFS('Daily Model'!$AN$4:$AN$555,'Daily Model'!$A$4:$A$555,">="&$B10,'Daily Model'!$A$4:$A$555,"<="&$C10) | AQ10: =IF(AP10=0,"",AO10/AP10) | AR10: 44818417 | AS10: =SUMIFS('Daily Model'!$AQ$4:$AQ$555,'Daily Model'!$A$4:$A$555,">="&$B10,'Daily Model'!$A$4:$A$555,"<="&$C10) | AT10: =SUMIFS('Daily Model'!$AR$4:$AR$555,'Daily Model'!$A$4:$A$555,">="&$B10,'Daily Model'!$A$4:$A$555,"<="&$C10) | AU10: =SUMIFS('Daily Model'!$AS$4:$AS$555,'Daily Model'!$A$4:$A$555,">="&$B10,'Daily Model'!$A$4:$A$555,"<="&$C10) | AV10: 430.5641 | AW10: 0.0215 | AX10: 4.1434815e+08 | AY10: 60100000 | AZ10: 44818417 | BA10: 3100000 | BB10: 803572.8 | BC10: 4.7682986e+08 | BD10: 241.3849 | BE10: 235.4449 | BF10: 3.3559286e+10

Sheet Sources
A1: SOURCES & METHODOLOGY
A2: • BRIDGE (per segment): Gross Fees − HLP − (Unit on spot) − (deployer on HIP-3) = Revenue to HyperCore. Builder code fees are ON-TOP (paid by users to front-ends) and are NOT deducted. Sum of segment revenues = HyperCore Revenue = hyperscreener "HyperCore Buybacks" (north star). + HyperEVM + Auction burn = Total Revenue.
A3: • Core crypto perp is the residual segment: Core Revenue = HyperCore − Spot − HIP-3 − HIP-4; Core Fees = Core Revenue / (1 − HLP). This makes the bridge tie exactly to the north star (Check column ≈ 0).
A4: • HLP share: 1% of perp+spot fees from 2025-08-30 (3% before); on spot it applies to (fees − Unit). HIP-3 & Spot revenue use clean computed HLP; any accrual-vs-buyback timing difference is absorbed by the core-perp residual.
A5: • HIP-3 volume AND fees are both from Loris (single source) so the take-rate is internally consistent. The asset-category split (commodities/crypto/fx/indices/pre-IPO/stocks) is the hyperscreener category mix allocated to the Loris HIP-3 total, so the categories sum exactly to HIP-3 volume.
A6: • HIP-4 (outcome / prediction markets) launched 2026-05-02, zero-fee. Hyperscreener only publishes the current day for HIP-4 (no daily history endpoint), so the column is sparse; immaterial to revenue.
A7: • OTS (Hyperliquid Strategies basis) = 1,000M − Future Emissions&CR − Hyper Foundation − Assistance Fund − Community Grants − HyperCore&HyperEVM fee burns. Validated to HL Strategies 29-Apr-2026 (477.0M vs 476.7M). Split into Core Contributors (locked) + Circulating; team vesting moves tokens Core→Circulating, OTS unchanged.
A9: Data | B9: Source | C9: Endpoint / URL | D9: Notes
A10: Core / total perp volume | B10: hyperscreener (ASXN) | C10: https://api-hyperliquid.asxn.xyz/api/cloudfront/total_volume | D10: Daily $ by coin, summed. Core = total − HIP-3.
A11: HIP-3 volume, gross fees, deployer fees | B11: Loris | C11: https://loris.tools/hip3 (api.loris.tools; HL perpDexs-derived) | D11: timeseries: volume, total_fees, total_deployer_fees. Single source for HIP-3 vol & fees.
A12: HIP-3 category mix | B12: hyperscreener (ASXN) | C12: https://api-hyperliquid.asxn.xyz/api/categories/hip3-categories/historical | D12: Asset-category proportions; allocated to the Loris HIP-3 total.
A13: Spot volume / fees / revenue | B13: DefiLlama | C13: https://api.llama.fi/summary/fees/hyperliquid-spot-orderbook · /dexs/hyperliquid-spot-orderbook | D13: dailyVolume, dailyFees (incl Unit).
A14: Unit protocol fees | B14: DefiLlama | C14: https://api.llama.fi/summary/fees/unit | D14: Hyperunit deployer cut on spot tokens it deploys.
A15: HIP-4 (outcome) volume/fees | B15: hyperscreener (ASXN) | C15: https://api-hyperliquid.asxn.xyz/api/outcome-coins/analytics/daily | D15: Current day only; live 2026-05-02, zero-fee.
A16: HyperCore revenue / buyback / AF | B16: hyperscreener (ASXN) | C16: https://api-hyperliquid.asxn.xyz/api/buyback/revenues · /hl-buybacks · /assistance-fund-holdings | D16: HyperCore Buybacks (north star), HyperEVM & auction burn, buyback HYPE/price, AF balance.
A17: Emissions / supply / fee burns | B17: hyperscreener (ASXN) | C17: https://api-hyperliquid.asxn.xyz/api/validators/daily-emissions · buyback/daily-burn | D17: dailyEmission, future-emission, total supply, dailyBurn.
A18: HYPE staked + implied yield | B18: hyperscreener (ASXN) | C18: https://api-hyperliquid.asxn.xyz/api/validators/hype-staking/metrics | D18: Daily totalStake + ASXN-computed yield.
A19: Builder code fees (on-top) | B19: hyperscreener (ASXN) | C19: https://api-hyperliquid.asxn.xyz/api/node/builders/stacked-fees-chart | D19: Pass-through to front-ends; not in the bridge.
A20: HLP share (1%/3%) | B20: DefiLlama methodology | C20: hyperliquid-perps & -spot-orderbook methodology | D20: 1% from 2025-08-30, 3% before.
... A23: Perp revenue (cross-check only) | B23: DefiLlama | C23: https://api.llama.fi/summary/fees/hyperliquid-perps | D23: Accrual basis; ~7.5% above hyperscreener buyback cumulatively (timing).
