Workbook
Name HLP_Current: Assumptions!$C$4
Name HLP_Legacy: Assumptions!$C$5
Name HLP_ChangeDate: Assumptions!$C$6
Name Rate_Builder: Assumptions!$C$7

Sheet Read Me
B1: Hyperliquid — Fee → Revenue DAILY Decomposition
B2: Splits the actual HyperCore revenue into core-perp / HIP-3 / spot, every day, by top-down subtraction.
B3: Generated 2026-05-21. Daily, 2025-01-01 → 2026-05-20.
B5: THE METHOD (everything daily — no monthly aggregation)
B6: • NORTH STAR: the actual HyperCore revenue reported by hyperscreener.asxn.xyz (the $ that funds HYPE buybacks). The model never overrides it — it decomposes it.
B7: • STEP 1 — HIP-3: HIP-3 gross fees and deployer fees come from Loris (loris.tools), daily. HIP-3 protocol revenue = gross fees − deployer fees.
B8: • STEP 2 — Spot: spot revenue comes from DefiLlama (hyperliquid-spot-orderbook), daily.
B9: • STEP 3 — Core perp (the plug): Core perp revenue = HyperCore revenue − HIP-3 protocol revenue − spot revenue. Because it is a residual, the three pieces ALWAYS sum back to the north star exactly.
B10: • STEP 4 — Fees & HLP: revenue is grossed up to protocol fees by adding back the HLP provider share — 1% of perp+spot fees, and 3% before 2025-08-30 (DefiLlama methodology). Protocol fee = revenue ÷ (1 − HLP%).
B11: • CROSS-CHECKS: each segment's implied take-rate (fees ÷ volume, in bps) is shown so you can sanity-check it against the Hyperliquid fee schedule.
B13: WHAT THE NUMBERS SAY (read these before using the model)
B14: • HIP-3 is in GROWTH MODE: gross fees are ~0.7 bps of HIP-3 volume — roughly 4x lower than core perp. HIP-3 deployer fees are zero until 2026-03-21 (deployers took 0% in growth mode), so before that the protocol kept 100% of the (small) HIP-3 fees. HIP-3 is huge in volume but tiny in revenue today.
... B21: TABS
B22: Assumptions | D22: HLP share (1% / 3% pre-2025-08-30) and the builder-code fee rate. Yellow = editable.
B23: Daily Model | D23: The daily decomposition — one row per day. Volumes → revenue split → implied fees → take-rates.
B24: Daily Data | D24: Raw daily inputs from every source, plus the supply reconciliation.
B25: Sources | D25: Each column → its exact source.
B27: Colour legend: | C27: yellow = input | E27: blue = source value | G27: black = formula | I27: green = cross-tab link

Sheet Assumptions
A1: ASSUMPTIONS — yellow cells are inputs you control
B3: Parameter | C3: Value | D3: bps | E3: Basis / notes
B4: HLP provider share — current | C4: 0.01 | D4: =C4 | E4: Share of perp+spot protocol fees paid to HLP liquidity providers, from 2025-08-30. Source: DefiLlama methodology.
B5: HLP provider share — legacy (pre-changeover) | C5: 0.03 | D5: =C5 | E5: HLP share before 2025-08-30 (it was 3%, cut to 1%). Source: DefiLlama methodology.
B6: HLP rate changeover date | C6: 45899 | E6: Date the HLP share dropped from legacy to current.
B7: Builder code fee rate | C7: 1.63104e-05 | D7: =C7*10000 | E7: Builder code fees as a rate on HyperCore volume. Calibrated from hyperscreener actual builder fees ($2.10M in May-2026; $75.3M all-time, 386 builders). Builder fees are paid on top, 100% to builders.
B9: • Decomposition identity: HyperCore revenue = core perp revenue + HIP-3 protocol revenue + spot revenue (exact, every day).
B10: • HIP-3 (Hyperliquid docs + Loris): users pay ~2x a normal perp fee, but HIP-3 markets run in growth mode — realised HIP-3 fees are very low and the deployer share was 0% until 2026-03-21.
B11: • Hyperliquid fee schedule (reference): perps 0.045%/0.015% taker/maker; spot 0.07%/0.04%; realised rates are far lower due to volume tiers and discounts.

Sheet Daily Model
A1: HYPERLIQUID — DAILY FEE → REVENUE DECOMPOSITION (HyperCore revenue split into core perp / HIP-3 / spot)
B2: VOLUME | E2: REVENUE DECOMPOSITION | K2: IMPLIED FEES | P2: TAKE-RATE CROSS-CHECK
A3: Date | B3: Core Perp Volume ($) | C3: HIP-3 Volume ($) | D3: Spot Volume ($) | E3: HyperCore Revenue — north star ($) | F3: HIP-3 Gross Fees ($) | G3: HIP-3 Deployer Fees ($) | H3: HIP-3 Protocol Revenue ($) | I3: Spot Revenue ($) | J3: Core Perp Revenue — plug ($) | K3: HLP Rate Applied | L3: Core Perp Protocol Fees ($) | M3: Spot Protocol Fees ($) | N3: Builder Code Fees ($) | O3: HLP Provider Cut ($) | P3: Core Perp Take Rate (bps) | Q3: HIP-3 Take Rate (bps) | R3: Spot Take Rate (bps)
A4: 45658 | B4: ='Daily Data'!B4-'Daily Data'!D4 | C4: ='Daily Data'!D4 | D4: ='Daily Data'!C4 | E4: =IF('Daily Data'!E4="","",'Daily Data'!E4) | F4: =IF($E4="","",'Daily Data'!F4) | G4: =IF($E4="","",'Daily Data'!G4) | H4: =IF($E4="","",F4-G4) | I4: =IF($E4="","",'Daily Data'!H4) | J4: =IF($E4="","",E4-H4-I4) | K4: =IF($E4="","",IF(A4<HLP_ChangeDate,HLP_Legacy,HLP_Current)) | L4: =IF($E4="","",J4/(1-K4)) | M4: =IF($E4="","",I4/(1-K4)) | N4: =IF($E4="","",(B4+C4+D4)*Rate_Builder) | O4: =IF($E4="","",E4*K4/(1-K4)) | P4: =IF(OR($E4="",B4=0),"",L4/B4*10000) | Q4: =IF(OR($E4="",C4=0),"",F4/C4*10000) | R4: =IF(OR($E4="",D4=0),"",'Daily Data'!I4/D4*10000)
A5: 45659 | B5: ='Daily Data'!B5-'Daily Data'!D5 | C5: ='Daily Data'!D5 | D5: ='Daily Data'!C5 | E5: =IF('Daily Data'!E5="","",'Daily Data'!E5) | F5: =IF($E5="","",'Daily Data'!F5) | G5: =IF($E5="","",'Daily Data'!G5) | H5: =IF($E5="","",F5-G5) | I5: =IF($E5="","",'Daily Data'!H5) | J5: =IF($E5="","",E5-H5-I5) | K5: =IF($E5="","",IF(A5<HLP_ChangeDate,HLP_Legacy,HLP_Current)) | L5: =IF($E5="","",J5/(1-K5)) | M5: =IF($E5="","",I5/(1-K5)) | N5: =IF($E5="","",(B5+C5+D5)*Rate_Builder) | O5: =IF($E5="","",E5*K5/(1-K5)) | P5: =IF(OR($E5="",B5=0),"",L5/B5*10000) | Q5: =IF(OR($E5="",C5=0),"",F5/C5*10000) | R5: =IF(OR($E5="",D5=0),"",'Daily Data'!I5/D5*10000)
A6: 45660 | B6: ='Daily Data'!B6-'Daily Data'!D6 | C6: ='Daily Data'!D6 | D6: ='Daily Data'!C6 | E6: =IF('Daily Data'!E6="","",'Daily Data'!E6) | F6: =IF($E6="","",'Daily Data'!F6) | G6: =IF($E6="","",'Daily Data'!G6) | H6: =IF($E6="","",F6-G6) | I6: =IF($E6="","",'Daily Data'!H6) | J6: =IF($E6="","",E6-H6-I6) | K6: =IF($E6="","",IF(A6<HLP_ChangeDate,HLP_Legacy,HLP_Current)) | L6: =IF($E6="","",J6/(1-K6)) | M6: =IF($E6="","",I6/(1-K6)) | N6: =IF($E6="","",(B6+C6+D6)*Rate_Builder) | O6: =IF($E6="","",E6*K6/(1-K6)) | P6: =IF(OR($E6="",B6=0),"",L6/B6*10000) | Q6: =IF(OR($E6="",C6=0),"",F6/C6*10000) | R6: =IF(OR($E6="",D6=0),"",'Daily Data'!I6/D6*10000)
A7: 45661 | B7: ='Daily Data'!B7-'Daily Data'!D7 | C7: ='Daily Data'!D7 | D7: ='Daily Data'!C7 | E7: =IF('Daily Data'!E7="","",'Daily Data'!E7) | F7: =IF($E7="","",'Daily Data'!F7) | G7: =IF($E7="","",'Daily Data'!G7) | H7: =IF($E7="","",F7-G7) | I7: =IF($E7="","",'Daily Data'!H7) | J7: =IF($E7="","",E7-H7-I7) | K7: =IF($E7="","",IF(A7<HLP_ChangeDate,HLP_Legacy,HLP_Current)) | L7: =IF($E7="","",J7/(1-K7)) | M7: =IF($E7="","",I7/(1-K7)) | N7: =IF($E7="","",(B7+C7+D7)*Rate_Builder) | O7: =IF($E7="","",E7*K7/(1-K7)) | P7: =IF(OR($E7="",B7=0),"",L7/B7*10000) | Q7: =IF(OR($E7="",C7=0),"",F7/C7*10000) | R7: =IF(OR($E7="",D7=0),"",'Daily Data'!I7/D7*10000)
A8: 45662 | B8: ='Daily Data'!B8-'Daily Data'!D8 | C8: ='Daily Data'!D8 | D8: ='Daily Data'!C8 | E8: =IF('Daily Data'!E8="","",'Daily Data'!E8) | F8: =IF($E8="","",'Daily Data'!F8) | G8: =IF($E8="","",'Daily Data'!G8) | H8: =IF($E8="","",F8-G8) | I8: =IF($E8="","",'Daily Data'!H8) | J8: =IF($E8="","",E8-H8-I8) | K8: =IF($E8="","",IF(A8<HLP_ChangeDate,HLP_Legacy,HLP_Current)) | L8: =IF($E8="","",J8/(1-K8)) | M8: =IF($E8="","",I8/(1-K8)) | N8: =IF($E8="","",(B8+C8+D8)*Rate_Builder) | O8: =IF($E8="","",E8*K8/(1-K8)) | P8: =IF(OR($E8="",B8=0),"",L8/B8*10000) | Q8: =IF(OR($E8="",C8=0),"",F8/C8*10000) | R8: =IF(OR($E8="",D8=0),"",'Daily Data'!I8/D8*10000)
A9: 45663 | B9: ='Daily Data'!B9-'Daily Data'!D9 | C9: ='Daily Data'!D9 | D9: ='Daily Data'!C9 | E9: =IF('Daily Data'!E9="","",'Daily Data'!E9) | F9: =IF($E9="","",'Daily Data'!F9) | G9: =IF($E9="","",'Daily Data'!G9) | H9: =IF($E9="","",F9-G9) | I9: =IF($E9="","",'Daily Data'!H9) | J9: =IF($E9="","",E9-H9-I9) | K9: =IF($E9="","",IF(A9<HLP_ChangeDate,HLP_Legacy,HLP_Current)) | L9: =IF($E9="","",J9/(1-K9)) | M9: =IF($E9="","",I9/(1-K9)) | N9: =IF($E9="","",(B9+C9+D9)*Rate_Builder) | O9: =IF($E9="","",E9*K9/(1-K9)) | P9: =IF(OR($E9="",B9=0),"",L9/B9*10000) | Q9: =IF(OR($E9="",C9=0),"",F9/C9*10000) | R9: =IF(OR($E9="",D9=0),"",'Daily Data'!I9/D9*10000)
A10: 45664 | B10: ='Daily Data'!B10-'Daily Data'!D10 | C10: ='Daily Data'!D10 | D10: ='Daily Data'!C10 | E10: =IF('Daily Data'!E10="","",'Daily Data'!E10) | F10: =IF($E10="","",'Daily Data'!F10) | G10: =IF($E10="","",'Daily Data'!G10) | H10: =IF($E10="","",F10-G10) | I10: =IF($E10="","",'Daily Data'!H10) | J10: =IF($E10="","",E10-H10-I10) | K10: =IF($E10="","",IF(A10<HLP_ChangeDate,HLP_Legacy,HLP_Current)) | L10: =IF($E10="","",J10/(1-K10)) | M10: =IF($E10="","",I10/(1-K10)) | N10: =IF($E10="","",(B10+C10+D10)*Rate_Builder) | O10: =IF($E10="","",E10*K10/(1-K10)) | P10: =IF(OR($E10="",B10=0),"",L10/B10*10000) | Q10: =IF(OR($E10="",C10=0),"",F10/C10*10000) | R10: =IF(OR($E10="",D10=0),"",'Daily Data'!I10/D10*10000)
A11: 45665 | B11: ='Daily Data'!B11-'Daily Data'!D11 | C11: ='Daily Data'!D11 | D11: ='Daily Data'!C11 | E11: =IF('Daily Data'!E11="","",'Daily Data'!E11) | F11: =IF($E11="","",'Daily Data'!F11) | G11: =IF($E11="","",'Daily Data'!G11) | H11: =IF($E11="","",F11-G11) | I11: =IF($E11="","",'Daily Data'!H11) | J11: =IF($E11="","",E11-H11-I11) | K11: =IF($E11="","",IF(A11<HLP_ChangeDate,HLP_Legacy,HLP_Current)) | L11: =IF($E11="","",J11/(1-K11)) | M11: =IF($E11="","",I11/(1-K11)) | N11: =IF($E11="","",(B11+C11+D11)*Rate_Builder) | O11: =IF($E11="","",E11*K11/(1-K11)) | P11: =IF(OR($E11="",B11=0),"",L11/B11*10000) | Q11: =IF(OR($E11="",C11=0),"",F11/C11*10000) | R11: =IF(OR($E11="",D11=0),"",'Daily Data'!I11/D11*10000)
A12: 45666 | B12: ='Daily Data'!B12-'Daily Data'!D12 | C12: ='Daily Data'!D12 | D12: ='Daily Data'!C12 | E12: =IF('Daily Data'!E12="","",'Daily Data'!E12) | F12: =IF($E12="","",'Daily Data'!F12) | G12: =IF($E12="","",'Daily Data'!G12) | H12: =IF($E12="","",F12-G12) | I12: =IF($E12="","",'Daily Data'!H12) | J12: =IF($E12="","",E12-H12-I12) | K12: =IF($E12="","",IF(A12<HLP_ChangeDate,HLP_Legacy,HLP_Current)) | L12: =IF($E12="","",J12/(1-K12)) | M12: =IF($E12="","",I12/(1-K12)) | N12: =IF($E12="","",(B12+C12+D12)*Rate_Builder) | O12: =IF($E12="","",E12*K12/(1-K12)) | P12: =IF(OR($E12="",B12=0),"",L12/B12*10000) | Q12: =IF(OR($E12="",C12=0),"",F12/C12*10000) | R12: =IF(OR($E12="",D12=0),"",'Daily Data'!I12/D12*10000)
A13: 45667 | B13: ='Daily Data'!B13-'Daily Data'!D13 | C13: ='Daily Data'!D13 | D13: ='Daily Data'!C13 | E13: =IF('Daily Data'!E13="","",'Daily Data'!E13) | F13: =IF($E13="","",'Daily Data'!F13) | G13: =IF($E13="","",'Daily Data'!G13) | H13: =IF($E13="","",F13-G13) | I13: =IF($E13="","",'Daily Data'!H13) | J13: =IF($E13="","",E13-H13-I13) | K13: =IF($E13="","",IF(A13<HLP_ChangeDate,HLP_Legacy,HLP_Current)) | L13: =IF($E13="","",J13/(1-K13)) | M13: =IF($E13="","",I13/(1-K13)) | N13: =IF($E13="","",(B13+C13+D13)*Rate_Builder) | O13: =IF($E13="","",E13*K13/(1-K13)) | P13: =IF(OR($E13="",B13=0),"",L13/B13*10000) | Q13: =IF(OR($E13="",C13=0),"",F13/C13*10000) | R13: =IF(OR($E13="",D13=0),"",'Daily Data'!I13/D13*10000)
A14: 45668 | B14: ='Daily Data'!B14-'Daily Data'!D14 | C14: ='Daily Data'!D14 | D14: ='Daily Data'!C14 | E14: =IF('Daily Data'!E14="","",'Daily Data'!E14) | F14: =IF($E14="","",'Daily Data'!F14) | G14: =IF($E14="","",'Daily Data'!G14) | H14: =IF($E14="","",F14-G14) | I14: =IF($E14="","",'Daily Data'!H14) | J14: =IF($E14="","",E14-H14-I14) | K14: =IF($E14="","",IF(A14<HLP_ChangeDate,HLP_Legacy,HLP_Current)) | L14: =IF($E14="","",J14/(1-K14)) | M14: =IF($E14="","",I14/(1-K14)) | N14: =IF($E14="","",(B14+C14+D14)*Rate_Builder) | O14: =IF($E14="","",E14*K14/(1-K14)) | P14: =IF(OR($E14="",B14=0),"",L14/B14*10000) | Q14: =IF(OR($E14="",C14=0),"",F14/C14*10000) | R14: =IF(OR($E14="",D14=0),"",'Daily Data'!I14/D14*10000)
A15: 45669 | B15: ='Daily Data'!B15-'Daily Data'!D15 | C15: ='Daily Data'!D15 | D15: ='Daily Data'!C15 | E15: =IF('Daily Data'!E15="","",'Daily Data'!E15) | F15: =IF($E15="","",'Daily Data'!F15) | G15: =IF($E15="","",'Daily Data'!G15) | H15: =IF($E15="","",F15-G15) | I15: =IF($E15="","",'Daily Data'!H15) | J15: =IF($E15="","",E15-H15-I15) | K15: =IF($E15="","",IF(A15<HLP_ChangeDate,HLP_Legacy,HLP_Current)) | L15: =IF($E15="","",J15/(1-K15)) | M15: =IF($E15="","",I15/(1-K15)) | N15: =IF($E15="","",(B15+C15+D15)*Rate_Builder) | O15: =IF($E15="","",E15*K15/(1-K15)) | P15: =IF(OR($E15="",B15=0),"",L15/B15*10000) | Q15: =IF(OR($E15="",C15=0),"",F15/C15*10000) | R15: =IF(OR($E15="",D15=0),"",'Daily Data'!I15/D15*10000)
... A508: 46162 | B508: ='Daily Data'!B508-'Daily Data'!D508 | C508: ='Daily Data'!D508 | D508: ='Daily Data'!C508 | E508: =IF('Daily Data'!E508="","",'Daily Data'!E508) | F508: =IF($E508="","",'Daily Data'!F508) | G508: =IF($E508="","",'Daily Data'!G508) | H508: =IF($E508="","",F508-G508) | I508: =IF($E508="","",'Daily Data'!H508) | J508: =IF($E508="","",E508-H508-I508) | K508: =IF($E508="","",IF(A508<HLP_ChangeDate,HLP_Legacy,HLP_Current)) | L508: =IF($E508="","",J508/(1-K508)) | M508: =IF($E508="","",I508/(1-K508)) | N508: =IF($E508="","",(B508+C508+D508)*Rate_Builder) | O508: =IF($E508="","",E508*K508/(1-K508)) | P508: =IF(OR($E508="",B508=0),"",L508/B508*10000) | Q508: =IF(OR($E508="",C508=0),"",F508/C508*10000) | R508: =IF(OR($E508="",D508=0),"",'Daily Data'!I508/D508*10000)

Sheet Daily Data
A1: DAILY DATA — raw inputs by source. hyperscreener.asxn.xyz · Loris (loris.tools) · DefiLlama
B2: hyperscreener | C2: hyperscreener | D2: Loris | E2: hyperscreener | F2: Loris | G2: Loris | H2: DefiLlama | I2: DefiLlama | J2: hyperscreener | K2: hyperscreener | L2: hyperscreener | M2: hyperscreener | N2: hyperscreener | O2: hyperscreener | P2: hyperscreener | Q2: hyperscreener | R2: hyperscreener | S2: hyperscreener | T2: Calc | U2: Calc | V2: Calc | W2: Calc
A3: Date | B3: Total Perp Volume ($) | C3: Spot Volume ($) | D3: HIP-3 Volume ($) | E3: HyperCore Revenue ($) | F3: HIP-3 Gross Fees ($) | G3: HIP-3 Deployer Fees ($) | H3: Spot Revenue ($) | I3: Spot Fees ($) | J3: HyperEVM Burn ($) | K3: Auction Burn ($) | L3: Buyback HYPE | M3: Buyback USD ($) | N3: AF Holdings (HYPE) | O3: Daily Emission (HYPE) | P3: Daily Burn (HYPE) | Q3: Daily Burn ($) | R3: Circulating Supply (HYPE) | S3: Total Supply (HYPE) | T3: Δ Circ Supply (HYPE) | U3: Δ Total Supply (HYPE) | V3: Total Supply Check ≈0 | W3: Circ Residual / Other (HYPE)
A4: 45658 | B4: 2.1572568e+09 | D4: 0 | F4: 0 | G4: 0 | H4: 29237 | I4: 30141 | N4: 11719551 | O4: 24499.354 | P4: 941.1022 | Q4: 22586.45 | R4: 3.3384913e+08 | S4: 9.9988896e+08
A5: 45659 | B5: 3.6458162e+09 | D5: 0 | F5: 0 | G5: 0 | H5: 40416 | I5: 41666 | N5: 11756781 | O5: 24851.902 | P5: 920.9016 | Q5: 24230.76 | R5: 3.3385788e+08 | S5: 9.9988804e+08 | T5: =IF(OR(R5="",R4=""),"",R5-R4) | U5: =IF(OR(S5="",S4=""),"",S5-S4) | V5: =IF(OR(U5="",P5=""),"",U5+P5) | W5: =IF(OR(T5="",O5="",P5=""),"",T5-O5+P5)
A6: 45660 | B6: 3.5731603e+09 | D6: 0 | F6: 0 | G6: 0 | H6: 35895 | I6: 37005 | N6: 11812513 | O6: 25219.868 | P6: 905.5316 | Q6: 20963.06 | R6: 3.3386719e+08 | S6: 9.9988714e+08 | T6: =IF(OR(R6="",R5=""),"",R6-R5) | U6: =IF(OR(S6="",S5=""),"",S6-S5) | V6: =IF(OR(U6="",P6=""),"",U6+P6) | W6: =IF(OR(T6="",O6="",P6=""),"",T6-O6+P6)
A7: 45661 | B7: 2.5062676e+09 | D7: 0 | F7: 0 | G7: 0 | H7: 24616 | I7: 25377 | N7: 11846794 | O7: 25452.778 | P7: 1232.8801 | Q7: 30121.73 | R7: 3.3387648e+08 | S7: 9.998859e+08 | T7: =IF(OR(R7="",R6=""),"",R7-R6) | U7: =IF(OR(S7="",S6=""),"",S7-S6) | V7: =IF(OR(U7="",P7=""),"",U7+P7) | W7: =IF(OR(T7="",O7="",P7=""),"",T7-O7+P7)
A8: 45662 | B8: 2.149149e+09 | D8: 0 | F8: 0 | G8: 0 | H8: 18684 | I8: 19262 | N8: 11889348 | O8: 25665.111 | P8: 617.3145 | Q8: 15443.36 | R8: 3.3388674e+08 | S8: 9.9988529e+08 | T8: =IF(OR(R8="",R7=""),"",R8-R7) | U8: =IF(OR(S8="",S7=""),"",S8-S7) | V8: =IF(OR(U8="",P8=""),"",U8+P8) | W8: =IF(OR(T8="",O8="",P8=""),"",T8-O8+P8)
A9: 45663 | B9: 4.4049187e+09 | D9: 0 | F9: 0 | G9: 0 | H9: 22750 | I9: 23453 | N9: 11933135 | O9: 25789.885 | P9: 447.5855 | Q9: 10920.86 | R9: 3.3389734e+08 | S9: 9.9988484e+08 | T9: =IF(OR(R9="",R8=""),"",R9-R8) | U9: =IF(OR(S9="",S8=""),"",S9-S8) | V9: =IF(OR(U9="",P9=""),"",U9+P9) | W9: =IF(OR(T9="",O9="",P9=""),"",T9-O9+P9)
A10: 45664 | B10: 7.0045455e+09 | D10: 0 | F10: 0 | G10: 0 | H10: 29308 | I10: 30214 | N10: 11991787 | O10: 25854.611 | P10: 718.7295 | Q10: 18132.11 | R10: 3.3390778e+08 | S10: 9.9988412e+08 | T10: =IF(OR(R10="",R9=""),"",R10-R9) | U10: =IF(OR(S10="",S9=""),"",S10-S9) | V10: =IF(OR(U10="",P10=""),"",U10+P10) | W10: =IF(OR(T10="",O10="",P10=""),"",T10-O10+P10)
A11: 45665 | B11: 6.0197847e+09 | D11: 0 | F11: 0 | G11: 0 | H11: 43915 | I11: 45273 | N11: 12076330 | O11: 25924.42 | P11: 744.9065 | Q11: 17501.58 | R11: 3.3391828e+08 | S11: 9.9988338e+08 | T11: =IF(OR(R11="",R10=""),"",R11-R10) | U11: =IF(OR(S11="",S10=""),"",S11-S10) | V11: =IF(OR(U11="",P11=""),"",U11+P11) | W11: =IF(OR(T11="",O11="",P11=""),"",T11-O11+P11)
A12: 45666 | B12: 7.1233273e+09 | D12: 0 | F12: 0 | G12: 0 | H12: 45969 | I12: 47391 | N12: 12156975 | O12: 25984.345 | P12: 1579.5356 | Q12: 35552.19 | R12: 3.3392805e+08 | S12: 9.998818e+08 | T12: =IF(OR(R12="",R11=""),"",R12-R11) | U12: =IF(OR(S12="",S11=""),"",S12-S11) | V12: =IF(OR(U12="",P12=""),"",U12+P12) | W12: =IF(OR(T12="",O12="",P12=""),"",T12-O12+P12)
A13: 45667 | B13: 5.1100061e+09 | D13: 0 | F13: 0 | G13: 0 | H13: 26938 | I13: 27771 | N13: 12241033 | O13: 26008.903 | P13: 1664.9046 | Q13: 33764.27 | R13: 3.3393775e+08 | S13: 9.9988013e+08 | T13: =IF(OR(R13="",R12=""),"",R13-R12) | U13: =IF(OR(S13="",S12=""),"",S13-S12) | V13: =IF(OR(U13="",P13=""),"",U13+P13) | W13: =IF(OR(T13="",O13="",P13=""),"",T13-O13+P13)
A14: 45668 | B14: 1.9752201e+09 | D14: 0 | F14: 0 | G14: 0 | H14: 14512 | I14: 14961 | N14: 12305409 | O14: 26032.719 | P14: 984.8383 | Q14: 20333.96 | R14: 3.3394818e+08 | S14: 9.9987915e+08 | T14: =IF(OR(R14="",R13=""),"",R14-R13) | U14: =IF(OR(S14="",S13=""),"",S14-S13) | V14: =IF(OR(U14="",P14=""),"",U14+P14) | W14: =IF(OR(T14="",O14="",P14=""),"",T14-O14+P14)
A15: 45669 | B15: 1.8688233e+09 | D15: 0 | F15: 0 | G15: 0 | N15: 12323093 | O15: 26062.989 | P15: 555.3528 | Q15: 11594.93 | R15: 3.3395908e+08 | S15: 9.9987859e+08 | T15: =IF(OR(R15="",R14=""),"",R15-R14) | U15: =IF(OR(S15="",S14=""),"",S15-S14) | V15: =IF(OR(U15="",P15=""),"",U15+P15) | W15: =IF(OR(T15="",O15="",P15=""),"",T15-O15+P15)
A16: 45670 | B16: 7.6148894e+09 | D16: 0 | F16: 0 | G16: 0 | N16: 12366458 | O16: 26085.585 | P16: 490.8274 | Q16: 10364.31 | R16: 3.339701e+08 | S16: 9.998781e+08 | T16: =IF(OR(R16="",R15=""),"",R16-R15) | U16: =IF(OR(S16="",S15=""),"",S16-S15) | V16: =IF(OR(U16="",P16=""),"",U16+P16) | W16: =IF(OR(T16="",O16="",P16=""),"",T16-O16+P16)
A17: 45671 | B17: 4.1645346e+09 | D17: 0 | F17: 0 | G17: 0 | H17: 23594 | I17: 24324 | N17: 12467821 | O17: 26275.62 | P17: 1292.8946 | Q17: 27962.08 | R17: 3.3398062e+08 | S17: 9.9987681e+08 | T17: =IF(OR(R17="",R16=""),"",R17-R16) | U17: =IF(OR(S17="",S16=""),"",S17-S16) | V17: =IF(OR(U17="",P17=""),"",U17+P17) | W17: =IF(OR(T17="",O17="",P17=""),"",T17-O17+P17)
A18: 45672 | B18: 5.3154076e+09 | D18: 0 | F18: 0 | G18: 0 | H18: 23198 | I18: 23915 | N18: 12522774 | O18: 26404.186 | P18: 1035.8599 | Q18: 23826.33 | R18: 3.3399159e+08 | S18: 9.9987577e+08 | T18: =IF(OR(R18="",R17=""),"",R18-R17) | U18: =IF(OR(S18="",S17=""),"",S18-S17) | V18: =IF(OR(U18="",P18=""),"",U18+P18) | W18: =IF(OR(T18="",O18="",P18=""),"",T18-O18+P18)
A19: 45673 | B19: 5.7136112e+09 | D19: 0 | F19: 0 | G19: 0 | H19: 18044 | I19: 18602 | N19: 12591917 | O19: 26508.232 | P19: 883.4029 | Q19: 21532.95 | R19: 3.3400284e+08 | S19: 9.9987489e+08 | T19: =IF(OR(R19="",R18=""),"",R19-R18) | U19: =IF(OR(S19="",S18=""),"",S19-S18) | V19: =IF(OR(U19="",P19=""),"",U19+P19) | W19: =IF(OR(T19="",O19="",P19=""),"",T19-O19+P19)
A20: 45674 | B20: 5.4612772e+09 | D20: 0 | F20: 0 | G20: 0 | H20: 19870 | I20: 20485 | N20: 12657482 | O20: 26562.754 | P20: 560.1256 | Q20: 13148.11 | R20: 3.3401451e+08 | S20: 9.9987433e+08 | T20: =IF(OR(R20="",R19=""),"",R20-R19) | U20: =IF(OR(S20="",S19=""),"",S20-S19) | V20: =IF(OR(U20="",P20=""),"",U20+P20) | W20: =IF(OR(T20="",O20="",P20=""),"",T20-O20+P20)
A21: 45675 | B21: 9.6789601e+09 | D21: 0 | F21: 0 | G21: 0 | H21: 50841 | I21: 52413 | N21: 12746262 | O21: 26584.013 | P21: 614.0791 | Q21: 14179.39 | R21: 3.3402616e+08 | S21: 9.9987371e+08 | T21: =IF(OR(R21="",R20=""),"",R21-R20) | U21: =IF(OR(S21="",S20=""),"",S21-S20) | V21: =IF(OR(U21="",P21=""),"",U21+P21) | W21: =IF(OR(T21="",O21="",P21=""),"",T21-O21+P21)
A22: 45676 | B22: 1.775022e+10 | D22: 0 | F22: 0 | G22: 0 | H22: 59675 | I22: 61521 | N22: 12889603 | O22: 26576.453 | P22: 1549.2138 | Q22: 33984.33 | R22: 3.3403684e+08 | S22: 9.9987217e+08 | T22: =IF(OR(R22="",R21=""),"",R22-R21) | U22: =IF(OR(S22="",S21=""),"",S22-S21) | V22: =IF(OR(U22="",P22=""),"",U22+P22) | W22: =IF(OR(T22="",O22="",P22=""),"",T22-O22+P22)
A23: 45677 | B23: 1.6339005e+10 | D23: 0 | F23: 0 | G23: 0 | H23: 33251 | I23: 34279 | N23: 13118130 | O23: 26541.273 | P23: 2127.3129 | Q23: 42947.26 | R23: 3.3404689e+08 | S23: 9.9987004e+08 | T23: =IF(OR(R23="",R22=""),"",R23-R22) | U23: =IF(OR(S23="",S22=""),"",S23-S22) | V23: =IF(OR(U23="",P23=""),"",U23+P23) | W23: =IF(OR(T23="",O23="",P23=""),"",T23-O23+P23)
A24: 45678 | B24: 8.3419449e+09 | D24: 0 | F24: 0 | G24: 0 | H24: 33047 | I24: 34069 | N24: 13251259 | O24: 26530.748 | P24: 1392.5278 | Q24: 28622.71 | R24: 3.3405768e+08 | S24: 9.9986865e+08 | T24: =IF(OR(R24="",R23=""),"",R24-R23) | U24: =IF(OR(S24="",S23=""),"",S24-S23) | V24: =IF(OR(U24="",P24=""),"",U24+P24) | W24: =IF(OR(T24="",O24="",P24=""),"",T24-O24+P24)
A25: 45679 | B25: 5.2815512e+09 | D25: 0 | F25: 0 | G25: 0 | H25: 29505 | I25: 30418 | N25: 13322389 | O25: 26567.346 | P25: 1404.8497 | Q25: 32564.41 | R25: 3.3406849e+08 | S25: 9.9986724e+08 | T25: =IF(OR(R25="",R24=""),"",R25-R24) | U25: =IF(OR(S25="",S24=""),"",S25-S24) | V25: =IF(OR(U25="",P25=""),"",U25+P25) | W25: =IF(OR(T25="",O25="",P25=""),"",T25-O25+P25)
A26: 45680 | B26: 1.1321581e+10 | D26: 0 | F26: 0 | G26: 0 | H26: 37014 | I26: 38159 | N26: 13384449 | O26: 26581.533 | P26: 923.5959 | Q26: 22448.92 | R26: 3.3407981e+08 | S26: 9.9986632e+08 | T26: =IF(OR(R26="",R25=""),"",R26-R25) | U26: =IF(OR(S26="",S25=""),"",S26-S25) | V26: =IF(OR(U26="",P26=""),"",U26+P26) | W26: =IF(OR(T26="",O26="",P26=""),"",T26-O26+P26)
A27: 45681 | B27: 5.7847318e+09 | D27: 0 | F27: 0 | G27: 0 | H27: 23279 | I27: 23999 | N27: 13500446 | O27: 26552.402 | P27: 1425.0715 | Q27: 31310.24 | R27: 3.3409059e+08 | S27: 9.9986489e+08 | T27: =IF(OR(R27="",R26=""),"",R27-R26) | U27: =IF(OR(S27="",S26=""),"",S27-S26) | V27: =IF(OR(U27="",P27=""),"",U27+P27) | W27: =IF(OR(T27="",O27="",P27=""),"",T27-O27+P27)
A28: 45682 | B28: 3.5167284e+09 | D28: 0 | F28: 0 | G28: 0 | H28: 13888 | I28: 14317 | N28: 13559681 | O28: 26530.811 | P28: 909.6107 | Q28: 20977.9 | R28: 3.3410184e+08 | S28: 9.9986398e+08 | T28: =IF(OR(R28="",R27=""),"",R28-R27) | U28: =IF(OR(S28="",S27=""),"",S28-S27) | V28: =IF(OR(U28="",P28=""),"",U28+P28) | W28: =IF(OR(T28="",O28="",P28=""),"",T28-O28+P28)
... A81: 45735 | B81: 5.9364707e+09 | D81: 0 | F81: 0 | G81: 0 | H81: 17924 | I81: 18478 | N81: 17658356 | O81: 26377.289 | P81: 408.8611 | Q81: 5793.56 | R81: 3.3470475e+08 | S81: 9.9981459e+08 | T81: =IF(OR(R81="",R80=""),"",R81-R80) | U81: =IF(OR(S81="",S80=""),"",S81-S80) | V81: =IF(OR(U81="",P81=""),"",U81+P81) | W81: =IF(OR(T81="",O81="",P81=""),"",T81-O81+P81)
A82: 45736 | B82: 4.7983491e+09 | D82: 0 | E82: 1360250.1 | F82: 0 | G82: 0 | H82: 13612 | I82: 14033 | J82: 222.65073 | K82: 35438.86 | L82: 93242.48 | M82: 1360250.1 | N82: 17751598 | O82: 26389.385 | P82: 1047.6243 | Q82: 16362.32 | R82: 3.347156e+08 | S82: 9.9981354e+08 | T82: =IF(OR(R82="",R81=""),"",R82-R81) | U82: =IF(OR(S82="",S81=""),"",S82-S81) | V82: =IF(OR(U82="",P82=""),"",U82+P82) | W82: =IF(OR(T82="",O82="",P82=""),"",T82-O82+P82)
A83: 45737 | B83: 3.5352826e+09 | D83: 0 | E83: 1031164.9 | F83: 0 | G83: 0 | H83: 11995 | I83: 12366 | J83: 2823.9089 | K83: 45038.24 | L83: 70431.98 | M83: 1031164.9 | N83: 17822030 | O83: 26422.9 | P83: 592.8651 | Q83: 8389.63 | R83: 3.3472695e+08 | S83: 9.9981295e+08 | T83: =IF(OR(R83="",R82=""),"",R83-R82) | U83: =IF(OR(S83="",S82=""),"",S83-S82) | V83: =IF(OR(U83="",P83=""),"",U83+P83) | W83: =IF(OR(T83="",O83="",P83=""),"",T83-O83+P83)
A84: 45738 | B84: 2.0454278e+09 | D84: 0 | E84: 847303.18 | F84: 0 | G84: 0 | H84: 8184 | I84: 8437 | J84: 212.65569 | K84: 57676.12 | L84: 53131.87 | M84: 847303.18 | N84: 17875162 | O84: 26439.06 | P84: 633.9893 | Q84: 10097.86 | R84: 3.3473829e+08 | S84: 9.9981231e+08 | T84: =IF(OR(R84="",R83=""),"",R84-R83) | U84: =IF(OR(S84="",S83=""),"",S84-S83) | V84: =IF(OR(U84="",P84=""),"",U84+P84) | W84: =IF(OR(T84="",O84="",P84=""),"",T84-O84+P84)
A85: 45739 | B85: 2.4627913e+09 | D85: 0 | E85: 450708.74 | F85: 0 | G85: 0 | H85: 6361 | I85: 6558 | J85: 313.52069 | K85: 0 | L85: 28455.13 | M85: 450708.74 | N85: 17903617 | O85: 26250.617 | P85: 393.117 | Q85: 6122.6 | R85: 3.3474968e+08 | S85: 9.9981192e+08 | T85: =IF(OR(R85="",R84=""),"",R85-R84) | U85: =IF(OR(S85="",S84=""),"",S85-S84) | V85: =IF(OR(U85="",P85=""),"",U85+P85) | W85: =IF(OR(T85="",O85="",P85=""),"",T85-O85+P85)
A86: 45740 | B86: 5.1058256e+09 | D86: 0 | E86: 829053.81 | F86: 0 | G86: 0 | H86: 18609 | I86: 19185 | J86: 377.73303 | K86: 49980 | L86: 49430.03 | M86: 829053.81 | N86: 17953047 | O86: 26407.972 | P86: 282.117 | Q86: 4596.11 | R86: 3.3476131e+08 | S86: 9.9981164e+08 | T86: =IF(OR(R86="",R85=""),"",R86-R85) | U86: =IF(OR(S86="",S85=""),"",S86-S85) | V86: =IF(OR(U86="",P86=""),"",U86+P86) | W86: =IF(OR(T86="",O86="",P86=""),"",T86-O86+P86)
A87: 45741 | B87: 3.9320302e+09 | D87: 0 | E87: 1041581.3 | F87: 0 | G87: 0 | H87: 11179 | I87: 11525 | J87: 325.86711 | K87: 63542.04 | L87: 63584.4 | M87: 1041581.3 | N87: 18016632 | O87: 26408.12 | P87: 874.4752 | Q87: 14662.32 | R87: 3.3477236e+08 | S87: 9.9981076e+08 | T87: =IF(OR(R87="",R86=""),"",R87-R86) | U87: =IF(OR(S87="",S86=""),"",S87-S86) | V87: =IF(OR(U87="",P87=""),"",U87+P87) | W87: =IF(OR(T87="",O87="",P87=""),"",T87-O87+P87)
A88: 45742 | B88: 4.5464593e+09 | D88: 0 | E88: 829339.39 | F88: 0 | G88: 0 | H88: 60200 | I88: 62061 | J88: 520.88851 | K88: 0 | L88: 57631.29 | M88: 829339.39 | N88: 18074263 | O88: 26422.374 | P88: 418.2386 | Q88: 6705.62 | R88: 3.3478388e+08 | S88: 9.9981034e+08 | T88: =IF(OR(R88="",R87=""),"",R88-R87) | U88: =IF(OR(S88="",S87=""),"",S88-S87) | V88: =IF(OR(U88="",P88=""),"",U88+P88) | W88: =IF(OR(T88="",O88="",P88=""),"",T88-O88+P88)
A89: 45743 | B89: 2.9680178e+09 | D89: 0 | E89: 1118366.5 | F89: 0 | G89: 0 | H89: 11862 | I89: 12229 | J89: 170.72506 | K89: 145034.84 | L89: 77117.5 | M89: 1118366.5 | N89: 18151380 | O89: 26404.382 | P89: 3348.6945 | Q89: 47070.92 | R89: 3.3479246e+08 | S89: 9.99807e+08 | T89: =IF(OR(R89="",R88=""),"",R89-R88) | U89: =IF(OR(S89="",S88=""),"",S89-S88) | V89: =IF(OR(U89="",P89=""),"",U89+P89) | W89: =IF(OR(T89="",O89="",P89=""),"",T89-O89+P89)
A90: 45744 | B90: 4.6960274e+09 | D90: 0 | E90: 828868.5 | F90: 0 | G90: 0 | H90: 17635 | I90: 18181 | J90: 148.90207 | K90: 0 | L90: 62740.01 | M90: 828868.5 | N90: 18214121 | O90: 26355.458 | P90: 572.3714 | Q90: 8353.19 | R90: 3.3480375e+08 | S90: 9.9980642e+08 | T90: =IF(OR(R90="",R89=""),"",R90-R89) | U90: =IF(OR(S90="",S89=""),"",S90-S89) | V90: =IF(OR(U90="",P90=""),"",U90+P90) | W90: =IF(OR(T90="",O90="",P90=""),"",T90-O90+P90)
A91: 45745 | B91: 3.3004373e+09 | D91: 0 | E91: 901117.23 | F91: 0 | G91: 0 | H91: 12226 | I91: 12604 | J91: 123.14806 | K91: 53370.55 | L91: 70357.02 | M91: 901117.23 | N91: 18284478 | O91: 26368.156 | P91: 574.8896 | Q91: 7698.63 | R91: 3.3481505e+08 | S91: 9.9980585e+08 | T91: =IF(OR(R91="",R90=""),"",R91-R90) | U91: =IF(OR(S91="",S90=""),"",S91-S90) | V91: =IF(OR(U91="",P91=""),"",U91+P91) | W91: =IF(OR(T91="",O91="",P91=""),"",T91-O91+P91)
A92: 45746 | B92: 2.7740623e+09 | D92: 0 | E92: 696924.24 | F92: 0 | G92: 0 | H92: 7203 | I92: 7425 | J92: 101.87837 | K92: 45820.11 | L92: 55468.07 | M92: 696924.24 | N92: 18339946 | O92: 26361.194 | P92: 564.418 | Q92: 7222.57 | R92: 3.3482634e+08 | S92: 9.9980528e+08 | T92: =IF(OR(R92="",R91=""),"",R92-R91) | U92: =IF(OR(S92="",S91=""),"",S92-S91) | V92: =IF(OR(U92="",P92=""),"",U92+P92) | W92: =IF(OR(T92="",O92="",P92=""),"",T92-O92+P92)
...

Sheet Sources
A1: SOURCES
A2: Data | B2: Source | C2: Endpoint / reference | D2: Notes
A3: Total perp & spot volume | B3: hyperscreener.asxn.xyz | C3: API /cloudfront/total_volume, /spot-ecosystem | D3: Daily.
A4: HyperCore revenue (NORTH STAR) | B4: hyperscreener.asxn.xyz | C4: API /buyback/revenues | D4: Actual protocol revenue / buyback. From 2025-03-20.
A5: Buyback, AF, emissions, burns, supply | B5: hyperscreener.asxn.xyz | C5: API /buyback/*, /validators/daily-emissions | D5: On the Daily Data tab.
A6: HIP-3 volume, gross fees, deployer fees | B6: Loris | C6: loris.tools/hip3 (via v3 workbook) | D6: Daily. HIP-3 fees from 2025-10-13; deployer fees from 2026-03-21.
A7: Spot revenue & spot fees | B7: DefiLlama | C7: api.llama.fi /summary/fees/hyperliquid-spot-orderbook | D7: dailyHoldersRevenue & dailyFees. Daily.
A8: HLP share rule (1% / 3%) | B8: DefiLlama | C8: Hyperliquid fees methodology | D8: HLP got 3% of perp fees before 2025-08-30, 1% after.
A9: Builder code fees | B9: hyperscreener.asxn.xyz | C9: API /node/builders/* | D9: $75.3M all-time. Modelled as a rate on volume (Assumptions).
A10: HIP-3 fee structure | B10: Hyperliquid docs | C10: HIP-3 builder-deployed perpetuals | D10: Users pay ~2x; markets currently in growth mode (low realised fees).
